Workbook
Name ActivePayoff: Disposition!$C$18
Name AssessedValueStab: Operating!$C$56
Name AvgUnitSF: UnitMatrix!$C$19
Name BaseLowRentMo: UnitMatrix!$C$21
Name BaseMarketRentMo: UnitMatrix!$C$20
Name BasisPerUnitCur: Returns!$C$29
Name BasisPerUnitExit: Returns!$C$30
Name BlendedExitCap: Disposition!$C$9
Name BrokerCost: Disposition!$C$14
Name BuildableSF: UnitMatrix!$C$18
Name Chk_ConBalEnd: ConLoan!$C$47
Name Chk_DebtDraws: ConLoan!$C$44
Name Chk_EquityDraws: ConLoan!$C$45
Name Chk_IntReserve: ConLoan!$C$48
Name Chk_LeaseUpReached: LeaseUp!$C$13
Name Chk_LoanRetired: Disposition!$C$24
Name Chk_Reassess: Disposition!$C$25
Name Chk_RefiBalance: PermLoan!$C$33
Name Chk_TaxMethod: Operating!$C$59
Name Chk_UnitsDelivered: LeaseUp!$C$14
Name Chk_Uses: ConLoan!$C$46
Name ConCostBasis: ConLoan!$C$4
Name ConCostCommit: ConLoan!$C$8
Name ConCostExInt: ConLoan!$C$11
Name ConDSCRtest: ConLoan!$C$17
Name ConDYtest: ConLoan!$C$16
Name ConLoanTotal: ConLoan!$C$37
Name ConMaturity: Timeline!$C$18
Name ConPayoffBal: ConLoan!$C$38
Name ConPayoffMonth: Timeline!$C$25
Name ConPoints: ConLoan!$C$9
Name ConRealizedLTC: ConLoan!$C$18
Name ConStart: Timeline!$C$17
Name DebtShare: ConLoan!$C$12
Name DebtYieldStab: Returns!$C$25
Name DeliverStart: Timeline!$C$19
Name DevSpreadBps: Returns!$C$22
Name DevSpreadPct: Returns!$C$21
Name DispoEffTaxRate: Operating!$C$55
Name DispoMonth: Timeline!$C$21
Name EffTaxRateOnValue: Operating!$C$54
Name EquityBudget: ConLoan!$C$13
Name EquityTotal: ConLoan!$C$40
Name ExitValue: Disposition!$C$10
Name FwdEGI: Disposition!$C$6
Name FwdNOIafter: Disposition!$C$5
Name FwdNOIbt: Disposition!$C$4
Name FwdRetail: Disposition!$C$7
Name GrossSale: Disposition!$C$13
Name GrowthStartMonth: Timeline!$C$22
Name InterestReserveAccrued: ConLoan!$C$35
Name InterestReserveFunded: ConLoan!$C$36
Name LevDistros: CashFlow!$C$11
Name LevEquityIn: CashFlow!$C$10
Name LevIRR: Returns!$C$4
Name LevIRRgross: Returns!$C$14
Name LevMOIC: Returns!$C$6
Name LevMOICgross: Returns!$C$16
Name LevNetProfit: CashFlow!$C$12
Name LowUnits: UnitMatrix!$C$16

Sheet Dashboard
B1: ="Multifamily Development Model — "&PropertyName
B2: =City&", "&State&" • "&TotalUnits&" units • "&TEXT(NRSF,"#,##0")&" NRSF"
B4: =IF(ErrorsFound=0,"✔ ALL CHECKS PASS — model is clean","⚠ "&ErrorsFound&" ERROR(S) FOUND — REVIEW DIAGNOSTICS") | F4: ="Warnings: "&WarningsFound
B6: Development Return (untrended) | E6: Cost & Basis
B7: Yield on Cost (untrended) | C7: =YieldOnCost | E7: Total Development Cost | F7: =TDC_Total
B8: Exit Cap Rate | C8: =ExitCapResidential | E8: TDC / Unit | F8: =TDCperUnit
B9: Development Spread | C9: =DevSpreadBps | E9: TDC / NRSF | F9: =TDCperSF
B10: Return on Cost (stabilized) | C10: =ROCstab | E10: Exit Value | F10: =ExitValue
B11: Debt Yield (stab, active loan) | C11: =DebtYieldStab | E11: Exit Basis / Unit | F11: =BasisPerUnitExit
E12: Static Value (untrended) | F12: =StaticValue
B13: Trended Performance (with growth) | E13: Sources & Uses
B14: Stabilized NOI (trended) | C14: =StabNOI | E14: Construction Loan | F14: =ConLoanTotal
E15: Equity | F15: =EquityTotal
B16: Returns | E16: Total Sources | F16: =ConLoanTotal+EquityTotal
B17: Levered IRR (net) | C17: =LevIRR | E17: Total Uses (TDC) | F17: =TDC_Total
B18: Levered IRR (gross) | C18: =LevIRRgross | E18: Sources − Uses (check) | F18: =ConLoanTotal+EquityTotal-TDC_Total
B19: Unlevered IRR (net) | C19: =UnlevIRR
B20: Levered MOIC (net) | C20: =LevMOIC | E20: Loan Sizing (binding constraint)
B21: Unlevered MOIC (net) | C21: =UnlevMOIC | E21: Refi or Sell | F21: =IF(RefiFlag=1,"Refinance then hold","Sell during construction")
B22: Static Unlevered IRR (no-growth) | C22: =StaticUnlevIRR | E22: Construction Loan — binding | F22: =ConBinding
E23: Con Debt Yield / DSCR | F23: =ConDYtest&" / "&ConDSCRtest
B24: Timeline (months) | E24: Permanent Loan — binding | F24: =PermBinding
B25: Construction Start → Maturity | C25: =ConStart&" → "&ConMaturity | E25: Perm LTV / DSCR | F25: =PermLTVtest&" / "&PermDSCRtest
B26: 1st Delivery → Stabilization | C26: =DeliverStart&" → "&StabMonth
B27: Refi / Disposition | C27: =IF(RefiFlag=1,RefiMonth,0)&" / "&DispoMonth | E27: Validation
E28: Errors / Warnings / Sanity flags | F28: =ErrorsFound&" / "&WarningsFound&" / "&SanityFlags

Sheet Annual
B1: Annual Summary
B2: ="Hold: "&HoldPeriodMonths&" months • Disposition month "&DispoMonth
B4: Sources & Uses
B5: Uses
B6: Land | C6: =BudgetLand
B7: Hard Costs | C7: =BudgetHard
B8: Soft Costs | C8: =BudgetSoft
B9: Development Fee | C9: =DevFee
B10: Loan Costs (points, recourse, other) | C10: =ConPoints+RecourseFee+ConOtherCosts
B11: Interest Reserve | C11: =InterestReserveFunded
B12: Operating Reserve | C12: =OpReserve
B13: Total Uses (TDC) | C13: =TDC_Total
B14: Sources
B15: Construction Loan | C15: =ConLoanTotal
B16: Equity | C16: =EquityTotal
B17: Refi Cash-Out (memo) | C17: =RefiCashOut
B18: Total Sources | C18: =ConLoanTotal+EquityTotal
B19: Sources − Uses (check = 0) | C19: =ConLoanTotal+EquityTotal-TDC_Total
B21: Annual Cash Flow (Year 1 … 31)
B22: Year → | C22: 1 | D22: 2 | E22: 3 | F22: 4 | G22: 5 | H22: 6 | I22: 7 | J22: 8 | K22: 9 | L22: 10 | M22: 11 | N22: 12 | O22: 13 | P22: 14 | Q22: 15 | R22: 16 | S22: 17 | T22: 18 | U22: 19 | V22: 20 | W22: 21 | X22: 22 | Y22: 23 | Z22: 24 | AA22: 25 | AB22: 26 | AC22: 27 | AD22: 28 | AE22: 29 | AF22: 30 | AG22: 31
B23: Development Cost (cash, ex-interest) | C23: =SUM(INDEX(ConLoan!$E$26:$NL$26,((C$22-1)*12+1)):INDEX(ConLoan!$E$26:$NL$26,((C$22-1)*12+1)+11)) | D23: =SUM(INDEX(ConLoan!$E$26:$NL$26,((D$22-1)*12+1)):INDEX(ConLoan!$E$26:$NL$26,((D$22-1)*12+1)+11)) | E23: =SUM(INDEX(ConLoan!$E$26:$NL$26,((E$22-1)*12+1)):INDEX(ConLoan!$E$26:$NL$26,((E$22-1)*12+1)+11)) | F23: =SUM(INDEX(ConLoan!$E$26:$NL$26,((F$22-1)*12+1)):INDEX(ConLoan!$E$26:$NL$26,((F$22-1)*12+1)+11)) | G23: =SUM(INDEX(ConLoan!$E$26:$NL$26,((G$22-1)*12+1)):INDEX(ConLoan!$E$26:$NL$26,((G$22-1)*12+1)+11)) | H23: =SUM(INDEX(ConLoan!$E$26:$NL$26,((H$22-1)*12+1)):INDEX(ConLoan!$E$26:$NL$26,((H$22-1)*12+1)+11)) | I23: =SUM(INDEX(ConLoan!$E$26:$NL$26,((I$22-1)*12+1)):INDEX(ConLoan!$E$26:$NL$26,((I$22-1)*12+1)+11)) | J23: =SUM(INDEX(ConLoan!$E$26:$NL$26,((J$22-1)*12+1)):INDEX(ConLoan!$E$26:$NL$26,((J$22-1)*12+1)+11)) | ... AG23: =SUM(INDEX(ConLoan!$E$26:$NL$26,((AG$22-1)*12+1)):INDEX(ConLoan!$E$26:$NL$26,((AG$22-1)*12+1)+11))
B24: Construction Debt Draw | C24: =SUM(INDEX(ConLoan!$E$29:$NL$29,((C$22-1)*12+1)):INDEX(ConLoan!$E$29:$NL$29,((C$22-1)*12+1)+11)) | D24: =SUM(INDEX(ConLoan!$E$29:$NL$29,((D$22-1)*12+1)):INDEX(ConLoan!$E$29:$NL$29,((D$22-1)*12+1)+11)) | E24: =SUM(INDEX(ConLoan!$E$29:$NL$29,((E$22-1)*12+1)):INDEX(ConLoan!$E$29:$NL$29,((E$22-1)*12+1)+11)) | F24: =SUM(INDEX(ConLoan!$E$29:$NL$29,((F$22-1)*12+1)):INDEX(ConLoan!$E$29:$NL$29,((F$22-1)*12+1)+11)) | G24: =SUM(INDEX(ConLoan!$E$29:$NL$29,((G$22-1)*12+1)):INDEX(ConLoan!$E$29:$NL$29,((G$22-1)*12+1)+11)) | H24: =SUM(INDEX(ConLoan!$E$29:$NL$29,((H$22-1)*12+1)):INDEX(ConLoan!$E$29:$NL$29,((H$22-1)*12+1)+11)) | I24: =SUM(INDEX(ConLoan!$E$29:$NL$29,((I$22-1)*12+1)):INDEX(ConLoan!$E$29:$NL$29,((I$22-1)*12+1)+11)) | J24: =SUM(INDEX(ConLoan!$E$29:$NL$29,((J$22-1)*12+1)):INDEX(ConLoan!$E$29:$NL$29,((J$22-1)*12+1)+11)) | ... AG24: =SUM(INDEX(ConLoan!$E$29:$NL$29,((AG$22-1)*12+1)):INDEX(ConLoan!$E$29:$NL$29,((AG$22-1)*12+1)+11))
B25: Equity Draw | C25: =SUM(INDEX(ConLoan!$E$27:$NL$27,((C$22-1)*12+1)):INDEX(ConLoan!$E$27:$NL$27,((C$22-1)*12+1)+11)) | D25: =SUM(INDEX(ConLoan!$E$27:$NL$27,((D$22-1)*12+1)):INDEX(ConLoan!$E$27:$NL$27,((D$22-1)*12+1)+11)) | E25: =SUM(INDEX(ConLoan!$E$27:$NL$27,((E$22-1)*12+1)):INDEX(ConLoan!$E$27:$NL$27,((E$22-1)*12+1)+11)) | F25: =SUM(INDEX(ConLoan!$E$27:$NL$27,((F$22-1)*12+1)):INDEX(ConLoan!$E$27:$NL$27,((F$22-1)*12+1)+11)) | G25: =SUM(INDEX(ConLoan!$E$27:$NL$27,((G$22-1)*12+1)):INDEX(ConLoan!$E$27:$NL$27,((G$22-1)*12+1)+11)) | H25: =SUM(INDEX(ConLoan!$E$27:$NL$27,((H$22-1)*12+1)):INDEX(ConLoan!$E$27:$NL$27,((H$22-1)*12+1)+11)) | I25: =SUM(INDEX(ConLoan!$E$27:$NL$27,((I$22-1)*12+1)):INDEX(ConLoan!$E$27:$NL$27,((I$22-1)*12+1)+11)) | J25: =SUM(INDEX(ConLoan!$E$27:$NL$27,((J$22-1)*12+1)):INDEX(ConLoan!$E$27:$NL$27,((J$22-1)*12+1)+11)) | ... AG25: =SUM(INDEX(ConLoan!$E$27:$NL$27,((AG$22-1)*12+1)):INDEX(ConLoan!$E$27:$NL$27,((AG$22-1)*12+1)+11))
B26: Effective Gross Income | C26: =SUM(INDEX(Operating!$E$23:$NL$23,((C$22-1)*12+1)):INDEX(Operating!$E$23:$NL$23,((C$22-1)*12+1)+11)) | D26: =SUM(INDEX(Operating!$E$23:$NL$23,((D$22-1)*12+1)):INDEX(Operating!$E$23:$NL$23,((D$22-1)*12+1)+11)) | E26: =SUM(INDEX(Operating!$E$23:$NL$23,((E$22-1)*12+1)):INDEX(Operating!$E$23:$NL$23,((E$22-1)*12+1)+11)) | F26: =SUM(INDEX(Operating!$E$23:$NL$23,((F$22-1)*12+1)):INDEX(Operating!$E$23:$NL$23,((F$22-1)*12+1)+11)) | G26: =SUM(INDEX(Operating!$E$23:$NL$23,((G$22-1)*12+1)):INDEX(Operating!$E$23:$NL$23,((G$22-1)*12+1)+11)) | H26: =SUM(INDEX(Operating!$E$23:$NL$23,((H$22-1)*12+1)):INDEX(Operating!$E$23:$NL$23,((H$22-1)*12+1)+11)) | I26: =SUM(INDEX(Operating!$E$23:$NL$23,((I$22-1)*12+1)):INDEX(Operating!$E$23:$NL$23,((I$22-1)*12+1)+11)) | J26: =SUM(INDEX(Operating!$E$23:$NL$23,((J$22-1)*12+1)):INDEX(Operating!$E$23:$NL$23,((J$22-1)*12+1)+11)) | ... AG26: =SUM(INDEX(Operating!$E$23:$NL$23,((AG$22-1)*12+1)):INDEX(Operating!$E$23:$NL$23,((AG$22-1)*12+1)+11))
B27: Net Operating Income | C27: =SUM(INDEX(Operating!$E$38:$NL$38,((C$22-1)*12+1)):INDEX(Operating!$E$38:$NL$38,((C$22-1)*12+1)+11)) | D27: =SUM(INDEX(Operating!$E$38:$NL$38,((D$22-1)*12+1)):INDEX(Operating!$E$38:$NL$38,((D$22-1)*12+1)+11)) | E27: =SUM(INDEX(Operating!$E$38:$NL$38,((E$22-1)*12+1)):INDEX(Operating!$E$38:$NL$38,((E$22-1)*12+1)+11)) | F27: =SUM(INDEX(Operating!$E$38:$NL$38,((F$22-1)*12+1)):INDEX(Operating!$E$38:$NL$38,((F$22-1)*12+1)+11)) | G27: =SUM(INDEX(Operating!$E$38:$NL$38,((G$22-1)*12+1)):INDEX(Operating!$E$38:$NL$38,((G$22-1)*12+1)+11)) | H27: =SUM(INDEX(Operating!$E$38:$NL$38,((H$22-1)*12+1)):INDEX(Operating!$E$38:$NL$38,((H$22-1)*12+1)+11)) | I27: =SUM(INDEX(Operating!$E$38:$NL$38,((I$22-1)*12+1)):INDEX(Operating!$E$38:$NL$38,((I$22-1)*12+1)+11)) | J27: =SUM(INDEX(Operating!$E$38:$NL$38,((J$22-1)*12+1)):INDEX(Operating!$E$38:$NL$38,((J$22-1)*12+1)+11)) | ... AG27: =SUM(INDEX(Operating!$E$38:$NL$38,((AG$22-1)*12+1)):INDEX(Operating!$E$38:$NL$38,((AG$22-1)*12+1)+11))
B28: Construction Interest (capitalized, financed) | C28: =SUM(INDEX(ConLoan!$E$31:$NL$31,((C$22-1)*12+1)):INDEX(ConLoan!$E$31:$NL$31,((C$22-1)*12+1)+11)) | D28: =SUM(INDEX(ConLoan!$E$31:$NL$31,((D$22-1)*12+1)):INDEX(ConLoan!$E$31:$NL$31,((D$22-1)*12+1)+11)) | E28: =SUM(INDEX(ConLoan!$E$31:$NL$31,((E$22-1)*12+1)):INDEX(ConLoan!$E$31:$NL$31,((E$22-1)*12+1)+11)) | F28: =SUM(INDEX(ConLoan!$E$31:$NL$31,((F$22-1)*12+1)):INDEX(ConLoan!$E$31:$NL$31,((F$22-1)*12+1)+11)) | G28: =SUM(INDEX(ConLoan!$E$31:$NL$31,((G$22-1)*12+1)):INDEX(ConLoan!$E$31:$NL$31,((G$22-1)*12+1)+11)) | H28: =SUM(INDEX(ConLoan!$E$31:$NL$31,((H$22-1)*12+1)):INDEX(ConLoan!$E$31:$NL$31,((H$22-1)*12+1)+11)) | I28: =SUM(INDEX(ConLoan!$E$31:$NL$31,((I$22-1)*12+1)):INDEX(ConLoan!$E$31:$NL$31,((I$22-1)*12+1)+11)) | J28: =SUM(INDEX(ConLoan!$E$31:$NL$31,((J$22-1)*12+1)):INDEX(ConLoan!$E$31:$NL$31,((J$22-1)*12+1)+11)) | ... AG28: =SUM(INDEX(ConLoan!$E$31:$NL$31,((AG$22-1)*12+1)):INDEX(ConLoan!$E$31:$NL$31,((AG$22-1)*12+1)+11))
B29: Permanent Debt Service | C29: =SUM(INDEX(PermLoan!$E$29:$NL$29,((C$22-1)*12+1)):INDEX(PermLoan!$E$29:$NL$29,((C$22-1)*12+1)+11)) | D29: =SUM(INDEX(PermLoan!$E$29:$NL$29,((D$22-1)*12+1)):INDEX(PermLoan!$E$29:$NL$29,((D$22-1)*12+1)+11)) | E29: =SUM(INDEX(PermLoan!$E$29:$NL$29,((E$22-1)*12+1)):INDEX(PermLoan!$E$29:$NL$29,((E$22-1)*12+1)+11)) | F29: =SUM(INDEX(PermLoan!$E$29:$NL$29,((F$22-1)*12+1)):INDEX(PermLoan!$E$29:$NL$29,((F$22-1)*12+1)+11)) | G29: =SUM(INDEX(PermLoan!$E$29:$NL$29,((G$22-1)*12+1)):INDEX(PermLoan!$E$29:$NL$29,((G$22-1)*12+1)+11)) | H29: =SUM(INDEX(PermLoan!$E$29:$NL$29,((H$22-1)*12+1)):INDEX(PermLoan!$E$29:$NL$29,((H$22-1)*12+1)+11)) | I29: =SUM(INDEX(PermLoan!$E$29:$NL$29,((I$22-1)*12+1)):INDEX(PermLoan!$E$29:$NL$29,((I$22-1)*12+1)+11)) | J29: =SUM(INDEX(PermLoan!$E$29:$NL$29,((J$22-1)*12+1)):INDEX(PermLoan!$E$29:$NL$29,((J$22-1)*12+1)+11)) | ... AG29: =SUM(INDEX(PermLoan!$E$29:$NL$29,((AG$22-1)*12+1)):INDEX(PermLoan!$E$29:$NL$29,((AG$22-1)*12+1)+11))
B30: Unlevered Cash Flow | C30: =SUM(INDEX(CashFlow!$E$7:$NL$7,((C$22-1)*12+1)):INDEX(CashFlow!$E$7:$NL$7,((C$22-1)*12+1)+11)) | D30: =SUM(INDEX(CashFlow!$E$7:$NL$7,((D$22-1)*12+1)):INDEX(CashFlow!$E$7:$NL$7,((D$22-1)*12+1)+11)) | E30: =SUM(INDEX(CashFlow!$E$7:$NL$7,((E$22-1)*12+1)):INDEX(CashFlow!$E$7:$NL$7,((E$22-1)*12+1)+11)) | F30: =SUM(INDEX(CashFlow!$E$7:$NL$7,((F$22-1)*12+1)):INDEX(CashFlow!$E$7:$NL$7,((F$22-1)*12+1)+11)) | G30: =SUM(INDEX(CashFlow!$E$7:$NL$7,((G$22-1)*12+1)):INDEX(CashFlow!$E$7:$NL$7,((G$22-1)*12+1)+11)) | H30: =SUM(INDEX(CashFlow!$E$7:$NL$7,((H$22-1)*12+1)):INDEX(CashFlow!$E$7:$NL$7,((H$22-1)*12+1)+11)) | I30: =SUM(INDEX(CashFlow!$E$7:$NL$7,((I$22-1)*12+1)):INDEX(CashFlow!$E$7:$NL$7,((I$22-1)*12+1)+11)) | J30: =SUM(INDEX(CashFlow!$E$7:$NL$7,((J$22-1)*12+1)):INDEX(CashFlow!$E$7:$NL$7,((J$22-1)*12+1)+11)) | ... AG30: =SUM(INDEX(CashFlow!$E$7:$NL$7,((AG$22-1)*12+1)):INDEX(CashFlow!$E$7:$NL$7,((AG$22-1)*12+1)+11))
B31: Levered Cash Flow | C31: =SUM(INDEX(CashFlow!$E$6:$NL$6,((C$22-1)*12+1)):INDEX(CashFlow!$E$6:$NL$6,((C$22-1)*12+1)+11)) | D31: =SUM(INDEX(CashFlow!$E$6:$NL$6,((D$22-1)*12+1)):INDEX(CashFlow!$E$6:$NL$6,((D$22-1)*12+1)+11)) | E31: =SUM(INDEX(CashFlow!$E$6:$NL$6,((E$22-1)*12+1)):INDEX(CashFlow!$E$6:$NL$6,((E$22-1)*12+1)+11)) | F31: =SUM(INDEX(CashFlow!$E$6:$NL$6,((F$22-1)*12+1)):INDEX(CashFlow!$E$6:$NL$6,((F$22-1)*12+1)+11)) | G31: =SUM(INDEX(CashFlow!$E$6:$NL$6,((G$22-1)*12+1)):INDEX(CashFlow!$E$6:$NL$6,((G$22-1)*12+1)+11)) | H31: =SUM(INDEX(CashFlow!$E$6:$NL$6,((H$22-1)*12+1)):INDEX(CashFlow!$E$6:$NL$6,((H$22-1)*12+1)+11)) | I31: =SUM(INDEX(CashFlow!$E$6:$NL$6,((I$22-1)*12+1)):INDEX(CashFlow!$E$6:$NL$6,((I$22-1)*12+1)+11)) | J31: =SUM(INDEX(CashFlow!$E$6:$NL$6,((J$22-1)*12+1)):INDEX(CashFlow!$E$6:$NL$6,((J$22-1)*12+1)+11)) | ... AG31: =SUM(INDEX(CashFlow!$E$6:$NL$6,((AG$22-1)*12+1)):INDEX(CashFlow!$E$6:$NL$6,((AG$22-1)*12+1)+11))
B32: Construction Loan Balance (EOY) | C32: =INDEX(ConLoan!$E$32:$NL$32,((C$22-1)*12+1)+11) | D32: =INDEX(ConLoan!$E$32:$NL$32,((D$22-1)*12+1)+11) | E32: =INDEX(ConLoan!$E$32:$NL$32,((E$22-1)*12+1)+11) | F32: =INDEX(ConLoan!$E$32:$NL$32,((F$22-1)*12+1)+11) | G32: =INDEX(ConLoan!$E$32:$NL$32,((G$22-1)*12+1)+11) | H32: =INDEX(ConLoan!$E$32:$NL$32,((H$22-1)*12+1)+11) | I32: =INDEX(ConLoan!$E$32:$NL$32,((I$22-1)*12+1)+11) | J32: =INDEX(ConLoan!$E$32:$NL$32,((J$22-1)*12+1)+11) | ... AG32: =INDEX(ConLoan!$E$32:$NL$32,((AG$22-1)*12+1)+11)
B33: Permanent Loan Balance (EOY) | C33: =INDEX(PermLoan!$E$30:$NL$30,((C$22-1)*12+1)+11) | D33: =INDEX(PermLoan!$E$30:$NL$30,((D$22-1)*12+1)+11) | E33: =INDEX(PermLoan!$E$30:$NL$30,((E$22-1)*12+1)+11) | F33: =INDEX(PermLoan!$E$30:$NL$30,((F$22-1)*12+1)+11) | G33: =INDEX(PermLoan!$E$30:$NL$30,((G$22-1)*12+1)+11) | H33: =INDEX(PermLoan!$E$30:$NL$30,((H$22-1)*12+1)+11) | I33: =INDEX(PermLoan!$E$30:$NL$30,((I$22-1)*12+1)+11) | J33: =INDEX(PermLoan!$E$30:$NL$30,((J$22-1)*12+1)+11) | ... AG33: =INDEX(PermLoan!$E$30:$NL$30,((AG$22-1)*12+1)+11)
B34: Physical Occupancy (EOY) | C34: =INDEX(LeaseUp!$E$10:$NL$10,((C$22-1)*12+1)+11) | D34: =INDEX(LeaseUp!$E$10:$NL$10,((D$22-1)*12+1)+11) | E34: =INDEX(LeaseUp!$E$10:$NL$10,((E$22-1)*12+1)+11) | F34: =INDEX(LeaseUp!$E$10:$NL$10,((F$22-1)*12+1)+11) | G34: =INDEX(LeaseUp!$E$10:$NL$10,((G$22-1)*12+1)+11) | H34: =INDEX(LeaseUp!$E$10:$NL$10,((H$22-1)*12+1)+11) | I34: =INDEX(LeaseUp!$E$10:$NL$10,((I$22-1)*12+1)+11) | J34: =INDEX(LeaseUp!$E$10:$NL$10,((J$22-1)*12+1)+11) | ... AG34: =INDEX(LeaseUp!$E$10:$NL$10,((AG$22-1)*12+1)+11)
B36: Check: ΣAnnual NOI − monthly total | C36: =SUM(C27:AG27)-Operating!$D$38
B37: Check: Σ Dev Cost + Σ Cap. Interest − TDC | C37: =SUM(C23:AG23)+SUM(C28:AG28)-TDC_Total | D37: =IF(ABS(C37)<1,"PASS","FAIL")

Sheet Proforma
B1: Stabilized Operating Proforma — Untrended
B2: =""&PropertyName&" • "&City&", "&State&" • point-in-time at stabilized occupancy (no growth trending)"
B4: Basis
B5: Total Units | C5: =TotalUnits | E5: Occupied Units (stab) | F5: =StabLeasedTarget
B6: Net Rentable SF | C6: =NRSF | E6: Stabilized Occupancy | F6: =StabilizedOccupancy
B7: Avg Unit SF | C7: =AvgUnitSF | E7: Effective Tax Rate on Value | F7: =EffTaxRateOnValue
B10: Untrended Stabilized Proforma | C10: % of / amt | D10: $ / SF /mo | E10: $ / Unit /mo | F10: $ / Month | G10: $ / Year | H10: Trended $/yr (ref)
B11: Revenue
B12: Gross Potential Rent | C12: =(BaseMarketRentMo+BaseLowRentMo)/TotalUnits | D12: =IF(NRSF=0,0,G12/12/NRSF) | E12: =IF(TotalUnits=0,0,G12/12/TotalUnits) | F12: =G12/12 | G12: =(BaseMarketRentMo+BaseLowRentMo)*12 | H12: =SUM(INDEX(Operating!$E$14:$NL$14,StabMonth):INDEX(Operating!$E$14:$NL$14,StabMonth+11))
B13: Vacancy Loss | C13: -0.06 | D13: =IF(NRSF=0,0,G13/12/NRSF) | E13: =IF(TotalUnits=0,0,G13/12/TotalUnits) | F13: =G13/12 | G13: =G12*VacancyPct | H13: =SUM(INDEX(Operating!$E$15:$NL$15,StabMonth):INDEX(Operating!$E$15:$NL$15,StabMonth+11))
B14: Gain / (Loss) to Lease | C14: 0 | D14: =IF(NRSF=0,0,G14/12/NRSF) | E14: =IF(TotalUnits=0,0,G14/12/TotalUnits) | F14: =G14/12 | G14: =G12*LossToLeasePct | H14: =SUM(INDEX(Operating!$E$16:$NL$16,StabMonth):INDEX(Operating!$E$16:$NL$16,StabMonth+11))
B15: Bad Debt | C15: -0.005 | D15: =IF(NRSF=0,0,G15/12/NRSF) | E15: =IF(TotalUnits=0,0,G15/12/TotalUnits) | F15: =G15/12 | G15: =G12*BadDebtPct | H15: =SUM(INDEX(Operating!$E$17:$NL$17,StabMonth):INDEX(Operating!$E$17:$NL$17,StabMonth+11))
B16: Concessions | C16: 0 | D16: =IF(NRSF=0,0,G16/12/NRSF) | E16: =IF(TotalUnits=0,0,G16/12/TotalUnits) | F16: =G16/12 | G16: =G12*ConcessionsPct | H16: =SUM(INDEX(Operating!$E$18:$NL$18,StabMonth):INDEX(Operating!$E$18:$NL$18,StabMonth+11))
B17: Model / Down Units | C17: 1 | D17: =IF(NRSF=0,0,G17/12/NRSF) | E17: =IF(TotalUnits=0,0,G17/12/TotalUnits) | F17: =G17/12 | G17: =-G12*ModelUnits/TotalUnits
B18: Parking & Storage | C18: 50 | D18: =IF(NRSF=0,0,G18/12/NRSF) | E18: =IF(TotalUnits=0,0,G18/12/TotalUnits) | F18: =G18/12 | G18: =ParkingPerUnitMo*StabLeasedTarget*12 | H18: =SUM(INDEX(Operating!$E$19:$NL$19,StabMonth):INDEX(Operating!$E$19:$NL$19,StabMonth+11))
B19: Utility Reimbursement | C19: 50 | D19: =IF(NRSF=0,0,G19/12/NRSF) | E19: =IF(TotalUnits=0,0,G19/12/TotalUnits) | F19: =G19/12 | G19: =UtilReimbPerUnitMo*StabLeasedTarget*12 | H19: =SUM(INDEX(Operating!$E$20:$NL$20,StabMonth):INDEX(Operating!$E$20:$NL$20,StabMonth+11))
B20: Other Income | C20: 50 | D20: =IF(NRSF=0,0,G20/12/NRSF) | E20: =IF(TotalUnits=0,0,G20/12/TotalUnits) | F20: =G20/12 | G20: =OtherIncPerUnitMo*StabLeasedTarget*12 | H20: =SUM(INDEX(Operating!$E$21:$NL$21,StabMonth):INDEX(Operating!$E$21:$NL$21,StabMonth+11))
B21: Retail Income | C21: =RetailRentMo | D21: =IF(NRSF=0,0,G21/12/NRSF) | E21: =IF(TotalUnits=0,0,G21/12/TotalUnits) | F21: =G21/12 | G21: =RetailRentMo*StabilizedOccupancy*12 | H21: =SUM(INDEX(Operating!$E$22:$NL$22,StabMonth):INDEX(Operating!$E$22:$NL$22,StabMonth+11))
B22: Effective Gross Income | D22: =IF(NRSF=0,0,G22/12/NRSF) | E22: =IF(TotalUnits=0,0,G22/12/TotalUnits) | F22: =G22/12 | G22: =SUM(G12:G21) | H22: =SUM(INDEX(Operating!$E$23:$NL$23,StabMonth):INDEX(Operating!$E$23:$NL$23,StabMonth+11))
B23: Operating Expenses
B24: Insurance | C24: 500 | D24: =IF(NRSF=0,0,G24/12/NRSF) | E24: =IF(TotalUnits=0,0,G24/12/TotalUnits) | F24: =G24/12 | G24: =ExpInsurancePerUnit*TotalUnits | H24: =SUM(INDEX(Operating!$E$25:$NL$25,StabMonth):INDEX(Operating!$E$25:$NL$25,StabMonth+11))
B25: Utilities | C25: 1000 | D25: =IF(NRSF=0,0,G25/12/NRSF) | E25: =IF(TotalUnits=0,0,G25/12/TotalUnits) | F25: =G25/12 | G25: =ExpUtilitiesPerUnit*TotalUnits | H25: =SUM(INDEX(Operating!$E$27:$NL$27,StabMonth):INDEX(Operating!$E$27:$NL$27,StabMonth+11))
B26: Payroll | C26: 1544 | D26: =IF(NRSF=0,0,G26/12/NRSF) | E26: =IF(TotalUnits=0,0,G26/12/TotalUnits) | F26: =G26/12 | G26: =ExpPayrollPerUnit*TotalUnits | H26: =SUM(INDEX(Operating!$E$31:$NL$31,StabMonth):INDEX(Operating!$E$31:$NL$31,StabMonth+11))
B27: Management Fee | C27: 0.034 | D27: =IF(NRSF=0,0,G27/12/NRSF) | E27: =IF(TotalUnits=0,0,G27/12/TotalUnits) | F27: =G27/12 | G27: =MgmtFeePct*G22 | H27: =SUM(INDEX(Operating!$E$33:$NL$33,StabMonth):INDEX(Operating!$E$33:$NL$33,StabMonth+11))
B28: Repairs & Maintenance | C28: 365 | D28: =IF(NRSF=0,0,G28/12/NRSF) | E28: =IF(TotalUnits=0,0,G28/12/TotalUnits) | F28: =G28/12 | G28: =ExpRMPerUnit*TotalUnits | H28: =SUM(INDEX(Operating!$E$28:$NL$28,StabMonth):INDEX(Operating!$E$28:$NL$28,StabMonth+11))
B29: Turnover | C29: 335 | D29: =IF(NRSF=0,0,G29/12/NRSF) | E29: =IF(TotalUnits=0,0,G29/12/TotalUnits) | F29: =G29/12 | G29: =ExpTurnoverPerUnit*TotalUnits | H29: =SUM(INDEX(Operating!$E$29:$NL$29,StabMonth):INDEX(Operating!$E$29:$NL$29,StabMonth+11))
B30: Contract Services | C30: =441+408 | D30: =IF(NRSF=0,0,G30/12/NRSF) | E30: =IF(TotalUnits=0,0,G30/12/TotalUnits) | F30: =G30/12 | G30: =ExpContractPerUnit*TotalUnits | H30: =SUM(INDEX(Operating!$E$30:$NL$30,StabMonth):INDEX(Operating!$E$30:$NL$30,StabMonth+11))
B31: Admin & Legal | C31: 478 | D31: =IF(NRSF=0,0,G31/12/NRSF) | E31: =IF(TotalUnits=0,0,G31/12/TotalUnits) | F31: =G31/12 | G31: =ExpAdminPerUnit*TotalUnits | H31: =SUM(INDEX(Operating!$E$26:$NL$26,StabMonth):INDEX(Operating!$E$26:$NL$26,StabMonth+11))
B32: Advertising | C32: 200 | D32: =IF(NRSF=0,0,G32/12/NRSF) | E32: =IF(TotalUnits=0,0,G32/12/TotalUnits) | F32: =G32/12 | G32: =ExpAdvertisingPerUnit*TotalUnits | H32: =SUM(INDEX(Operating!$E$32:$NL$32,StabMonth):INDEX(Operating!$E$32:$NL$32,StabMonth+11))
B33: Property Taxes | C33: =UntrendedTaxRate | D33: =IF(NRSF=0,0,G33/12/NRSF) | E33: =IF(TotalUnits=0,0,G33/12/TotalUnits) | F33: =G33/12 | G33: =IF(TaxYear1Override>0,TaxYear1Override,(G22-SUM(G24:G32))/(EntryCapRate+UntrendedTaxRate)*UntrendedTaxRate) | H33: =SUM(INDEX(Operating!$E$36:$NL$36,StabMonth):INDEX(Operating!$E$36:$NL$36,StabMonth+11))
B34: Total Operating Expenses | D34: =IF(NRSF=0,0,G34/12/NRSF) | E34: =IF(TotalUnits=0,0,G34/12/TotalUnits) | F34: =G34/12 | G34: =SUM(G24:G33) | H34: =SUM(INDEX(Operating!$E$37:$NL$37,StabMonth):INDEX(Operating!$E$37:$NL$37,StabMonth+11))
B35: Net Operating Income | D35: =IF(NRSF=0,0,G35/12/NRSF) | E35: =IF(TotalUnits=0,0,G35/12/TotalUnits) | F35: =G35/12 | G35: =G22-G34 | H35: =SUM(INDEX(Operating!$E$38:$NL$38,StabMonth):INDEX(Operating!$E$38:$NL$38,StabMonth+11))
B36: Below-the-Line Expenses
B37: Capital Reserves | C37: 300 | D37: =IF(NRSF=0,0,G37/12/NRSF) | E37: =IF(TotalUnits=0,0,G37/12/TotalUnits) | F37: =G37/12 | G37: =CapReservePerUnit*TotalUnits
B38: Tax Prep & Appraisal | C38: 0 | D38: =IF(NRSF=0,0,G38/12/NRSF) | E38: =IF(TotalUnits=0,0,G38/12/TotalUnits) | F38: =G38/12 | G38: =TaxPrepPerUnit*TotalUnits
B39: Asset Management Fees | C39: 0.01 | D39: =IF(NRSF=0,0,G39/12/NRSF) | E39: =IF(TotalUnits=0,0,G39/12/TotalUnits) | F39: =G39/12 | G39: =AssetMgmtFeePct*G22
B40: Total Below-the-Line | D40: =IF(NRSF=0,0,G40/12/NRSF) | E40: =IF(TotalUnits=0,0,G40/12/TotalUnits) | F40: =G40/12 | G40: =SUM(G37:G39)
B41: Proforma Operating Cash Flow | D41: =IF(NRSF=0,0,G41/12/NRSF) | E41: =IF(TotalUnits=0,0,G41/12/TotalUnits) | F41: =G41/12 | G41: =G35-G40 | H41: =SUM(INDEX(Operating!$E$42:$NL$42,StabMonth):INDEX(Operating!$E$42:$NL$42,StabMonth+11))
B43: Untrended Stabilized NOI before Property Tax | G43: =G22-SUM(G24:G32)
B45: Reconciliation
...

Sheet Inputs
B1: ="Multifamily Development Model — Master Input | "&PropertyName
B3: Levered IRR (net) | E3: Levered MOIC | H3: Untrended YOC | K3: Dev Spread | N3: TDC | Q3: TDC / Unit
B4: =LevIRR | E4: =LevMOIC | H4: =YieldOnCost | K4: =DevSpreadBps | N4: =TDC_Total | R4: =TDCperUnit
B6: Unlevered IRR (net) | E6: Unlevered MOIC | H6: Static Value | K6: Realized LTC | N6: Debt Yield (stab) | Q6: Model Status
B7: =UnlevIRR | E7: =UnlevMOIC | H7: =StaticValue | K7: =LTC_Realized | N7: =DebtYieldStab | Q7: =IF(ErrorsFound=0,"PASS","REVIEW")
B8: Property Details | J8: Permanent Loan (Refinance) | N8: Site Details | R8: Derived & Static Value
B9: Investment Type | C9: Ground-Up Development | J9: Perm Max LTV | K9: 0.65 | N9: Land Cost | O9: 567000 | R9: Effective Tax Rate on Value | S9: =TaxLevyPct*TaxAssessmentPct*TaxValueAdjFactor
B10: Property Name | C10: The Verde | J10: Perm Rate | K10: 0.0625 | N10: Gross Acres | O10: 3.65 | R10: Stabilized Tax / Unit / Yr | S10: =IF(TotalUnits=0,0,StabTaxAnnual/TotalUnits)
B11: City | C11: Cottonwood | J11: Perm Term (mo) | K11: 360 | N11: Net Acres | O11: =+GrossAcres | R11: Static Value (Untrended NOI ÷ Entry Cap) | S11: =IF(EntryCapRate=0,0,StabNOI_Untrended/EntryCapRate)
B12: State | C12: AZ | J12: Perm I/O (mo) | K12: 24 | N12: FAR Ratio | O12: 1.75 | R12: Static Value / Unit | S12: =IF(TotalUnits=0,0,StaticValue/TotalUnits)
B13: Market | C13: Verde Valley | J13: Perm Amort (mo) | K13: 360 | N13: Efficiency Ratio | O13: 0.85 | R13: Density (units / net acre) | S13: =IF(NetAcres=0,0,TotalUnits/NetAcres)
B14: Product Type | C14: Garden | J14: Perm Interest Calc | K14: 30/360 | L14: =IF(K14="Actual/360",1,0) | N14: Existing Structure Cost | O14: 0 | R14: Max Buildable SF by FAR | S14: =FARRatio*NetAcres*43560
B15: Location | C15: Suburban | J15: Perm Points | K15: 0.0075
B16: Open Escrow Date | C16: 46210 | J16: Perm Min Debt Yield | K16: 0.08 | R16: Input Sanity (soft warnings)
J17: Perm Min DSCR | K17: 1.15 | R17: Construction term ≤ 48 mo | S17: =ConLoanTermMonths | T17: =IF(ConLoanTermMonths<=48,"OK","CHECK")
B18: Investment Details | J18: Cash-Out at Refi | K18: Cash-Out Permitted | L18: =IF(K18="No Cash-Out (solve LTV to zero)",1,0) | R18: Stab tax/unit $500–$4,000 | S18: =IF(TotalUnits=0,0,StabTaxAnnual/TotalUnits) | T18: =IF(AND(StabTaxAnnual/TotalUnits>=500,StabTaxAnnual/TotalUnits<=4000),"OK","CHECK")
B19: Hold Period (mo) | C19: 120 | J19: Refi Month Override | K19: 0 | R19: Absorption ≤ delivery pace | S19: =UnitsLeasedPerMo | T19: =IF(UnitsLeasedPerMo<=UnitsDeliveredPerMo,"OK","CHECK")
B20: Entry Cap Rate | C20: 0.0525 | R20: Untrended YOC ≥ exit cap | S20: =YieldOnCost-ExitCapResidential | T20: =IF(YieldOnCost>=ExitCapResidential,"OK","CHECK")
F21: Capitalization & Funding | J21: Sponsor Fees | R21: Occupancy 85%–98% | S21: =StabilizedOccupancy | T21: =IF(AND(StabilizedOccupancy>=0.85,StabilizedOccupancy<=0.98),"OK","CHECK")
B22: Cap Rate & Adjustments | F22: Funding Order | G22: Equity First | H22: =IF(G22="Pari-Passu",1,0) | J22: Dev Fee % of Direct | K22: 0 | R22: Rent growth ≤ 5% | S22: =GrowthRent | T22: =IF(GrowthRent<=0.05,"OK","CHECK")
B23: Cap Adj — Location | C23: 0 | F23: Target LTC | G23: 0.65 | J23: 3rd-Party Fee Split | K23: 0 | R23: Sanity checks flagged | S23: =COUNTIF(T17:T22,"CHECK")
B24: Cap Adj — Size | C24: 0 | F24: Op Reserve Coverage | G24: 1.1 | J24: Sponsor Dispo Fee | K24: 0
B25: Cap Adj — Aging | C25: 0 | F25: Op Reserve Min Months | G25: 3 | J25: Recourse Fee | K25: 0
B26: Exit Cap — Residential | C26: =EntryCapRate+CapAdjLocation+CapAdjSize+CapAdjAging
B27: Exit Cap — Retail | C27: 0.065 | F27: Construction Loan | J27: Disposition & Sale
F28: Con Loan Term (mo) | G28: 36 | J28: Broker / Sale Cost | K28: 0.01
B29: Default Growth Rates | F29: Con Rate | G29: 0.057 | J29: Transfer / Sales Tax | K29: 0
B30: Rent Growth | C30: 0.03 | F30: Con Interest Calc | G30: Actual/360 | H30: =IF(G30="Actual/360",1,0) | J30: Tax Proration (mo) | K30: 2
B31: Low-Income Rent Growth | C31: 0.03 | F31: Con Points | G31: 0.01
B32: Expense Growth | C32: 0.03 | F32: Con Other Costs | G32: 250000 | J32: Property Taxes
B33: Utility Growth | C33: 0.03 | F33: Con Min Debt Yield | G33: 0.07 | J33: Tax Levy % | K33: 0.0185
B34: Tax Growth | C34: 0.03 | F34: Con Min DSCR | G34: 1.15 | J34: Assessment Ratio % | K34: 0.1
B35: Other-Income Growth | C35: 0.03 | F35: Lender Reserve Override | G35: 0 | J35: Value-Adj Factor | K35: 0.5
B36: Growth Start Date (effective) | C36: =IF(ISNUMBER(GrowthStartOverride),GrowthStartOverride,EOMONTH(InceptionDate,1)) | J36: Post-Stab Tax Method | K36: Value Approach | L36: =IF(K36="Value Approach",1,0)
B37: → Override (blank = auto) | F37: Construction Interest & Refi | J37: Year-1 Tax Override | K37: 0
B38: Unit Delivery & Lease-Up | F38: Refi Lag (mo) | G38: 1 | J38: Dispo Tax Driver | K38: Imputed | L38: =IF(K38="Reassessed",1,0)
B39: Lease-Up Income | C39: Offset vs equity | D39: =IF(C39="Offset vs equity",1,0) | F39: Interest Method | G39: Current Pay | H39: =IF(G39="Current Pay",1,0) | J39: Buyer Tax Rate | K39: 0
B40: Units Delivered / Mo | C40: 24 | F40: Interest Conversion Mo | G40: 0 | J40: Lease-Up Tax | K40: Capitalize in budget | L40: =IF(K40="Capitalize in budget",1,0)
B41: Units Leased / Mo | C41: 18
B42: Lease-Up Opex Ramp | C42: 0.6
...

Sheet UnitMatrix
B1: Unit Matrix — Residential & Retail
B3: Plan | C3: Class | D3: Units | E3: Avg SF | F3: Total SF | G3: Market Rent | H3: Net Eff. Rent | I3: Annual Rent | J3: Rent / SF | K3: % of Total
B4: Studio | C4: Market | D4: 30 | E4: 750 | F4: =D4*E4 | G4: 1625 | H4: =+G4 | I4: =D4*G4*12 | J4: =IF(E4=0,0,G4/E4) | K4: =IF(TotalUnits=0,0,D4/TotalUnits)
B5: 1BR-A | C5: Market | D5: 38 | E5: 1025 | F5: =D5*E5 | G5: 1850 | H5: =+G5 | I5: =D5*G5*12 | J5: =IF(E5=0,0,G5/E5) | K5: =IF(TotalUnits=0,0,D5/TotalUnits)
B6: 1BR-B | C6: Market | D6: 0 | E6: 0 | F6: =D6*E6 | G6: 0 | H6: =+G6 | I6: =D6*G6*12 | J6: =IF(E6=0,0,G6/E6) | K6: =IF(TotalUnits=0,0,D6/TotalUnits)
B7: 2BR-A | C7: Market | D7: 0 | E7: 0 | F7: =D7*E7 | G7: 0 | H7: =+G7 | I7: =D7*G7*12 | J7: =IF(E7=0,0,G7/E7) | K7: =IF(TotalUnits=0,0,D7/TotalUnits)
B8: 2BR-B | C8: Market | D8: 0 | E8: 0 | F8: =D8*E8 | G8: 0 | H8: =+G8 | I8: =D8*G8*12 | J8: =IF(E8=0,0,G8/E8) | K8: =IF(TotalUnits=0,0,D8/TotalUnits)
B9: 1BR-LI | C9: Low | D9: 0 | E9: 0 | F9: =D9*E9 | G9: 0 | H9: =+G9 | I9: =D9*G9*12 | J9: =IF(E9=0,0,G9/E9) | K9: =IF(TotalUnits=0,0,D9/TotalUnits)
B10: 2BR-LI | C10: Low | D10: 0 | E10: 0 | F10: =D10*E10 | G10: 0 | H10: =+G10 | I10: =D10*G10*12 | J10: =IF(E10=0,0,G10/E10) | K10: =IF(TotalUnits=0,0,D10/TotalUnits)
B11: Total / Weighted | D11: =SUM(D4:D10) | E11: =SUMPRODUCT(E4:E10,$D$4:$D$10)/$D$11 | F11: =SUM(F4:F10) | G11: =SUMPRODUCT(G4:G10,$D$4:$D$10)/$D$11 | H11: =SUMPRODUCT(H4:H10,$D$4:$D$10)/$D$11 | I11: =SUM(I4:I10) | J11: =SUMPRODUCT(J4:J10,$D$4:$D$10)/$D$11 | K11: =SUM(K4:K10)
B13: Derived Unit Metrics
B14: Total Units | C14: =SUM(D4:D10)
B15: Market-Rate Units | C15: =SUMIF(C4:C10,"Market",D4:D10)
B16: Low-Income Units | C16: =SUMIF(C4:C10,"Low",D4:D10)
B17: Net Rentable SF (NRSF) | C17: =SUM(F4:F10)
B18: Buildable SF | C18: =NRSF/EfficiencyRatio
B19: Avg Unit SF | C19: =IF(TotalUnits=0,0,NRSF/TotalUnits)
B20: Base Market Rent / mo | C20: =SUMPRODUCT((C4:C10="Market")*D4:D10*G4:G10)
B21: Base Low-Income Rent / mo | C21: =SUMPRODUCT((C4:C10="Low")*D4:D10*G4:G10)
B23: Retail Matrix
B24: Suite | C24: SF | D24: Rent / SF / yr | E24: Annual Rent | F24: Monthly Rent
B25: Retail-1 | C25: 0 | D25: 0 | E25: =C25*D25 | F25: =C25*D25/12
B26: Retail-2 | C26: 0 | D26: 0 | E26: =C26*D26 | F26: =C26*D26/12
B27: Retail Rent / mo | C27: =SUM(F25:F26)

Sheet Budget
B1: Development Budget & Cost Assumptions
B2: Basis: abs=$ unit=$/unit sf=$/NRSF. Modifier shifts the phase start/end by whole months (+later / −earlier). Modeled Total drives the cost-curve engine.
I3: ± months vs. phase
B4: Line Item | C4: Group | D4: Type | E4: Basis | F4: Amount | G4: Phase | H4: Cost Curve | I4: Modifier (months) | J4: Modeled Total | K4: Per Unit | L4: Per SF | M4: % of TDC
B5: Land Purchase Costs | C5: Land | D5: Land | E5: abs | F5: =LandCost | G5: Pre-Construction | H5: Single_Point | I5: 0 | J5: =IF(E5="abs",F5,IF(E5="unit",F5*TotalUnits,IF(E5="sf",F5*NRSF,F5))) | K5: =IF(TotalUnits=0,0,J5/TotalUnits) | L5: =IF(NRSF=0,0,J5/NRSF) | M5: =IF(TDC_Total=0,0,J5/TDC_Total)
B6: Broker Fee | C6: Land | D6: Land | E6: abs | F6: 0 | G6: Entitlement | H6: Single_Point | I6: 0 | J6: =IF(E6="abs",F6,IF(E6="unit",F6*TotalUnits,IF(E6="sf",F6*NRSF,F6))) | K6: =IF(TotalUnits=0,0,J6/TotalUnits) | L6: =IF(NRSF=0,0,J6/NRSF) | M6: =IF(TDC_Total=0,0,J6/TDC_Total)
B7: Other Land Cost | C7: Land | D7: Land | E7: abs | F7: 0 | G7: Entitlement | H7: Single_Point | I7: 0 | J7: =IF(E7="abs",F7,IF(E7="unit",F7*TotalUnits,IF(E7="sf",F7*NRSF,F7))) | K7: =IF(TotalUnits=0,0,J7/TotalUnits) | L7: =IF(NRSF=0,0,J7/NRSF) | M7: =IF(TDC_Total=0,0,J7/TDC_Total)
B8: Legal: Entity Formation | C8: Soft | D8: Due Diligence | E8: abs | F8: 0 | G8: Entitlement | H8: Straight_Line | I8: 0 | J8: =IF(E8="abs",F8,IF(E8="unit",F8*TotalUnits,IF(E8="sf",F8*NRSF,F8))) | K8: =IF(TotalUnits=0,0,J8/TotalUnits) | L8: =IF(NRSF=0,0,J8/NRSF) | M8: =IF(TDC_Total=0,0,J8/TDC_Total)
B9: Legal: Closing Costs/Title/Escrow | C9: Soft | D9: Due Diligence | E9: abs | F9: 0 | G9: Entitlement | H9: Straight_Line | I9: 0 | J9: =IF(E9="abs",F9,IF(E9="unit",F9*TotalUnits,IF(E9="sf",F9*NRSF,F9))) | K9: =IF(TotalUnits=0,0,J9/TotalUnits) | L9: =IF(NRSF=0,0,J9/NRSF) | M9: =IF(TDC_Total=0,0,J9/TDC_Total)
B10: Legal: Misc. | C10: Soft | D10: Due Diligence | E10: abs | F10: 0 | G10: Construction | H10: Straight_Line | I10: 0 | J10: =IF(E10="abs",F10,IF(E10="unit",F10*TotalUnits,IF(E10="sf",F10*NRSF,F10))) | K10: =IF(TotalUnits=0,0,J10/TotalUnits) | L10: =IF(NRSF=0,0,J10/NRSF) | M10: =IF(TDC_Total=0,0,J10/TDC_Total)
B11: HOA/CC&R's/Land Use | C11: Soft | D11: Due Diligence | E11: abs | F11: 0 | G11: Lease-Up | H11: Straight_Line | I11: 0 | J11: =IF(E11="abs",F11,IF(E11="unit",F11*TotalUnits,IF(E11="sf",F11*NRSF,F11))) | K11: =IF(TotalUnits=0,0,J11/TotalUnits) | L11: =IF(NRSF=0,0,J11/NRSF) | M11: =IF(TDC_Total=0,0,J11/TDC_Total)
B12: Market Study/Appraisal | C12: Soft | D12: Due Diligence | E12: abs | F12: 0 | G12: Entitlement | H12: Straight_Line | I12: 0 | J12: =IF(E12="abs",F12,IF(E12="unit",F12*TotalUnits,IF(E12="sf",F12*NRSF,F12))) | K12: =IF(TotalUnits=0,0,J12/TotalUnits) | L12: =IF(NRSF=0,0,J12/NRSF) | M12: =IF(TDC_Total=0,0,J12/TDC_Total)
B13: Other Due Diligence (DD Report, Tax, Misc.) | C13: Soft | D13: Due Diligence | E13: abs | F13: 60000 | G13: Due Diligence | H13: Straight_Line | I13: 0 | J13: =IF(E13="abs",F13,IF(E13="unit",F13*TotalUnits,IF(E13="sf",F13*NRSF,F13))) | K13: =IF(TotalUnits=0,0,J13/TotalUnits) | L13: =IF(NRSF=0,0,J13/NRSF) | M13: =IF(TDC_Total=0,0,J13/TDC_Total)
B14: Municipal Fees: Entitlement Phase | C14: Soft | D14: Entitlements | E14: abs | F14: 0 | G14: Entitlement | H14: Straight_Line | I14: 0 | J14: =IF(E14="abs",F14,IF(E14="unit",F14*TotalUnits,IF(E14="sf",F14*NRSF,F14))) | K14: =IF(TotalUnits=0,0,J14/TotalUnits) | L14: =IF(NRSF=0,0,J14/NRSF) | M14: =IF(TDC_Total=0,0,J14/TDC_Total)
B15: Municipal Fees: Plan Review Fees | C15: Soft | D15: Entitlements | E15: abs | F15: 0 | G15: Entitlement | H15: Straight_Line | I15: 0 | J15: =IF(E15="abs",F15,IF(E15="unit",F15*TotalUnits,IF(E15="sf",F15*NRSF,F15))) | K15: =IF(TotalUnits=0,0,J15/TotalUnits) | L15: =IF(NRSF=0,0,J15/NRSF) | M15: =IF(TDC_Total=0,0,J15/TDC_Total)
B16: Municipal Fees: Development Fees | C16: Soft | D16: Entitlements | E16: abs | F16: 460000 | G16: Entitlement | H16: Straight_Line | I16: 0 | J16: =IF(E16="abs",F16,IF(E16="unit",F16*TotalUnits,IF(E16="sf",F16*NRSF,F16))) | K16: =IF(TotalUnits=0,0,J16/TotalUnits) | L16: =IF(NRSF=0,0,J16/NRSF) | M16: =IF(TDC_Total=0,0,J16/TDC_Total)
B17: Municipal Fees: Permit Fees | C17: Soft | D17: Entitlements | E17: abs | F17: 0 | G17: Entitlement | H17: Straight_Line | I17: 0 | J17: =IF(E17="abs",F17,IF(E17="unit",F17*TotalUnits,IF(E17="sf",F17*NRSF,F17))) | K17: =IF(TotalUnits=0,0,J17/TotalUnits) | L17: =IF(NRSF=0,0,J17/NRSF) | M17: =IF(TDC_Total=0,0,J17/TDC_Total)
... B84: Off Site Improvements (Not Included Above) | C84: Hard | D84: Hard | E84: abs | F84: 0 | G84: Construction | H84: Straight_Line | I84: 0 | J84: =IF(E84="abs",F84,IF(E84="unit",F84*TotalUnits,IF(E84="sf",F84*NRSF,F84))) | K84: =IF(TotalUnits=0,0,J84/TotalUnits) | L84: =IF(NRSF=0,0,J84/NRSF) | M84: =IF(TDC_Total=0,0,J84/TDC_Total)
B85: Demolition (Not Included Above) | C85: Hard | D85: Hard | E85: abs | F85: =ExistingStructureCost | G85: Construction | H85: Straight_Line | I85: 0 | J85: =IF(E85="abs",F85,IF(E85="unit",F85*TotalUnits,IF(E85="sf",F85*NRSF,F85))) | K85: =IF(TotalUnits=0,0,J85/TotalUnits) | L85: =IF(NRSF=0,0,J85/NRSF) | M85: =IF(TDC_Total=0,0,J85/TDC_Total)
B86: Utility System Installation Costs | C86: Hard | D86: Hard | E86: abs | F86: 0 | G86: Construction | H86: Straight_Line | I86: 0 | J86: =IF(E86="abs",F86,IF(E86="unit",F86*TotalUnits,IF(E86="sf",F86*NRSF,F86))) | K86: =IF(TotalUnits=0,0,J86/TotalUnits) | L86: =IF(NRSF=0,0,J86/NRSF) | M86: =IF(TDC_Total=0,0,J86/TDC_Total)
B87: Other Hard Costs Outside GC Contract | C87: Hard | D87: Hard | E87: abs | F87: 0 | G87: Lease-Up | H87: Straight_Line | I87: 0 | J87: =IF(E87="abs",F87,IF(E87="unit",F87*TotalUnits,IF(E87="sf",F87*NRSF,F87))) | K87: =IF(TotalUnits=0,0,J87/TotalUnits) | L87: =IF(NRSF=0,0,J87/NRSF) | M87: =IF(TDC_Total=0,0,J87/TDC_Total)
B88: Hard Cost Contingency | C88: Hard | D88: Hard | E88: abs | F88: 0 | G88: Construction | H88: Straight_Line | I88: 0 | J88: =IF(E88="abs",F88,IF(E88="unit",F88*TotalUnits,IF(E88="sf",F88*NRSF,F88))) | K88: =IF(TotalUnits=0,0,J88/TotalUnits) | L88: =IF(NRSF=0,0,J88/NRSF) | M88: =IF(TDC_Total=0,0,J88/TDC_Total)
B89: Tenant Improvements | C89: Hard | D89: Hard | E89: abs | F89: 0 | G89: Lease-Up | H89: Straight_Line | I89: 0 | J89: =IF(E89="abs",F89,IF(E89="unit",F89*TotalUnits,IF(E89="sf",F89*NRSF,F89))) | K89: =IF(TotalUnits=0,0,J89/TotalUnits) | L89: =IF(NRSF=0,0,J89/NRSF) | M89: =IF(TDC_Total=0,0,J89/TDC_Total)
B90: Taxes - State Excise & Other | C90: Hard | D90: Hard | E90: abs | F90: 0 | G90: Construction | H90: Bell_Curve | I90: 0 | J90: =IF(E90="abs",F90,IF(E90="unit",F90*TotalUnits,IF(E90="sf",F90*NRSF,F90))) | K90: =IF(TotalUnits=0,0,J90/TotalUnits) | L90: =IF(NRSF=0,0,J90/NRSF) | M90: =IF(TDC_Total=0,0,J90/TDC_Total)
B91: Insurance - Builders Risk, OCIP, Pollution | C91: Hard | D91: Hard | E91: abs | F91: 0 | G91: Construction | H91: Straight_Line | I91: 0 | J91: =IF(E91="abs",F91,IF(E91="unit",F91*TotalUnits,IF(E91="sf",F91*NRSF,F91))) | K91: =IF(TotalUnits=0,0,J91/TotalUnits) | L91: =IF(NRSF=0,0,J91/NRSF) | M91: =IF(TDC_Total=0,0,J91/TDC_Total)
B92: Unit Finish Upgrades Outside GC Contract | C92: Hard | D92: Hard | E92: abs | F92: 0 | G92: Construction | H92: Straight_Line | I92: 0 | J92: =IF(E92="abs",F92,IF(E92="unit",F92*TotalUnits,IF(E92="sf",F92*NRSF,F92))) | K92: =IF(TotalUnits=0,0,J92/TotalUnits) | L92: =IF(NRSF=0,0,J92/NRSF) | M92: =IF(TDC_Total=0,0,J92/TDC_Total)
B93: GC Fee | C93: Hard | D93: Hard | E93: abs | F93: 0 | G93: Construction | H93: Bell_Curve | I93: 0 | J93: =IF(E93="abs",F93,IF(E93="unit",F93*TotalUnits,IF(E93="sf",F93*NRSF,F93))) | K93: =IF(TotalUnits=0,0,J93/TotalUnits) | L93: =IF(NRSF=0,0,J93/NRSF) | M93: =IF(TDC_Total=0,0,J93/TDC_Total)
B94: Other Hard Cost Item 1 | C94: Hard | D94: Hard | E94: abs | F94: 0 | G94: Construction | H94: Straight_Line | I94: 0 | J94: =IF(E94="abs",F94,IF(E94="unit",F94*TotalUnits,IF(E94="sf",F94*NRSF,F94))) | K94: =IF(TotalUnits=0,0,J94/TotalUnits) | L94: =IF(NRSF=0,0,J94/NRSF) | M94: =IF(TDC_Total=0,0,J94/TDC_Total)
B95: Other Hard Cost Item 2 | C95: Hard | D95: Hard | E95: abs | F95: 0 | G95: Construction | H95: Straight_Line | I95: 0 | J95: =IF(E95="abs",F95,IF(E95="unit",F95*TotalUnits,IF(E95="sf",F95*NRSF,F95))) | K95: =IF(TotalUnits=0,0,J95/TotalUnits) | L95: =IF(NRSF=0,0,J95/NRSF) | M95: =IF(TDC_Total=0,0,J95/TDC_Total)
B96: Other Hard Cost Item 3 | C96: Hard | D96: Hard | E96: abs | F96: 0 | G96: Construction | H96: Straight_Line | I96: 0 | J96: =IF(E96="abs",F96,IF(E96="unit",F96*TotalUnits,IF(E96="sf",F96*NRSF,F96))) | K96: =IF(TotalUnits=0,0,J96/TotalUnits) | L96: =IF(NRSF=0,0,J96/NRSF) | M96: =IF(TDC_Total=0,0,J96/TDC_Total)
B97: Other Hard Cost Item 4 | C97: Hard | D97: Hard | E97: abs | F97: 0 | G97: Construction | H97: Straight_Line | I97: 0 | J97: =IF(E97="abs",F97,IF(E97="unit",F97*TotalUnits,IF(E97="sf",F97*NRSF,F97))) | K97: =IF(TotalUnits=0,0,J97/TotalUnits) | L97: =IF(NRSF=0,0,J97/NRSF) | M97: =IF(TDC_Total=0,0,J97/TDC_Total)
B99: Financing & Reserves (captured in capitalization — not in Direct Costs)
B100: Points / Origination | C100: Memo | D100: Financing & Reserves | E100: abs | F100: =ConPoints | J100: =F100 | M100: =IF(TDC_Total=0,0,J100/TDC_Total)
B101: Other Loan / Closing Costs | C101: Memo | D101: Financing & Reserves | E101: abs | F101: =ConOtherCosts | J101: =F101 | M101: =IF(TDC_Total=0,0,J101/TDC_Total)
B102: Recourse / Indemnity Fee | C102: Memo | D102: Financing & Reserves | E102: abs | F102: =RecourseFee | J102: =F102 | M102: =IF(TDC_Total=0,0,J102/TDC_Total)
B103: Debt Service (Interest Reserve) | C103: Memo | D103: Financing & Reserves | E103: abs | F103: =InterestReserveFunded | J103: =F103 | M103: =IF(TDC_Total=0,0,J103/TDC_Total)
B104: Operating Reserve / Initial Operating Deficit | C104: Memo | D104: Financing & Reserves | E104: abs | F104: =OpReserve | J104: =F104 | M104: =IF(TDC_Total=0,0,J104/TDC_Total)
B105: Construction-Period Property Taxes | C105: Memo | D105: Financing & Reserves | E105: abs | F105: =ConTaxTotal | J105: =F105 | M105: =IF(TDC_Total=0,0,J105/TDC_Total)
B106: Sponsor Development Fee | C106: Memo | D106: Financing & Reserves | E106: abs | F106: =DevFee | J106: =F106 | M106: =IF(TDC_Total=0,0,J106/TDC_Total)
B108: Budget Summary
...

Sheet Timeline
B1: Timeline Engine — Milestones & Monthly Period Grid
B3: Milestone | C3: Start (mo) | D3: Duration (mo) | E3: End (mo)
B4: Due Diligence | C4: 1 | D4: 4 | E4: =SUM(C4:D4)-1
B5: Entitlement | C5: =+MS_Due_Diligence_End | D5: 5 | E5: =SUM(C5:D5)-1
B6: Pre-Construction | C6: =+MS_Entitlement_End | D6: 3 | E6: =SUM(C6:D6)-1
B7: Construction | C7: =+MS_Pre_Construction_End | D7: 22 | E7: =SUM(C7:D7)-1
B8: 1st Unit Delivery | C8: =+MS_Construction_Start+DeliveryLagMonths | D8: 1 | E8: =SUM(C8:D8)-1
B9: Lease-Up | C9: =+MS_1st_Unit_Delivery_Start | D9: =MAX(CEILING(StabLeasedTarget/UnitsLeasedPerMo,1),CEILING(StabLeasedTarget/UnitsDeliveredPerMo,1)) | E9: =SUM(C9:D9)-1
B10: Stabilization | C10: =+MS_Lease_Up_End | D10: 1 | E10: =SUM(C10:D10)-1
A11: Exit | B11: Recapitalization/Refinance | C11: =IF(RefiFlag=1,RefiMonth,MS_Stabilization_End) | D11: 1 | E11: =SUM(C11:D11)-1
B12: Disposition | C12: =HoldPeriodMonths | D12: 1 | E12: =SUM(C12:D12)-1
B16: Key Timing (derived)
B17: Construction Start | C17: =MS_Construction_Start
B18: Construction Maturity | C18: =ConStart+ConLoanTermMonths-1
B19: 1st Unit Delivery | C19: =MS_1st_Unit_Delivery_Start
B20: Stabilization Month | C20: =MS_Stabilization_Start
B21: Disposition Month | C21: =HoldPeriodMonths
B22: Growth Start Month | C22: =(YEAR(GrowthStartDate)-YEAR(InceptionDate))*12+MONTH(GrowthStartDate)-MONTH(InceptionDate)
B23: Refi Flag (1=refi,0=sell) | C23: =IF(DispoMonth>ConMaturity,1,0)
B24: Refi Month | C24: =IF(RefiFlag=1,MIN(ConMaturity,IF(RefiMonthOverride>0,RefiMonthOverride,MAX(StabMonth,ConEndMonth)+RefiLagMonths)),0)
B25: Con Payoff Month | C25: =IF(RefiFlag=1,RefiMonth,DispoMonth)
B27: Monthly Period Grid
B28: Period → | D28: Total | E28: 1 | F28: 2 | G28: 3 | H28: 4 | I28: 5 | J28: 6 | K28: 7 | L28: 8 | M28: 9 | N28: 10 | O28: 11 | P28: 12 | Q28: 13 | R28: 14 | S28: 15 | T28: 16 | U28: 17 | V28: 18 | W28: 19 | X28: 20 | Y28: 21 | Z28: 22 | AA28: 23 | AB28: 24 | AC28: 25 | AD28: 26 | AE28: 27 | AF28: 28 | AG28: 29 | AH28: 30 | AI28: 31 | AJ28: 32 | AK28: 33 | AL28: 34 | AM28: 35 | AN28: 36 | AO28: 37 | AP28: 38 | AQ28: 39 | AR28: 40 | AS28: 41 | AT28: 42 | AU28: 43 | AV28: 44 | AW28: 45 | AX28: 46 | AY28: 47 | AZ28: 48 | BA28: 49 | BB28: 50 | BC28: 51 | BD28: 52 | BE28: 53 | BF28: 54 | BG28: 55 | BH28: 56 | BI28: 57 | BJ28: 58 | BK28: 59 | BL28: 60 | BM28: 61 | BN28: 62 | BO28: 63 | BP28: 64 | BQ28: 65 | BR28: 66 | BS28: 67 | BT28: 68 | BU28: 69 | BV28: 70 | BW28: 71 | BX28: 72 | BY28: 73 | BZ28: 74 | CA28: 75 | CB28: 76 | CC28: 77 | CD28: 78 | CE28: 79 | CF28: 80 | CG28: 81 | CH28: 82 | CI28: 83 | CJ28: 84 | CK28: 85 | CL28: 86 | CM28: 87 | CN28: 88 | CO28: 89 | CP28: 90 | CQ28: 91 | CR28: 92 | CS28: 93 | CT28: 94 | CU28: 95 | CV28: 96 | CW28: 97 | CX28: 98 | CY28: 99 | CZ28: 100 | DA28: 101 | DB28: 102 | DC28: 103 | DD28: 104 | DE28: 105 | DF28: 106 | DG28: 107 | DH28: 108 | DI28: 109 | DJ28: 110 | DK28: 111 | DL28: 112 | DM28: 113 | DN28: 114 | DO28: 115 | DP28: 116 | DQ28: 117 | DR28: 118 | DS28: 119 | DT28: 120 | DU28: 121 | DV28: 122 | DW28: 123 | DX28: 124 | DY28: 125 | DZ28: 126 | EA28: 127 | EB28: 128 | EC28: 129 | ED28: 130 | EE28: 131 | EF28: 132 | EG28: 133 | EH28: 134 | EI28: 135 | EJ28: 136 | EK28: 137 | EL28: 138 | EM28: 139 | EN28: 140 | EO28: 141 | EP28: 142 | EQ28: 143 | ER28: 144 | ES28: 145 | ET28: 146 | EU28: 147 | EV28: 148 | EW28: 149 | EX28: 150 | EY28: 151 | EZ28: 152 | FA28: 153 | FB28: 154 | FC28: 155 | FD28: 156 | FE28: 157 | FF28: 158 | FG28: 159 | FH28: 160 | FI28: 161 | FJ28: 162 | FK28: 163 | FL28: 164 | FM28: 165 | FN28: 166 | FO28: 167 | FP28: 168 | FQ28: 169 | FR28: 170 | FS28: 171 | FT28: 172 | FU28: 173 | FV28: 174 | FW28: 175 | FX28: 176 | FY28: 177 | FZ28: 178 | GA28: 179 | GB28: 180 | GC28: 181 | GD28: 182 | GE28: 183 | GF28: 184 | GG28: 185 | GH28: 186 | GI28: 187 | GJ28: 188 | GK28: 189 | GL28: 190 | GM28: 191 | GN28: 192 | GO28: 193 | GP28: 194 | GQ28: 195 | GR28: 196 | GS28: 197 | GT28: 198 | GU28: 199 | GV28: 200 | GW28: 201 | GX28: 202 | GY28: 203 | GZ28: 204 | HA28: 205 | HB28: 206 | HC28: 207 | HD28: 208 | HE28: 209 | HF28: 210 | HG28: 211 | HH28: 212 | HI28: 213 | HJ28: 214 | HK28: 215 | HL28: 216 | HM28: 217 | HN28: 218 | HO28: 219 | HP28: 220 | HQ28: 221 | HR28: 222 | HS28: 223 | HT28: 224 | HU28: 225 | HV28: 226 | HW28: 227 | HX28: 228 | HY28: 229 | HZ28: 230 | IA28: 231 | IB28: 232 | IC28: 233 | ID28: 234 | IE28: 235 | IF28: 236 | IG28: 237 | IH28: 238 | II28: 239 | IJ28: 240 | IK28: 241 | IL28: 242 | IM28: 243 | IN28: 244 | IO28: 245 | IP28: 246 | IQ28: 247 | IR28: 248 | IS28: 249 | IT28: 250 | IU28: 251 | IV28: 252 | IW28: 253 | IX28: 254 | IY28: 255 | IZ28: 256 | JA28: 257 | JB28: 258 | JC28: 259 | JD28: 260 | JE28: 261 | JF28: 262 | JG28: 263 | JH28: 264 | JI28: 265 | JJ28: 266 | JK28: 267 | JL28: 268 | JM28: 269 | JN28: 270 | JO28: 271 | JP28: 272 | JQ28: 273 | JR28: 274 | JS28: 275 | JT28: 276 | JU28: 277 | JV28: 278 | JW28: 279 | JX28: 280 | JY28: 281 | JZ28: 282 | KA28: 283 | KB28: 284 | KC28: 285 | KD28: 286 | KE28: 287 | KF28: 288 | KG28: 289 | KH28: 290 | KI28: 291 | KJ28: 292 | KK28: 293 | KL28: 294 | KM28: 295 | KN28: 296 | KO28: 297 | KP28: 298 | KQ28: 299 | KR28: 300 | KS28: 301 | KT28: 302 | KU28: 303 | KV28: 304 | KW28: 305 | KX28: 306 | KY28: 307 | KZ28: 308 | LA28: 309 | LB28: 310 | LC28: 311 | LD28: 312 | LE28: 313 | LF28: 314 | LG28: 315 | LH28: 316 | LI28: 317 | LJ28: 318 | LK28: 319 | LL28: 320 | LM28: 321 | LN28: 322 | LO28: 323 | LP28: 324 | LQ28: 325 | LR28: 326 | LS28: 327 | LT28: 328 | LU28: 329 | LV28: 330 | LW28: 331 | LX28: 332 | LY28: 333 | LZ28: 334 | MA28: 335 | MB28: 336 | MC28: 337 | MD28: 338 | ME28: 339 | MF28: 340 | MG28: 341 | MH28: 342 | MI28: 343 | MJ28: 344 | MK28: 345 | ML28: 346 | MM28: 347 | MN28: 348 | MO28: 349 | MP28: 350 | MQ28: 351 | MR28: 352 | MS28: 353 | MT28: 354 | MU28: 355 | MV28: 356 | MW28: 357 | MX28: 358 | MY28: 359 | MZ28: 360 | NA28: 361 | NB28: 362 | NC28: 363 | ND28: 364 | NE28: 365 | NF28: 366 | NG28: 367 | NH28: 368 | NI28: 369 | NJ28: 370 | NK28: 371 | NL28: 372
