Workbook
Name InvestmentType: 'Inputs'!$B$5
Name PropertyName: 'Inputs'!$B$6
Name City: 'Inputs'!$B$7
Name State: 'Inputs'!$B$8
Name Market: 'Inputs'!$B$9
Name ProductType: 'Inputs'!$B$10
Name Location: 'Inputs'!$B$11
Name InceptionDate: 'Inputs'!$B$12
Name HoldPeriodMonths: 'Inputs'!$B$15
Name EntryCapRate: 'Inputs'!$B$16
Name CapAdjLocation: 'Inputs'!$B$17
Name CapAdjSize: 'Inputs'!$B$18
Name CapAdjAging: 'Inputs'!$B$19
Name ExitCapResidential: 'Inputs'!$B$20
Name ExitCapRetail: 'Inputs'!$B$21
Name GrowthRent: 'Inputs'!$B$22
Name GrowthLowIncRent: 'Inputs'!$B$23
Name GrowthExpense: 'Inputs'!$B$24
Name GrowthUtility: 'Inputs'!$B$25
Name GrowthTax: 'Inputs'!$B$26
Name GrowthOther: 'Inputs'!$B$27
Name LeaseUpIncomeOffset: 'Inputs'!$B$30
Name UnitsDeliveredPerMo: 'Inputs'!$B$31
Name UnitsLeasedPerMo: 'Inputs'!$B$32
Name LeaseUpRampPct: 'Inputs'!$B$33
Name LeaseUpElevationPct: 'Inputs'!$B$34
Name StabilizedOccupancy: 'Inputs'!$B$35
Name LandCost: 'Inputs'!$B$38
Name GrossAcres: 'Inputs'!$B$39
Name NetAcres: 'Inputs'!$B$40
Name FARRatio: 'Inputs'!$B$41
Name EfficiencyRatio: 'Inputs'!$B$42
Name ExistingStructureCost: 'Inputs'!$B$43
Name TaxLevyPct: 'Inputs'!$B$46
Name TaxAssessmentPct: 'Inputs'!$B$47
Name TaxValueAdjFactor: 'Inputs'!$B$48
Name TaxMethodValue: 'Inputs'!$B$49
Name TaxYear1: 'Inputs'!$B$50
Name ReassessOnSale: 'Inputs'!$B$51
Name DispoTaxRatePct: 'Inputs'!$B$52
Name FundingOrderPari: 'Inputs'!$B$55
Name TargetLTC: 'Inputs'!$B$56
Name OpReserveCoverage: 'Inputs'!$B$57
Name OpReserveMinMonths: 'Inputs'!$B$58
Name ConLoanTermMonths: 'Inputs'!$B$61
Name ConRate: 'Inputs'!$B$62
Name ConActual360: 'Inputs'!$B$63
Name ConPointsPct: 'Inputs'!$B$64
Name ConOtherCosts: 'Inputs'!$B$65
Name ConMinDebtYield: 'Inputs'!$B$66
Name ConMinDSCR: 'Inputs'!$B$67
Name LenderReqReserveOverride: 'Inputs'!$B$68
Name PermMaxLTV: 'Inputs'!$B$71
Name PermRate: 'Inputs'!$B$72
Name PermTermMonths: 'Inputs'!$B$73
Name PermIOMonths: 'Inputs'!$B$74
Name PermAmortMonths: 'Inputs'!$B$75
Name PermActual360: 'Inputs'!$B$76
Name PermPointsPct: 'Inputs'!$B$77
Name PermMinDebtYield: 'Inputs'!$B$78

Sheet Dashboard

Sheet Inputs
A1: Institutional Multifamily Development Model — Inputs
A2: Blue = hard-keyed input. Every value below is a workbook named range.
A4: Property Details
A5: Investment Type | B5: Ground-Up Development | C5: Investment type
A6: Property Name | B6: Meridian Apartments | C6: Deal name
A7: City | B7: Austin
A8: State | B8: TX
A9: Market | B9: Austin-Round Rock | C9: MSA
A10: Product Type | B10: Garden / Mid-Rise
A11: Location | B11: Suburban Infill
A12: Inception Date | B12: 2026-01-01 | C12: Model period 1 = this month
A14: Investment Details
A15: Hold Period Months | B15: 84 | C15: Disposition month (1-360 toggle)
A16: Entry Cap Rate | B16: 0.0475 | C16: Market / entry cap rate
A17: Cap Adj Location | B17: 0 | C17: Location adjustment (+/-)
A18: Cap Adj Size | B18: 0 | C18: Size adjustment (+/-)
A19: Cap Adj Aging | B19: 0.0025 | C19: Aging adjustment (+/-)
A20: Exit Cap Residential | B20: 0.05 | C20: Exit cap - residential
A21: Exit Cap Retail | B21: 0.065 | C21: Exit cap - retail
A22: Growth Rent | B22: 0.03 | C22: Annual market-rent growth
A23: Growth Low Inc Rent | B23: 0.02 | C23: Annual low-income-rent growth
A24: Growth Expense | B24: 0.03 | C24: Annual expense growth
A25: Growth Utility | B25: 0.035 | C25: Annual utility growth
A26: Growth Tax | B26: 0.02 | C26: Annual tax growth
A27: Growth Other | B27: 0.03 | C27: Annual other-income growth
A29: Unit Delivery & Lease-Up
A30: Lease Up Income Offset | B30: 1 | C30: 1=offset lease-up income vs equity, 0=no
A31: Units Delivered Per Mo | B31: 30 | C31: Units delivered per month
A32: Units Leased Per Mo | B32: 18 | C32: Units absorbed (leased) per month
A33: Lease Up Ramp Pct | B33: 0.6 | C33: Variable-opex ramp: % of stabilized during lease-up
A34: Lease Up Elevation Pct | B34: 0.25 | C34: Elevated-opex uplift over stabilized during lease-up
A35: Stabilized Occupancy | B35: 0.93 | C35: Physical occupancy at stabilization
A37: Site Details
A38: Land Cost | B38: 14000000 | C38: Total land cost
A39: Gross Acres | B39: 9.5 | C39: Gross site acres
A40: Net Acres | B40: 8 | C40: Net developable acres
A41: FARRatio | B41: 1.75 | C41: Floor-area ratio
A42: Efficiency Ratio | B42: 0.85 | C42: Net rentable / gross buildable
A43: Existing Structure Cost | B43: 0 | C43: Demo / existing structure
A45: Property Taxes
...

Sheet UnitMatrix
A1: Unit Matrix — Residential & Retail
A3: Plan | B3: Class | C3: Units | D3: Avg SF | E3: Total SF | F3: Market Rent | G3: Net Eff. Rent | H3: Annual Rent | I3: Rent / SF | J3: % of Total
A4: Studio | B4: Market | C4: 40 | D4: 540 | E4: =C4*D4 | F4: 1895 | G4: 1845 | H4: =C4*F4*12 | I4: =IF(D4=0,0,F4/D4) | J4: =IF(TotalUnits=0,0,C4/TotalUnits)
A5: 1BR-A | B5: Market | C5: 60 | D5: 720 | E5: =C5*D5 | F5: 2245 | G5: 2195 | H5: =C5*F5*12 | I5: =IF(D5=0,0,F5/D5) | J5: =IF(TotalUnits=0,0,C5/TotalUnits)
A6: 1BR-B | B6: Market | C6: 30 | D6: 780 | E6: =C6*D6 | F6: 2360 | G6: 2300 | H6: =C6*F6*12 | I6: =IF(D6=0,0,F6/D6) | J6: =IF(TotalUnits=0,0,C6/TotalUnits)
A7: 2BR-A | B7: Market | C7: 40 | D7: 1050 | E7: =C7*D7 | F7: 3050 | G7: 2975 | H7: =C7*F7*12 | I7: =IF(D7=0,0,F7/D7) | J7: =IF(TotalUnits=0,0,C7/TotalUnits)
A8: 2BR-B | B8: Market | C8: 10 | D8: 1150 | E8: =C8*D8 | F8: 3220 | G8: 3140 | H8: =C8*F8*12 | I8: =IF(D8=0,0,F8/D8) | J8: =IF(TotalUnits=0,0,C8/TotalUnits)
A9: 1BR-LI | B9: Low | C9: 12 | D9: 720 | E9: =C9*D9 | F9: 1350 | G9: 1350 | H9: =C9*F9*12 | I9: =IF(D9=0,0,F9/D9) | J9: =IF(TotalUnits=0,0,C9/TotalUnits)
A10: 2BR-LI | B10: Low | C10: 8 | D10: 1050 | E10: =C10*D10 | F10: 1625 | G10: 1625 | H10: =C10*F10*12 | I10: =IF(D10=0,0,F10/D10) | J10: =IF(TotalUnits=0,0,C10/TotalUnits)
A11: Total / Weighted | C11: =SUM(C4:C10) | E11: =SUM(E4:E10) | H11: =SUM(H4:H10)
A13: Derived Unit Metrics
A14: Total Units | B14: =SUM(C4:C10)
A15: Market-Rate Units | B15: =SUMIF(B4:B10,"Market",C4:C10)
A16: Low-Income Units | B16: =SUMIF(B4:B10,"Low",C4:C10)
A17: Net Rentable SF (NRSF) | B17: =SUM(E4:E10)
A18: Buildable SF | B18: =NRSF/EfficiencyRatio
A19: Avg Unit SF | B19: =IF(TotalUnits=0,0,NRSF/TotalUnits)
A20: Base Market Rent / mo | B20: =SUMPRODUCT((B4:B10="Market")*C4:C10*F4:F10)
A21: Base Low-Income Rent / mo | B21: =SUMPRODUCT((B4:B10="Low")*C4:C10*F4:F10)
A23: Retail Matrix
A24: Suite | B24: SF | C24: Rent / SF / yr | D24: Annual Rent | E24: Monthly Rent
A25: Retail-1 | B25: 4200 | C25: 34 | D25: =B25*C25 | E25: =B25*C25/12
A26: Retail-2 | B26: 3100 | C26: 32 | D26: =B26*C26 | E26: =B26*C26/12
A27: Retail Rent / mo | B27: =SUM(E25:E26)

Sheet Budget
A1: Development Budget & Cost Assumptions
A2: Basis: abs=$ unit=$/unit sf=$/NRSF. Modeled Total drives the cost-curve engine.
A4: Line Item | B4: Group | C4: Type | D4: Basis | E4: Amount | F4: Phase | G4: Cost Curve | H4: Modifier | I4: Modeled Total | J4: Per Unit | K4: Per SF
A5: Land Acquisition | B5: Land | C5: Land | D5: abs | E5: =LandCost | F5: Initial Closing | G5: Single_Point | H5: 0 | I5: =IF(D5="abs",E5,IF(D5="unit",E5*TotalUnits,IF(D5="sf",E5*NRSF,E5))) | J5: =IF(TotalUnits=0,0,I5/TotalUnits) | K5: =IF(NRSF=0,0,I5/NRSF)
A6: Existing Structure/Demo | B6: Land | C6: Land | D6: abs | E6: =ExistingStructureCost | F6: Pre-Construction | G6: Straight_Line | H6: 0 | I6: =IF(D6="abs",E6,IF(D6="unit",E6*TotalUnits,IF(D6="sf",E6*NRSF,E6))) | J6: =IF(TotalUnits=0,0,I6/TotalUnits) | K6: =IF(NRSF=0,0,I6/NRSF)
A7: Due Diligence | B7: Soft | C7: Soft | D7: abs | E7: 150000 | F7: Due Diligence | G7: Straight_Line | H7: 0 | I7: =IF(D7="abs",E7,IF(D7="unit",E7*TotalUnits,IF(D7="sf",E7*NRSF,E7))) | J7: =IF(TotalUnits=0,0,I7/TotalUnits) | K7: =IF(NRSF=0,0,I7/NRSF)
A8: Entitlements | B8: Soft | C8: Soft | D8: abs | E8: 600000 | F8: Entitlement | G8: Straight_Line | H8: 0 | I8: =IF(D8="abs",E8,IF(D8="unit",E8*TotalUnits,IF(D8="sf",E8*NRSF,E8))) | J8: =IF(TotalUnits=0,0,I8/TotalUnits) | K8: =IF(NRSF=0,0,I8/NRSF)
A9: Architecture & Eng. | B9: Soft | C9: Soft | D9: sf | E9: 6.5 | F9: Pre-Construction | G9: Straight_Line | H9: 0 | I9: =IF(D9="abs",E9,IF(D9="unit",E9*TotalUnits,IF(D9="sf",E9*NRSF,E9))) | J9: =IF(TotalUnits=0,0,I9/TotalUnits) | K9: =IF(NRSF=0,0,I9/NRSF)
A10: Consultants | B10: Soft | C10: Soft | D10: abs | E10: 400000 | F10: Entitlement | G10: Straight_Line | H10: 0 | I10: =IF(D10="abs",E10,IF(D10="unit",E10*TotalUnits,IF(D10="sf",E10*NRSF,E10))) | J10: =IF(TotalUnits=0,0,I10/TotalUnits) | K10: =IF(NRSF=0,0,I10/NRSF)
A11: Legal & Org. | B11: Soft | C11: Soft | D11: abs | E11: 300000 | F11: Due Diligence | G11: Straight_Line | H11: 0 | I11: =IF(D11="abs",E11,IF(D11="unit",E11*TotalUnits,IF(D11="sf",E11*NRSF,E11))) | J11: =IF(TotalUnits=0,0,I11/TotalUnits) | K11: =IF(NRSF=0,0,I11/NRSF)
A12: Marketing & Lease-Up | B12: Soft | C12: Soft | D12: unit | E12: 1200 | F12: Lease-Up | G12: Straight_Line | H12: 0 | I12: =IF(D12="abs",E12,IF(D12="unit",E12*TotalUnits,IF(D12="sf",E12*NRSF,E12))) | J12: =IF(TotalUnits=0,0,I12/TotalUnits) | K12: =IF(NRSF=0,0,I12/NRSF)
A13: Property Taxes (Dev) | B13: Soft | C13: Soft | D13: abs | E13: 700000 | F13: Construction | G13: Straight_Line | H13: 0 | I13: =IF(D13="abs",E13,IF(D13="unit",E13*TotalUnits,IF(D13="sf",E13*NRSF,E13))) | J13: =IF(TotalUnits=0,0,I13/TotalUnits) | K13: =IF(NRSF=0,0,I13/NRSF)
A14: Insurance (Dev) | B14: Soft | C14: Soft | D14: abs | E14: 500000 | F14: Construction | G14: Straight_Line | H14: 0 | I14: =IF(D14="abs",E14,IF(D14="unit",E14*TotalUnits,IF(D14="sf",E14*NRSF,E14))) | J14: =IF(TotalUnits=0,0,I14/TotalUnits) | K14: =IF(NRSF=0,0,I14/NRSF)
A15: GC Contract (Hard) | B15: Hard | C15: Hard | D15: sf | E15: 200 | F15: Construction | G15: Bell_Curve | H15: 0 | I15: =IF(D15="abs",E15,IF(D15="unit",E15*TotalUnits,IF(D15="sf",E15*NRSF,E15))) | J15: =IF(TotalUnits=0,0,I15/TotalUnits) | K15: =IF(NRSF=0,0,I15/NRSF)
A16: Off-Site Improvements | B16: Hard | C16: Hard | D16: abs | E16: 1200000 | F16: Construction | G16: Straight_Line | H16: 0 | I16: =IF(D16="abs",E16,IF(D16="unit",E16*TotalUnits,IF(D16="sf",E16*NRSF,E16))) | J16: =IF(TotalUnits=0,0,I16/TotalUnits) | K16: =IF(NRSF=0,0,I16/NRSF)
A17: Utilities & Hookups | B17: Hard | C17: Hard | D17: abs | E17: 900000 | F17: Construction | G17: Straight_Line | H17: 0 | I17: =IF(D17="abs",E17,IF(D17="unit",E17*TotalUnits,IF(D17="sf",E17*NRSF,E17))) | J17: =IF(TotalUnits=0,0,I17/TotalUnits) | K17: =IF(NRSF=0,0,I17/NRSF)
A18: Builder's Risk | B18: Hard | C18: Hard | D18: abs | E18: 350000 | F18: Construction | G18: Straight_Line | H18: 0 | I18: =IF(D18="abs",E18,IF(D18="unit",E18*TotalUnits,IF(D18="sf",E18*NRSF,E18))) | J18: =IF(TotalUnits=0,0,I18/TotalUnits) | K18: =IF(NRSF=0,0,I18/NRSF)
... A32: Other Hard Cost 6 | B32: Hard | C32: Hard | D32: abs | E32: 0 | F32: Construction | G32: Bell_Curve | H32: 0 | I32: =IF(D32="abs",E32,IF(D32="unit",E32*TotalUnits,IF(D32="sf",E32*NRSF,E32))) | J32: =IF(TotalUnits=0,0,I32/TotalUnits) | K32: =IF(NRSF=0,0,I32/NRSF)
A34: Budget Summary
A35: Land | I35: =SUMIF(B5:B32,"Land",I5:I32)
A36: Soft Costs | I36: =SUMIF(B5:B32,"Soft",I5:I32)
A37: Hard Costs | I37: =SUMIF(B5:B32,"Hard",I5:I32)
A38: Direct Costs (subtotal) | I38: =SUM(I5:I32)
A39: Sponsor Development Fee | I39: =DevFeePctDirect*DirectCosts
A40: Total Development Cost (per Diagnostics) | I40: =TDC_Total

Sheet Timeline
A1: Timeline Engine — Milestones & Monthly Period Grid
A3: Milestone | B3: Start (mo) | C3: Duration (mo) | D3: End (mo)
A4: Open Escrow | B4: 1 | C4: 1 | D4: =B4+C4-1
A5: Due Diligence | B5: 1 | C5: 3 | D5: =B5+C5-1
A6: Entitlement | B6: 2 | C6: 5 | D6: =B6+C6-1
A7: Pre-Construction | B7: 5 | C7: 3 | D7: =B7+C7-1
A8: Initial Closing | B8: 7 | C8: 1 | D8: =B8+C8-1
A9: Construction | B9: 7 | C9: 20 | D9: =B9+C9-1
A10: 1st Unit Delivery | B10: 21 | C10: 1 | D10: =B10+C10-1
A11: Lease-Up | B11: 21 | C11: 12 | D11: =B11+C11-1
A12: Stabilization | B12: 33 | C12: 1 | D12: =B12+C12-1
A13: Recapitalization/Refinance | B13: 43 | C13: 1 | D13: =B13+C13-1
A14: Disposition | B14: =HoldPeriodMonths | C14: 1 | D14: =B14+C14-1
A16: Key Timing (derived)
A17: Construction Start | B17: =MS_Construction_Start
A18: Construction Maturity | B18: =ConStart+ConLoanTermMonths-1
A19: 1st Unit Delivery | B19: =MS_1st_Unit_Delivery_Start
A20: Stabilization Month | B20: =MS_Stabilization_Start
A21: Disposition Month | B21: =HoldPeriodMonths
A22: Refi Flag (1=refi,0=sell) | B22: =IF(DispoMonth>ConMaturity,1,0)
A23: Refi Month | B23: =IF(RefiFlag=1,MIN(ConMaturity,IF(RefiMonthOverride>0,RefiMonthOverride,ConMaturity)),0)
A24: Con Payoff Month | B24: =IF(RefiFlag=1,RefiMonth,DispoMonth)
A26: Monthly Period Grid
A27: Period → | C27: Total | D27: 1 | E27: 2 | F27: 3 | G27: 4 | H27: 5 | I27: 6 | J27: 7 | K27: 8 | L27: 9 | M27: 10 | N27: 11 | O27: 12 | P27: 13 | Q27: 14 | R27: 15 | S27: 16 | T27: 17 | U27: 18 | V27: 19 | W27: 20 | X27: 21 | Y27: 22 | Z27: 23 | AA27: 24 | AB27: 25 | AC27: 26 | AD27: 27 | AE27: 28 | AF27: 29 | AG27: 30 | AH27: 31 | AI27: 32 | AJ27: 33 | AK27: 34 | AL27: 35 | AM27: 36 | AN27: 37 | AO27: 38 | AP27: 39 | AQ27: 40 | AR27: 41 | AS27: 42 | AT27: 43 | AU27: 44 | AV27: 45 | AW27: 46 | AX27: 47 | AY27: 48 | AZ27: 49 | BA27: 50 | BB27: 51 | BC27: 52 | BD27: 53 | BE27: 54 | BF27: 55 | BG27: 56 | BH27: 57 | BI27: 58 | BJ27: 59 | BK27: 60 | BL27: 61 | BM27: 62 | BN27: 63 | BO27: 64 | BP27: 65 | BQ27: 66 | BR27: 67 | BS27: 68 | BT27: 69 | BU27: 70 | BV27: 71 | BW27: 72 | BX27: 73 | BY27: 74 | BZ27: 75 | CA27: 76 | CB27: 77 | CC27: 78 | CD27: 79 | CE27: 80 | CF27: 81 | CG27: 82 | CH27: 83 | CI27: 84 | CJ27: 85 | CK27: 86 | CL27: 87 | CM27: 88 | CN27: 89 | CO27: 90 | CP27: 91 | CQ27: 92 | CR27: 93 | CS27: 94 | CT27: 95 | CU27: 96 | CV27: 97 | CW27: 98 | CX27: 99 | CY27: 100 | CZ27: 101 | DA27: 102 | DB27: 103 | DC27: 104 | DD27: 105 | DE27: 106 | DF27: 107 | DG27: 108 | DH27: 109 | DI27: 110 | DJ27: 111 | DK27: 112 | DL27: 113 | DM27: 114 | DN27: 115 | DO27: 116 | DP27: 117 | DQ27: 118 | DR27: 119 | DS27: 120 | DT27: 121 | DU27: 122 | DV27: 123 | DW27: 124 | DX27: 125 | DY27: 126 | DZ27: 127 | EA27: 128 | EB27: 129 | EC27: 130 | ED27: 131 | EE27: 132 | EF27: 133 | EG27: 134 | EH27: 135 | EI27: 136 | EJ27: 137 | EK27: 138 | EL27: 139 | EM27: 140 | EN27: 141 | EO27: 142 | EP27: 143 | EQ27: 144 | ER27: 145 | ES27: 146 | ET27: 147 | EU27: 148 | EV27: 149 | EW27: 150 | EX27: 151 | EY27: 152 | EZ27: 153 | FA27: 154 | FB27: 155 | FC27: 156 | FD27: 157 | FE27: 158 | FF27: 159 | FG27: 160 | FH27: 161 | FI27: 162 | FJ27: 163 | FK27: 164 | FL27: 165 | FM27: 166 | FN27: 167 | FO27: 168 | FP27: 169 | FQ27: 170 | FR27: 171 | FS27: 172 | FT27: 173 | FU27: 174 | FV27: 175 | FW27: 176 | FX27: 177 | FY27: 178 | FZ27: 179 | GA27: 180 | GB27: 181 | GC27: 182 | GD27: 183 | GE27: 184 | GF27: 185 | GG27: 186 | GH27: 187 | GI27: 188 | GJ27: 189 | GK27: 190 | GL27: 191 | GM27: 192 | GN27: 193 | GO27: 194 | GP27: 195 | GQ27: 196 | GR27: 197 | GS27: 198 | GT27: 199 | GU27: 200 | GV27: 201 | GW27: 202 | GX27: 203 | GY27: 204 | GZ27: 205 | HA27: 206 | HB27: 207 | HC27: 208 | HD27: 209 | HE27: 210 | HF27: 211 | HG27: 212 | HH27: 213 | HI27: 214 | HJ27: 215 | HK27: 216 | HL27: 217 | HM27: 218 | HN27: 219 | HO27: 220 | HP27: 221 | HQ27: 222 | HR27: 223 | HS27: 224 | HT27: 225 | HU27: 226 | HV27: 227 | HW27: 228 | HX27: 229 | HY27: 230 | HZ27: 231 | IA27: 232 | IB27: 233 | IC27: 234 | ID27: 235 | IE27: 236 | IF27: 237 | IG27: 238 | IH27: 239 | II27: 240 | IJ27: 241 | IK27: 242 | IL27: 243 | IM27: 244 | IN27: 245 | IO27: 246 | IP27: 247 | IQ27: 248 | IR27: 249 | IS27: 250 | IT27: 251 | IU27: 252 | IV27: 253 | IW27: 254 | IX27: 255 | IY27: 256 | IZ27: 257 | JA27: 258 | JB27: 259 | JC27: 260 | JD27: 261 | JE27: 262 | JF27: 263 | JG27: 264 | JH27: 265 | JI27: 266 | JJ27: 267 | JK27: 268 | JL27: 269 | JM27: 270 | JN27: 271 | JO27: 272 | JP27: 273 | JQ27: 274 | JR27: 275 | JS27: 276 | JT27: 277 | JU27: 278 | JV27: 279 | JW27: 280 | JX27: 281 | JY27: 282 | JZ27: 283 | KA27: 284 | KB27: 285 | KC27: 286 | KD27: 287 | KE27: 288 | KF27: 289 | KG27: 290 | KH27: 291 | KI27: 292 | KJ27: 293 | KK27: 294 | KL27: 295 | KM27: 296 | KN27: 297 | KO27: 298 | KP27: 299 | KQ27: 300 | KR27: 301 | KS27: 302 | KT27: 303 | KU27: 304 | KV27: 305 | KW27: 306 | KX27: 307 | KY27: 308 | KZ27: 309 | LA27: 310 | LB27: 311 | LC27: 312 | LD27: 313 | LE27: 314 | LF27: 315 | LG27: 316 | LH27: 317 | LI27: 318 | LJ27: 319 | LK27: 320 | LL27: 321 | LM27: 322 | LN27: 323 | LO27: 324 | LP27: 325 | LQ27: 326 | LR27: 327 | LS27: 328 | LT27: 329 | LU27: 330 | LV27: 331 | LW27: 332 | LX27: 333 | LY27: 334 | LZ27: 335 | MA27: 336 | MB27: 337 | MC27: 338 | MD27: 339 | ME27: 340 | MF27: 341 | MG27: 342 | MH27: 343 | MI27: 344 | MJ27: 345 | MK27: 346 | ML27: 347 | MM27: 348 | MN27: 349 | MO27: 350 | MP27: 351 | MQ27: 352 | MR27: 353 | MS27: 354 | MT27: 355 | MU27: 356 | MV27: 357 | MW27: 358 | MX27: 359 | MY27: 360 | MZ27: 361 | NA27: 362 | NB27: 363 | NC27: 364 | ND27: 365 | NE27: 366 | NF27: 367 | NG27: 368 | NH27: 369 | NI27: 370 | NJ27: 371 | NK27: 372
A28: Month Start | D28: =EDATE(InceptionDate,0) | E28: =EDATE(InceptionDate,1) | F28: =EDATE(InceptionDate,2) | G28: =EDATE(InceptionDate,3) | H28: =EDATE(InceptionDate,4) | I28: =EDATE(InceptionDate,5) | J28: =EDATE(InceptionDate,6) | K28: =EDATE(InceptionDate,7) | L28: =EDATE(InceptionDate,8) | M28: =EDATE(InceptionDate,9) | N28: =EDATE(InceptionDate,10) | O28: =EDATE(InceptionDate,11) | P28: =EDATE(InceptionDate,12) | Q28: =EDATE(InceptionDate,13) | R28: =EDATE(InceptionDate,14) | S28: =EDATE(InceptionDate,15) | T28: =EDATE(InceptionDate,16) | U28: =EDATE(InceptionDate,17) | V28: =EDATE(InceptionDate,18) | W28: =EDATE(InceptionDate,19) | X28: =EDATE(InceptionDate,20) | Y28: =EDATE(InceptionDate,21) | Z28: =EDATE(InceptionDate,22) | AA28: =EDATE(InceptionDate,23) | AB28: =EDATE(InceptionDate,24) | AC28: =EDATE(InceptionDate,25) | AD28: =EDATE(InceptionDate,26) | AE28: =EDATE(InceptionDate,27) | AF28: =EDATE(InceptionDate,28) | AG28: =EDATE(InceptionDate,29) | AH28: =EDATE(InceptionDate,30) | AI28: =EDATE(InceptionDate,31) | AJ28: =EDATE(InceptionDate,32) | AK28: =EDATE(InceptionDate,33) | AL28: =EDATE(InceptionDate,34) | AM28: =EDATE(InceptionDate,35) | AN28: =EDATE(InceptionDate,36) | AO28: =EDATE(InceptionDate,37) | AP28: =EDATE(InceptionDate,38) | AQ28: =EDATE(InceptionDate,39) | AR28: =EDATE(InceptionDate,40) | AS28: =EDATE(InceptionDate,41) | AT28: =EDATE(InceptionDate,42) | AU28: =EDATE(InceptionDate,43) | AV28: =EDATE(InceptionDate,44) | AW28: =EDATE(InceptionDate,45) | AX28: =EDATE(InceptionDate,46) | AY28: =EDATE(InceptionDate,47) | AZ28: =EDATE(InceptionDate,48) | BA28: =EDATE(InceptionDate,49) | BB28: =EDATE(InceptionDate,50) | BC28: =EDATE(InceptionDate,51) | BD28: =EDATE(InceptionDate,52) | BE28: =EDATE(InceptionDate,53) | BF28: =EDATE(InceptionDate,54) | BG28: =EDATE(InceptionDate,55) | BH28: =EDATE(InceptionDate,56) | BI28: =EDATE(InceptionDate,57) | BJ28: =EDATE(InceptionDate,58) | BK28: =EDATE(InceptionDate,59) | BL28: =EDATE(InceptionDate,60) | BM28: =EDATE(InceptionDate,61) | BN28: =EDATE(InceptionDate,62) | BO28: =EDATE(InceptionDate,63) | BP28: =EDATE(InceptionDate,64) | BQ28: =EDATE(InceptionDate,65) | BR28: =EDATE(InceptionDate,66) | BS28: =EDATE(InceptionDate,67) | BT28: =EDATE(InceptionDate,68) | BU28: =EDATE(InceptionDate,69) | BV28: =EDATE(InceptionDate,70) | BW28: =EDATE(InceptionDate,71) | BX28: =EDATE(InceptionDate,72) | BY28: =EDATE(InceptionDate,73) | BZ28: =EDATE(InceptionDate,74) | CA28: =EDATE(InceptionDate,75) | CB28: =EDATE(InceptionDate,76) | CC28: =EDATE(InceptionDate,77) | CD28: =EDATE(InceptionDate,78) | CE28: =EDATE(InceptionDate,79) | CF28: =EDATE(InceptionDate,80) | CG28: =EDATE(InceptionDate,81) | CH28: =EDATE(InceptionDate,82) | CI28: =EDATE(InceptionDate,83) | CJ28: =EDATE(InceptionDate,84) | CK28: =EDATE(InceptionDate,85) | CL28: =EDATE(InceptionDate,86) | CM28: =EDATE(InceptionDate,87) | CN28: =EDATE(InceptionDate,88) | CO28: =EDATE(InceptionDate,89) | CP28: =EDATE(InceptionDate,90) | CQ28: =EDATE(InceptionDate,91) | CR28: =EDATE(InceptionDate,92) | CS28: =EDATE(InceptionDate,93) | CT28: =EDATE(InceptionDate,94) | CU28: =EDATE(InceptionDate,95) | CV28: =EDATE(InceptionDate,96) | CW28: =EDATE(InceptionDate,97) | CX28: =EDATE(InceptionDate,98) | CY28: =EDATE(InceptionDate,99) | CZ28: =EDATE(InceptionDate,100) | DA28: =EDATE(InceptionDate,101) | DB28: =EDATE(InceptionDate,102) | DC28: =EDATE(InceptionDate,103) | DD28: =EDATE(InceptionDate,104) | DE28: =EDATE(InceptionDate,105) | DF28: =EDATE(InceptionDate,106) | DG28: =EDATE(InceptionDate,107) | DH28: =EDATE(InceptionDate,108) | DI28: =EDATE(InceptionDate,109) | DJ28: =EDATE(InceptionDate,110) | DK28: =EDATE(InceptionDate,111) | DL28: =EDATE(InceptionDate,112) | DM28: =EDATE(InceptionDate,113) | DN28: =EDATE(InceptionDate,114) | DO28: =EDATE(InceptionDate,115) | DP28: =EDATE(InceptionDate,116) | DQ28: =EDATE(InceptionDate,117) | DR28: =EDATE(InceptionDate,118) | DS28: =EDATE(InceptionDate,119) | DT28: =EDATE(InceptionDate,120) | DU28: =EDATE(InceptionDate,121) | DV28: =EDATE(InceptionDate,122) | DW28: =EDATE(InceptionDate,123) | DX28: =EDATE(InceptionDate,124) | DY28: =EDATE(InceptionDate,125) | DZ28: =EDATE(InceptionDate,126) | EA28: =EDATE(InceptionDate,127) | EB28: =EDATE(InceptionDate,128) | EC28: =EDATE(InceptionDate,129) | ED28: =EDATE(InceptionDate,130) | EE28: =EDATE(InceptionDate,131) | EF28: =EDATE(InceptionDate,132) | EG28: =EDATE(InceptionDate,133) | EH28: =EDATE(InceptionDate,134) | EI28: =EDATE(InceptionDate,135) | EJ28: =EDATE(InceptionDate,136) | EK28: =EDATE(InceptionDate,137) | EL28: =EDATE(InceptionDate,138) | EM28: =EDATE(InceptionDate,139) | EN28: =EDATE(InceptionDate,140) | EO28: =EDATE(InceptionDate,141) | EP28: =EDATE(InceptionDate,142) | EQ28: =EDATE(InceptionDate,143) | ER28: =EDATE(InceptionDate,144) | ES28: =EDATE(InceptionDate,145) | ET28: =EDATE(InceptionDate,146) | EU28: =EDATE(InceptionDate,147) | EV28: =EDATE(InceptionDate,148) | EW28: =EDATE(InceptionDate,149) | EX28: =EDATE(InceptionDate,150) | EY28: =EDATE(InceptionDate,151) | EZ28: =EDATE(InceptionDate,152) | FA28: =EDATE(InceptionDate,153) | FB28: =EDATE(InceptionDate,154) | FC28: =EDATE(InceptionDate,155) | FD28: =EDATE(InceptionDate,156) | FE28: =EDATE(InceptionDate,157) | FF28: =EDATE(InceptionDate,158) | FG28: =EDATE(InceptionDate,159) | FH28: =EDATE(InceptionDate,160) | FI28: =EDATE(InceptionDate,161) | FJ28: =EDATE(InceptionDate,162) | FK28: =EDATE(InceptionDate,163) | FL28: =EDATE(InceptionDate,164) | FM28: =EDATE(InceptionDate,165) | FN28: =EDATE(InceptionDate,166) | FO28: =EDATE(InceptionDate,167) | FP28: =EDATE(InceptionDate,168) | FQ28: =EDATE(InceptionDate,169) | FR28: =EDATE(InceptionDate,170) | FS28: =EDATE(InceptionDate,171) | FT28: =EDATE(InceptionDate,172) | FU28: =EDATE(InceptionDate,173) | FV28: =EDATE(InceptionDate,174) | FW28: =EDATE(InceptionDate,175) | FX28: =EDATE(InceptionDate,176) | FY28: =EDATE(InceptionDate,177) | FZ28: =EDATE(InceptionDate,178) | GA28: =EDATE(InceptionDate,179) | GB28: =EDATE(InceptionDate,180) | GC28: =EDATE(InceptionDate,181) | GD28: =EDATE(InceptionDate,182) | GE28: =EDATE(InceptionDate,183) | GF28: =EDATE(InceptionDate,184) | GG28: =EDATE(InceptionDate,185) | GH28: =EDATE(InceptionDate,186) | GI28: =EDATE(InceptionDate,187) | GJ28: =EDATE(InceptionDate,188) | GK28: =EDATE(InceptionDate,189) | GL28: =EDATE(InceptionDate,190) | GM28: =EDATE(InceptionDate,191) | GN28: =EDATE(InceptionDate,192) | GO28: =EDATE(InceptionDate,193) | GP28: =EDATE(InceptionDate,194) | GQ28: =EDATE(InceptionDate,195) | GR28: =EDATE(InceptionDate,196) | GS28: =EDATE(InceptionDate,197) | GT28: =EDATE(InceptionDate,198) | GU28: =EDATE(InceptionDate,199) | GV28: =EDATE(InceptionDate,200) | GW28: =EDATE(InceptionDate,201) | GX28: =EDATE(InceptionDate,202) | GY28: =EDATE(InceptionDate,203) | GZ28: =EDATE(InceptionDate,204) | HA28: =EDATE(InceptionDate,205) | HB28: =EDATE(InceptionDate,206) | HC28: =EDATE(InceptionDate,207) | HD28: =EDATE(InceptionDate,208) | HE28: =EDATE(InceptionDate,209) | HF28: =EDATE(InceptionDate,210) | HG28: =EDATE(InceptionDate,211) | HH28: =EDATE(InceptionDate,212) | HI28: =EDATE(InceptionDate,213) | HJ28: =EDATE(InceptionDate,214) | HK28: =EDATE(InceptionDate,215) | HL28: =EDATE(InceptionDate,216) | HM28: =EDATE(InceptionDate,217) | HN28: =EDATE(InceptionDate,218) | HO28: =EDATE(InceptionDate,219) | HP28: =EDATE(InceptionDate,220) | HQ28: =EDATE(InceptionDate,221) | HR28: =EDATE(InceptionDate,222) | HS28: =EDATE(InceptionDate,223) | HT28: =EDATE(InceptionDate,224) | HU28: =EDATE(InceptionDate,225) | HV28: =EDATE(InceptionDate,226) | HW28: =EDATE(InceptionDate,227) | HX28: =EDATE(InceptionDate,228) | HY28: =EDATE(InceptionDate,229) | HZ28: =EDATE(InceptionDate,230) | IA28: =EDATE(InceptionDate,231) | IB28: =EDATE(InceptionDate,232) | IC28: =EDATE(InceptionDate,233) | ID28: =EDATE(InceptionDate,234) | IE28: =EDATE(InceptionDate,235) | IF28: =EDATE(InceptionDate,236) | IG28: =EDATE(InceptionDate,237) | IH28: =EDATE(InceptionDate,238) | II28: =EDATE(InceptionDate,239) | IJ28: =EDATE(InceptionDate,240) | IK28: =EDATE(InceptionDate,241) | IL28: =EDATE(InceptionDate,242) | IM28: =EDATE(InceptionDate,243) | IN28: =EDATE(InceptionDate,244) | IO28: =EDATE(InceptionDate,245) | IP28: =EDATE(InceptionDate,246) | IQ28: =EDATE(InceptionDate,247) | IR28: =EDATE(InceptionDate,248) | IS28: =EDATE(InceptionDate,249) | IT28: =EDATE(InceptionDate,250) | IU28: =EDATE(InceptionDate,251) | IV28: =EDATE(InceptionDate,252) | IW28: =EDATE(InceptionDate,253) | IX28: =EDATE(InceptionDate,254) | IY28: =EDATE(InceptionDate,255) | IZ28: =EDATE(InceptionDate,256) | JA28: =EDATE(InceptionDate,257) | JB28: =EDATE(InceptionDate,258) | JC28: =EDATE(InceptionDate,259) | JD28: =EDATE(InceptionDate,260) | JE28: =EDATE(InceptionDate,261) | JF28: =EDATE(InceptionDate,262) | JG28: =EDATE(InceptionDate,263) | JH28: =EDATE(InceptionDate,264) | JI28: =EDATE(InceptionDate,265) | JJ28: =EDATE(InceptionDate,266) | JK28: =EDATE(InceptionDate,267) | JL28: =EDATE(InceptionDate,268) | JM28: =EDATE(InceptionDate,269) | JN28: =EDATE(InceptionDate,270) | JO28: =EDATE(InceptionDate,271) | JP28: =EDATE(InceptionDate,272) | JQ28: =EDATE(InceptionDate,273) | JR28: =EDATE(InceptionDate,274) | JS28: =EDATE(InceptionDate,275) | JT28: =EDATE(InceptionDate,276) | JU28: =EDATE(InceptionDate,277) | JV28: =EDATE(InceptionDate,278) | JW28: =EDATE(InceptionDate,279) | JX28: =EDATE(InceptionDate,280) | JY28: =EDATE(InceptionDate,281) | JZ28: =EDATE(InceptionDate,282) | KA28: =EDATE(InceptionDate,283) | KB28: =EDATE(InceptionDate,284) | KC28: =EDATE(InceptionDate,285) | KD28: =EDATE(InceptionDate,286) | KE28: =EDATE(InceptionDate,287) | KF28: =EDATE(InceptionDate,288) | KG28: =EDATE(InceptionDate,289) | KH28: =EDATE(InceptionDate,290) | KI28: =EDATE(InceptionDate,291) | KJ28: =EDATE(InceptionDate,292) | KK28: =EDATE(InceptionDate,293) | KL28: =EDATE(InceptionDate,294) | KM28: =EDATE(InceptionDate,295) | KN28: =EDATE(InceptionDate,296) | KO28: =EDATE(InceptionDate,297) | KP28: =EDATE(InceptionDate,298) | KQ28: =EDATE(InceptionDate,299) | KR28: =EDATE(InceptionDate,300) | KS28: =EDATE(InceptionDate,301) | KT28: =EDATE(InceptionDate,302) | KU28: =EDATE(InceptionDate,303) | KV28: =EDATE(InceptionDate,304) | KW28: =EDATE(InceptionDate,305) | KX28: =EDATE(InceptionDate,306) | KY28: =EDATE(InceptionDate,307) | KZ28: =EDATE(InceptionDate,308) | LA28: =EDATE(InceptionDate,309) | LB28: =EDATE(InceptionDate,310) | LC28: =EDATE(InceptionDate,311) | LD28: =EDATE(InceptionDate,312) | LE28: =EDATE(InceptionDate,313) | LF28: =EDATE(InceptionDate,314) | LG28: =EDATE(InceptionDate,315) | LH28: =EDATE(InceptionDate,316) | LI28: =EDATE(InceptionDate,317) | LJ28: =EDATE(InceptionDate,318) | LK28: =EDATE(InceptionDate,319) | LL28: =EDATE(InceptionDate,320) | LM28: =EDATE(InceptionDate,321) | LN28: =EDATE(InceptionDate,322) | LO28: =EDATE(InceptionDate,323) | LP28: =EDATE(InceptionDate,324) | LQ28: =EDATE(InceptionDate,325) | LR28: =EDATE(InceptionDate,326) | LS28: =EDATE(InceptionDate,327) | LT28: =EDATE(InceptionDate,328) | LU28: =EDATE(InceptionDate,329) | LV28: =EDATE(InceptionDate,330) | LW28: =EDATE(InceptionDate,331) | LX28: =EDATE(InceptionDate,332) | LY28: =EDATE(InceptionDate,333) | LZ28: =EDATE(InceptionDate,334) | MA28: =EDATE(InceptionDate,335) | MB28: =EDATE(InceptionDate,336) | MC28: =EDATE(InceptionDate,337) | MD28: =EDATE(InceptionDate,338) | ME28: =EDATE(InceptionDate,339) | MF28: =EDATE(InceptionDate,340) | MG28: =EDATE(InceptionDate,341) | MH28: =EDATE(InceptionDate,342) | MI28: =EDATE(InceptionDate,343) | MJ28: =EDATE(InceptionDate,344) | MK28: =EDATE(InceptionDate,345) | ML28: =EDATE(InceptionDate,346) | MM28: =EDATE(InceptionDate,347) | MN28: =EDATE(InceptionDate,348) | MO28: =EDATE(InceptionDate,349) | MP28: =EDATE(InceptionDate,350) | MQ28: =EDATE(InceptionDate,351) | MR28: =EDATE(InceptionDate,352) | MS28: =EDATE(InceptionDate,353) | MT28: =EDATE(InceptionDate,354) | MU28: =EDATE(InceptionDate,355) | MV28: =EDATE(InceptionDate,356) | MW28: =EDATE(InceptionDate,357) | MX28: =EDATE(InceptionDate,358) | MY28: =EDATE(InceptionDate,359) | MZ28: =EDATE(InceptionDate,360) | NA28: =EDATE(InceptionDate,361) | NB28: =EDATE(InceptionDate,362) | NC28: =EDATE(InceptionDate,363) | ND28: =EDATE(InceptionDate,364) | NE28: =EDATE(InceptionDate,365) | NF28: =EDATE(InceptionDate,366) | NG28: =EDATE(InceptionDate,367) | NH28: =EDATE(InceptionDate,368) | NI28: =EDATE(InceptionDate,369) | NJ28: =EDATE(InceptionDate,370) | NK28: =EDATE(InceptionDate,371)
A29: Flag: Open Escrow | D29: =IF(AND(1>=$B$4,1<=$D$4),1,0) | E29: =IF(AND(2>=$B$4,2<=$D$4),1,0) | F29: =IF(AND(3>=$B$4,3<=$D$4),1,0) | G29: =IF(AND(4>=$B$4,4<=$D$4),1,0) | H29: =IF(AND(5>=$B$4,5<=$D$4),1,0) | I29: =IF(AND(6>=$B$4,6<=$D$4),1,0) | J29: =IF(AND(7>=$B$4,7<=$D$4),1,0) | K29: =IF(AND(8>=$B$4,8<=$D$4),1,0) | L29: =IF(AND(9>=$B$4,9<=$D$4),1,0) | M29: =IF(AND(10>=$B$4,10<=$D$4),1,0) | N29: =IF(AND(11>=$B$4,11<=$D$4),1,0) | O29: =IF(AND(12>=$B$4,12<=$D$4),1,0) | P29: =IF(AND(13>=$B$4,13<=$D$4),1,0) | Q29: =IF(AND(14>=$B$4,14<=$D$4),1,0) | R29: =IF(AND(15>=$B$4,15<=$D$4),1,0) | S29: =IF(AND(16>=$B$4,16<=$D$4),1,0) | T29: =IF(AND(17>=$B$4,17<=$D$4),1,0) | U29: =IF(AND(18>=$B$4,18<=$D$4),1,0) | V29: =IF(AND(19>=$B$4,19<=$D$4),1,0) | W29: =IF(AND(20>=$B$4,20<=$D$4),1,0) | X29: =IF(AND(21>=$B$4,21<=$D$4),1,0) | Y29: =IF(AND(22>=$B$4,22<=$D$4),1,0) | Z29: =IF(AND(23>=$B$4,23<=$D$4),1,0) | AA29: =IF(AND(24>=$B$4,24<=$D$4),1,0) | AB29: =IF(AND(25>=$B$4,25<=$D$4),1,0) | AC29: =IF(AND(26>=$B$4,26<=$D$4),1,0) | AD29: =IF(AND(27>=$B$4,27<=$D$4),1,0) | AE29: =IF(AND(28>=$B$4,28<=$D$4),1,0) | AF29: =IF(AND(29>=$B$4,29<=$D$4),1,0) | AG29: =IF(AND(30>=$B$4,30<=$D$4),1,0) | AH29: =IF(AND(31>=$B$4,31<=$D$4),1,0) | AI29: =IF(AND(32>=$B$4,32<=$D$4),1,0) | AJ29: =IF(AND(33>=$B$4,33<=$D$4),1,0) | AK29: =IF(AND(34>=$B$4,34<=$D$4),1,0) | AL29: =IF(AND(35>=$B$4,35<=$D$4),1,0) | AM29: =IF(AND(36>=$B$4,36<=$D$4),1,0) | AN29: =IF(AND(37>=$B$4,37<=$D$4),1,0) | AO29: =IF(AND(38>=$B$4,38<=$D$4),1,0) | AP29: =IF(AND(39>=$B$4,39<=$D$4),1,0) | AQ29: =IF(AND(40>=$B$4,40<=$D$4),1,0) | AR29: =IF(AND(41>=$B$4,41<=$D$4),1,0) | AS29: =IF(AND(42>=$B$4,42<=$D$4),1,0) | AT29: =IF(AND(43>=$B$4,43<=$D$4),1,0) | AU29: =IF(AND(44>=$B$4,44<=$D$4),1,0) | AV29: =IF(AND(45>=$B$4,45<=$D$4),1,0) | AW29: =IF(AND(46>=$B$4,46<=$D$4),1,0) | AX29: =IF(AND(47>=$B$4,47<=$D$4),1,0) | AY29: =IF(AND(48>=$B$4,48<=$D$4),1,0) | AZ29: =IF(AND(49>=$B$4,49<=$D$4),1,0) | BA29: =IF(AND(50>=$B$4,50<=$D$4),1,0) | BB29: =IF(AND(51>=$B$4,51<=$D$4),1,0) | BC29: =IF(AND(52>=$B$4,52<=$D$4),1,0) | BD29: =IF(AND(53>=$B$4,53<=$D$4),1,0) | BE29: =IF(AND(54>=$B$4,54<=$D$4),1,0) | BF29: =IF(AND(55>=$B$4,55<=$D$4),1,0) | BG29: =IF(AND(56>=$B$4,56<=$D$4),1,0) | BH29: =IF(AND(57>=$B$4,57<=$D$4),1,0) | BI29: =IF(AND(58>=$B$4,58<=$D$4),1,0) | BJ29: =IF(AND(59>=$B$4,59<=$D$4),1,0) | BK29: =IF(AND(60>=$B$4,60<=$D$4),1,0) | BL29: =IF(AND(61>=$B$4,61<=$D$4),1,0) | BM29: =IF(AND(62>=$B$4,62<=$D$4),1,0) | BN29: =IF(AND(63>=$B$4,63<=$D$4),1,0) | BO29: =IF(AND(64>=$B$4,64<=$D$4),1,0) | BP29: =IF(AND(65>=$B$4,65<=$D$4),1,0) | BQ29: =IF(AND(66>=$B$4,66<=$D$4),1,0) | BR29: =IF(AND(67>=$B$4,67<=$D$4),1,0) | BS29: =IF(AND(68>=$B$4,68<=$D$4),1,0) | BT29: =IF(AND(69>=$B$4,69<=$D$4),1,0) | BU29: =IF(AND(70>=$B$4,70<=$D$4),1,0) | BV29: =IF(AND(71>=$B$4,71<=$D$4),1,0) | BW29: =IF(AND(72>=$B$4,72<=$D$4),1,0) | BX29: =IF(AND(73>=$B$4,73<=$D$4),1,0) | BY29: =IF(AND(74>=$B$4,74<=$D$4),1,0) | BZ29: =IF(AND(75>=$B$4,75<=$D$4),1,0) | CA29: =IF(AND(76>=$B$4,76<=$D$4),1,0) | CB29: =IF(AND(77>=$B$4,77<=$D$4),1,0) | CC29: =IF(AND(78>=$B$4,78<=$D$4),1,0) | CD29: =IF(AND(79>=$B$4,79<=$D$4),1,0) | CE29: =IF(AND(80>=$B$4,80<=$D$4),1,0) | CF29: =IF(AND(81>=$B$4,81<=$D$4),1,0) | CG29: =IF(AND(82>=$B$4,82<=$D$4),1,0) | CH29: =IF(AND(83>=$B$4,83<=$D$4),1,0) | CI29: =IF(AND(84>=$B$4,84<=$D$4),1,0) | CJ29: =IF(AND(85>=$B$4,85<=$D$4),1,0) | CK29: =IF(AND(86>=$B$4,86<=$D$4),1,0) | CL29: =IF(AND(87>=$B$4,87<=$D$4),1,0) | CM29: =IF(AND(88>=$B$4,88<=$D$4),1,0) | CN29: =IF(AND(89>=$B$4,89<=$D$4),1,0) | CO29: =IF(AND(90>=$B$4,90<=$D$4),1,0) | CP29: =IF(AND(91>=$B$4,91<=$D$4),1,0) | CQ29: =IF(AND(92>=$B$4,92<=$D$4),1,0) | CR29: =IF(AND(93>=$B$4,93<=$D$4),1,0) | CS29: =IF(AND(94>=$B$4,94<=$D$4),1,0) | CT29: =IF(AND(95>=$B$4,95<=$D$4),1,0) | CU29: =IF(AND(96>=$B$4,96<=$D$4),1,0) | CV29: =IF(AND(97>=$B$4,97<=$D$4),1,0) | CW29: =IF(AND(98>=$B$4,98<=$D$4),1,0) | CX29: =IF(AND(99>=$B$4,99<=$D$4),1,0) | CY29: =IF(AND(100>=$B$4,100<=$D$4),1,0) | CZ29: =IF(AND(101>=$B$4,101<=$D$4),1,0) | DA29: =IF(AND(102>=$B$4,102<=$D$4),1,0) | DB29: =IF(AND(103>=$B$4,103<=$D$4),1,0) | DC29: =IF(AND(104>=$B$4,104<=$D$4),1,0) | DD29: =IF(AND(105>=$B$4,105<=$D$4),1,0) | DE29: =IF(AND(106>=$B$4,106<=$D$4),1,0) | DF29: =IF(AND(107>=$B$4,107<=$D$4),1,0) | DG29: =IF(AND(108>=$B$4,108<=$D$4),1,0) | DH29: =IF(AND(109>=$B$4,109<=$D$4),1,0) | DI29: =IF(AND(110>=$B$4,110<=$D$4),1,0) | DJ29: =IF(AND(111>=$B$4,111<=$D$4),1,0) | DK29: =IF(AND(112>=$B$4,112<=$D$4),1,0) | DL29: =IF(AND(113>=$B$4,113<=$D$4),1,0) | DM29: =IF(AND(114>=$B$4,114<=$D$4),1,0) | DN29: =IF(AND(115>=$B$4,115<=$D$4),1,0) | DO29: =IF(AND(116>=$B$4,116<=$D$4),1,0) | DP29: =IF(AND(117>=$B$4,117<=$D$4),1,0) | DQ29: =IF(AND(118>=$B$4,118<=$D$4),1,0) | DR29: =IF(AND(119>=$B$4,119<=$D$4),1,0) | DS29: =IF(AND(120>=$B$4,120<=$D$4),1,0) | DT29: =IF(AND(121>=$B$4,121<=$D$4),1,0) | DU29: =IF(AND(122>=$B$4,122<=$D$4),1,0) | DV29: =IF(AND(123>=$B$4,123<=$D$4),1,0) | DW29: =IF(AND(124>=$B$4,124<=$D$4),1,0) | DX29: =IF(AND(125>=$B$4,125<=$D$4),1,0) | DY29: =IF(AND(126>=$B$4,126<=$D$4),1,0) | DZ29: =IF(AND(127>=$B$4,127<=$D$4),1,0) | EA29: =IF(AND(128>=$B$4,128<=$D$4),1,0) | EB29: =IF(AND(129>=$B$4,129<=$D$4),1,0) | EC29: =IF(AND(130>=$B$4,130<=$D$4),1,0) | ED29: =IF(AND(131>=$B$4,131<=$D$4),1,0) | EE29: =IF(AND(132>=$B$4,132<=$D$4),1,0) | EF29: =IF(AND(133>=$B$4,133<=$D$4),1,0) | EG29: =IF(AND(134>=$B$4,134<=$D$4),1,0) | EH29: =IF(AND(135>=$B$4,135<=$D$4),1,0) | EI29: =IF(AND(136>=$B$4,136<=$D$4),1,0) | EJ29: =IF(AND(137>=$B$4,137<=$D$4),1,0) | EK29: =IF(AND(138>=$B$4,138<=$D$4),1,0) | EL29: =IF(AND(139>=$B$4,139<=$D$4),1,0) | EM29: =IF(AND(140>=$B$4,140<=$D$4),1,0) | EN29: =IF(AND(141>=$B$4,141<=$D$4),1,0) | EO29: =IF(AND(142>=$B$4,142<=$D$4),1,0) | EP29: =IF(AND(143>=$B$4,143<=$D$4),1,0) | EQ29: =IF(AND(144>=$B$4,144<=$D$4),1,0) | ER29: =IF(AND(145>=$B$4,145<=$D$4),1,0) | ES29: =IF(AND(146>=$B$4,146<=$D$4),1,0) | ET29: =IF(AND(147>=$B$4,147<=$D$4),1,0) | EU29: =IF(AND(148>=$B$4,148<=$D$4),1,0) | EV29: =IF(AND(149>=$B$4,149<=$D$4),1,0) | EW29: =IF(AND(150>=$B$4,150<=$D$4),1,0) | EX29: =IF(AND(151>=$B$4,151<=$D$4),1,0) | EY29: =IF(AND(152>=$B$4,152<=$D$4),1,0) | EZ29: =IF(AND(153>=$B$4,153<=$D$4),1,0) | FA29: =IF(AND(154>=$B$4,154<=$D$4),1,0) | FB29: =IF(AND(155>=$B$4,155<=$D$4),1,0) | FC29: =IF(AND(156>=$B$4,156<=$D$4),1,0) | FD29: =IF(AND(157>=$B$4,157<=$D$4),1,0) | FE29: =IF(AND(158>=$B$4,158<=$D$4),1,0) | FF29: =IF(AND(159>=$B$4,159<=$D$4),1,0) | FG29: =IF(AND(160>=$B$4,160<=$D$4),1,0) | FH29: =IF(AND(161>=$B$4,161<=$D$4),1,0) | FI29: =IF(AND(162>=$B$4,162<=$D$4),1,0) | FJ29: =IF(AND(163>=$B$4,163<=$D$4),1,0) | FK29: =IF(AND(164>=$B$4,164<=$D$4),1,0) | FL29: =IF(AND(165>=$B$4,165<=$D$4),1,0) | FM29: =IF(AND(166>=$B$4,166<=$D$4),1,0) | FN29: =IF(AND(167>=$B$4,167<=$D$4),1,0) | FO29: =IF(AND(168>=$B$4,168<=$D$4),1,0) | FP29: =IF(AND(169>=$B$4,169<=$D$4),1,0) | FQ29: =IF(AND(170>=$B$4,170<=$D$4),1,0) | FR29: =IF(AND(171>=$B$4,171<=$D$4),1,0) | FS29: =IF(AND(172>=$B$4,172<=$D$4),1,0) | FT29: =IF(AND(173>=$B$4,173<=$D$4),1,0) | FU29: =IF(AND(174>=$B$4,174<=$D$4),1,0) | FV29: =IF(AND(175>=$B$4,175<=$D$4),1,0) | FW29: =IF(AND(176>=$B$4,176<=$D$4),1,0) | FX29: =IF(AND(177>=$B$4,177<=$D$4),1,0) | FY29: =IF(AND(178>=$B$4,178<=$D$4),1,0) | FZ29: =IF(AND(179>=$B$4,179<=$D$4),1,0) | GA29: =IF(AND(180>=$B$4,180<=$D$4),1,0) | GB29: =IF(AND(181>=$B$4,181<=$D$4),1,0) | GC29: =IF(AND(182>=$B$4,182<=$D$4),1,0) | GD29: =IF(AND(183>=$B$4,183<=$D$4),1,0) | GE29: =IF(AND(184>=$B$4,184<=$D$4),1,0) | GF29: =IF(AND(185>=$B$4,185<=$D$4),1,0) | GG29: =IF(AND(186>=$B$4,186<=$D$4),1,0) | GH29: =IF(AND(187>=$B$4,187<=$D$4),1,0) | GI29: =IF(AND(188>=$B$4,188<=$D$4),1,0) | GJ29: =IF(AND(189>=$B$4,189<=$D$4),1,0) | GK29: =IF(AND(190>=$B$4,190<=$D$4),1,0) | GL29: =IF(AND(191>=$B$4,191<=$D$4),1,0) | GM29: =IF(AND(192>=$B$4,192<=$D$4),1,0) | GN29: =IF(AND(193>=$B$4,193<=$D$4),1,0) | GO29: =IF(AND(194>=$B$4,194<=$D$4),1,0) | GP29: =IF(AND(195>=$B$4,195<=$D$4),1,0) | GQ29: =IF(AND(196>=$B$4,196<=$D$4),1,0) | GR29: =IF(AND(197>=$B$4,197<=$D$4),1,0) | GS29: =IF(AND(198>=$B$4,198<=$D$4),1,0) | GT29: =IF(AND(199>=$B$4,199<=$D$4),1,0) | GU29: =IF(AND(200>=$B$4,200<=$D$4),1,0) | GV29: =IF(AND(201>=$B$4,201<=$D$4),1,0) | GW29: =IF(AND(202>=$B$4,202<=$D$4),1,0) | GX29: =IF(AND(203>=$B$4,203<=$D$4),1,0) | GY29: =IF(AND(204>=$B$4,204<=$D$4),1,0) | GZ29: =IF(AND(205>=$B$4,205<=$D$4),1,0) | HA29: =IF(AND(206>=$B$4,206<=$D$4),1,0) | HB29: =IF(AND(207>=$B$4,207<=$D$4),1,0) | HC29: =IF(AND(208>=$B$4,208<=$D$4),1,0) | HD29: =IF(AND(209>=$B$4,209<=$D$4),1,0) | HE29: =IF(AND(210>=$B$4,210<=$D$4),1,0) | HF29: =IF(AND(211>=$B$4,211<=$D$4),1,0) | HG29: =IF(AND(212>=$B$4,212<=$D$4),1,0) | HH29: =IF(AND(213>=$B$4,213<=$D$4),1,0) | HI29: =IF(AND(214>=$B$4,214<=$D$4),1,0) | HJ29: =IF(AND(215>=$B$4,215<=$D$4),1,0) | HK29: =IF(AND(216>=$B$4,216<=$D$4),1,0) | HL29: =IF(AND(217>=$B$4,217<=$D$4),1,0) | HM29: =IF(AND(218>=$B$4,218<=$D$4),1,0) | HN29: =IF(AND(219>=$B$4,219<=$D$4),1,0) | HO29: =IF(AND(220>=$B$4,220<=$D$4),1,0) | HP29: =IF(AND(221>=$B$4,221<=$D$4),1,0) | HQ29: =IF(AND(222>=$B$4,222<=$D$4),1,0) | HR29: =IF(AND(223>=$B$4,223<=$D$4),1,0) | HS29: =IF(AND(224>=$B$4,224<=$D$4),1,0) | HT29: =IF(AND(225>=$B$4,225<=$D$4),1,0) | HU29: =IF(AND(226>=$B$4,226<=$D$4),1,0) | HV29: =IF(AND(227>=$B$4,227<=$D$4),1,0) | HW29: =IF(AND(228>=$B$4,228<=$D$4),1,0) | HX29: =IF(AND(229>=$B$4,229<=$D$4),1,0) | HY29: =IF(AND(230>=$B$4,230<=$D$4),1,0) | HZ29: =IF(AND(231>=$B$4,231<=$D$4),1,0) | IA29: =IF(AND(232>=$B$4,232<=$D$4),1,0) | IB29: =IF(AND(233>=$B$4,233<=$D$4),1,0) | IC29: =IF(AND(234>=$B$4,234<=$D$4),1,0) | ID29: =IF(AND(235>=$B$4,235<=$D$4),1,0) | IE29: =IF(AND(236>=$B$4,236<=$D$4),1,0) | IF29: =IF(AND(237>=$B$4,237<=$D$4),1,0) | IG29: =IF(AND(238>=$B$4,238<=$D$4),1,0) | IH29: =IF(AND(239>=$B$4,239<=$D$4),1,0) | II29: =IF(AND(240>=$B$4,240<=$D$4),1,0) | IJ29: =IF(AND(241>=$B$4,241<=$D$4),1,0) | IK29: =IF(AND(242>=$B$4,242<=$D$4),1,0) | IL29: =IF(AND(243>=$B$4,243<=$D$4),1,0) | IM29: =IF(AND(244>=$B$4,244<=$D$4),1,0) | IN29: =IF(AND(245>=$B$4,245<=$D$4),1,0) | IO29: =IF(AND(246>=$B$4,246<=$D$4),1,0) | IP29: =IF(AND(247>=$B$4,247<=$D$4),1,0) | IQ29: =IF(AND(248>=$B$4,248<=$D$4),1,0) | IR29: =IF(AND(249>=$B$4,249<=$D$4),1,0) | IS29: =IF(AND(250>=$B$4,250<=$D$4),1,0) | IT29: =IF(AND(251>=$B$4,251<=$D$4),1,0) | IU29: =IF(AND(252>=$B$4,252<=$D$4),1,0) | IV29: =IF(AND(253>=$B$4,253<=$D$4),1,0) | IW29: =IF(AND(254>=$B$4,254<=$D$4),1,0) | IX29: =IF(AND(255>=$B$4,255<=$D$4),1,0) | IY29: =IF(AND(256>=$B$4,256<=$D$4),1,0) | IZ29: =IF(AND(257>=$B$4,257<=$D$4),1,0) | JA29: =IF(AND(258>=$B$4,258<=$D$4),1,0) | JB29: =IF(AND(259>=$B$4,259<=$D$4),1,0) | JC29: =IF(AND(260>=$B$4,260<=$D$4),1,0) | JD29: =IF(AND(261>=$B$4,261<=$D$4),1,0) | JE29: =IF(AND(262>=$B$4,262<=$D$4),1,0) | JF29: =IF(AND(263>=$B$4,263<=$D$4),1,0) | JG29: =IF(AND(264>=$B$4,264<=$D$4),1,0) | JH29: =IF(AND(265>=$B$4,265<=$D$4),1,0) | JI29: =IF(AND(266>=$B$4,266<=$D$4),1,0) | JJ29: =IF(AND(267>=$B$4,267<=$D$4),1,0) | JK29: =IF(AND(268>=$B$4,268<=$D$4),1,0) | JL29: =IF(AND(269>=$B$4,269<=$D$4),1,0) | JM29: =IF(AND(270>=$B$4,270<=$D$4),1,0) | JN29: =IF(AND(271>=$B$4,271<=$D$4),1,0) | JO29: =IF(AND(272>=$B$4,272<=$D$4),1,0) | JP29: =IF(AND(273>=$B$4,273<=$D$4),1,0) | JQ29: =IF(AND(274>=$B$4,274<=$D$4),1,0) | JR29: =IF(AND(275>=$B$4,275<=$D$4),1,0) | JS29: =IF(AND(276>=$B$4,276<=$D$4),1,0) | JT29: =IF(AND(277>=$B$4,277<=$D$4),1,0) | JU29: =IF(AND(278>=$B$4,278<=$D$4),1,0) | JV29: =IF(AND(279>=$B$4,279<=$D$4),1,0) | JW29: =IF(AND(280>=$B$4,280<=$D$4),1,0) | JX29: =IF(AND(281>=$B$4,281<=$D$4),1,0) | JY29: =IF(AND(282>=$B$4,282<=$D$4),1,0) | JZ29: =IF(AND(283>=$B$4,283<=$D$4),1,0) | KA29: =IF(AND(284>=$B$4,284<=$D$4),1,0) | KB29: =IF(AND(285>=$B$4,285<=$D$4),1,0) | KC29: =IF(AND(286>=$B$4,286<=$D$4),1,0) | KD29: =IF(AND(287>=$B$4,287<=$D$4),1,0) | KE29: =IF(AND(288>=$B$4,288<=$D$4),1,0) | KF29: =IF(AND(289>=$B$4,289<=$D$4),1,0) | KG29: =IF(AND(290>=$B$4,290<=$D$4),1,0) | KH29: =IF(AND(291>=$B$4,291<=$D$4),1,0) | KI29: =IF(AND(292>=$B$4,292<=$D$4),1,0) | KJ29: =IF(AND(293>=$B$4,293<=$D$4),1,0) | KK29: =IF(AND(294>=$B$4,294<=$D$4),1,0) | KL29: =IF(AND(295>=$B$4,295<=$D$4),1,0) | KM29: =IF(AND(296>=$B$4,296<=$D$4),1,0) | KN29: =IF(AND(297>=$B$4,297<=$D$4),1,0) | KO29: =IF(AND(298>=$B$4,298<=$D$4),1,0) | KP29: =IF(AND(299>=$B$4,299<=$D$4),1,0) | KQ29: =IF(AND(300>=$B$4,300<=$D$4),1,0) | KR29: =IF(AND(301>=$B$4,301<=$D$4),1,0) | KS29: =IF(AND(302>=$B$4,302<=$D$4),1,0) | KT29: =IF(AND(303>=$B$4,303<=$D$4),1,0) | KU29: =IF(AND(304>=$B$4,304<=$D$4),1,0) | KV29: =IF(AND(305>=$B$4,305<=$D$4),1,0) | KW29: =IF(AND(306>=$B$4,306<=$D$4),1,0) | KX29: =IF(AND(307>=$B$4,307<=$D$4),1,0) | KY29: =IF(AND(308>=$B$4,308<=$D$4),1,0) | KZ29: =IF(AND(309>=$B$4,309<=$D$4),1,0) | LA29: =IF(AND(310>=$B$4,310<=$D$4),1,0) | LB29: =IF(AND(311>=$B$4,311<=$D$4),1,0) | LC29: =IF(AND(312>=$B$4,312<=$D$4),1,0) | LD29: =IF(AND(313>=$B$4,313<=$D$4),1,0) | LE29: =IF(AND(314>=$B$4,314<=$D$4),1,0) | LF29: =IF(AND(315>=$B$4,315<=$D$4),1,0) | LG29: =IF(AND(316>=$B$4,316<=$D$4),1,0) | LH29: =IF(AND(317>=$B$4,317<=$D$4),1,0) | LI29: =IF(AND(318>=$B$4,318<=$D$4),1,0) | LJ29: =IF(AND(319>=$B$4,319<=$D$4),1,0) | LK29: =IF(AND(320>=$B$4,320<=$D$4),1,0) | LL29: =IF(AND(321>=$B$4,321<=$D$4),1,0) | LM29: =IF(AND(322>=$B$4,322<=$D$4),1,0) | LN29: =IF(AND(323>=$B$4,323<=$D$4),1,0) | LO29: =IF(AND(324>=$B$4,324<=$D$4),1,0) | LP29: =IF(AND(325>=$B$4,325<=$D$4),1,0) | LQ29: =IF(AND(326>=$B$4,326<=$D$4),1,0) | LR29: =IF(AND(327>=$B$4,327<=$D$4),1,0) | LS29: =IF(AND(328>=$B$4,328<=$D$4),1,0) | LT29: =IF(AND(329>=$B$4,329<=$D$4),1,0) | LU29: =IF(AND(330>=$B$4,330<=$D$4),1,0) | LV29: =IF(AND(331>=$B$4,331<=$D$4),1,0) | LW29: =IF(AND(332>=$B$4,332<=$D$4),1,0) | LX29: =IF(AND(333>=$B$4,333<=$D$4),1,0) | LY29: =IF(AND(334>=$B$4,334<=$D$4),1,0) | LZ29: =IF(AND(335>=$B$4,335<=$D$4),1,0) | MA29: =IF(AND(336>=$B$4,336<=$D$4),1,0) | MB29: =IF(AND(337>=$B$4,337<=$D$4),1,0) | MC29: =IF(AND(338>=$B$4,338<=$D$4),1,0) | MD29: =IF(AND(339>=$B$4,339<=$D$4),1,0) | ME29: =IF(AND(340>=$B$4,340<=$D$4),1,0) | MF29: =IF(AND(341>=$B$4,341<=$D$4),1,0) | MG29: =IF(AND(342>=$B$4,342<=$D$4),1,0) | MH29: =IF(AND(343>=$B$4,343<=$D$4),1,0) | MI29: =IF(AND(344>=$B$4,344<=$D$4),1,0) | MJ29: =IF(AND(345>=$B$4,345<=$D$4),1,0) | MK29: =IF(AND(346>=$B$4,346<=$D$4),1,0) | ML29: =IF(AND(347>=$B$4,347<=$D$4),1,0) | MM29: =IF(AND(348>=$B$4,348<=$D$4),1,0) | MN29: =IF(AND(349>=$B$4,349<=$D$4),1,0) | MO29: =IF(AND(350>=$B$4,350<=$D$4),1,0) | MP29: =IF(AND(351>=$B$4,351<=$D$4),1,0) | MQ29: =IF(AND(352>=$B$4,352<=$D$4),1,0) | MR29: =IF(AND(353>=$B$4,353<=$D$4),1,0) | MS29: =IF(AND(354>=$B$4,354<=$D$4),1,0) | MT29: =IF(AND(355>=$B$4,355<=$D$4),1,0) | MU29: =IF(AND(356>=$B$4,356<=$D$4),1,0) | MV29: =IF(AND(357>=$B$4,357<=$D$4),1,0) | MW29: =IF(AND(358>=$B$4,358<=$D$4),1,0) | MX29: =IF(AND(359>=$B$4,359<=$D$4),1,0) | MY29: =IF(AND(360>=$B$4,360<=$D$4),1,0) | MZ29: =IF(AND(361>=$B$4,361<=$D$4),1,0) | NA29: =IF(AND(362>=$B$4,362<=$D$4),1,0) | NB29: =IF(AND(363>=$B$4,363<=$D$4),1,0) | NC29: =IF(AND(364>=$B$4,364<=$D$4),1,0) | ND29: =IF(AND(365>=$B$4,365<=$D$4),1,0) | NE29: =IF(AND(366>=$B$4,366<=$D$4),1,0) | NF29: =IF(AND(367>=$B$4,367<=$D$4),1,0) | NG29: =IF(AND(368>=$B$4,368<=$D$4),1,0) | NH29: =IF(AND(369>=$B$4,369<=$D$4),1,0) | NI29: =IF(AND(370>=$B$4,370<=$D$4),1,0) | NJ29: =IF(AND(371>=$B$4,371<=$D$4),1,0) | NK29: =IF(AND(372>=$B$4,372<=$D$4),1,0)
