Workbook
Name InvestmentType: 'Inputs'!$B$5
Name PropertyName: 'Inputs'!$B$6
Name City: 'Inputs'!$B$7
Name State: 'Inputs'!$B$8
Name Market: 'Inputs'!$B$9
Name ProductType: 'Inputs'!$B$10
Name Location: 'Inputs'!$B$11
Name InceptionDate: 'Inputs'!$B$12
Name HoldPeriodMonths: 'Inputs'!$B$15
Name EntryCapRate: 'Inputs'!$B$16
Name CapAdjLocation: 'Inputs'!$B$17
Name CapAdjSize: 'Inputs'!$B$18
Name CapAdjAging: 'Inputs'!$B$19
Name ExitCapResidential: 'Inputs'!$B$20
Name ExitCapRetail: 'Inputs'!$B$21
Name GrowthRent: 'Inputs'!$B$22
Name GrowthLowIncRent: 'Inputs'!$B$23
Name GrowthExpense: 'Inputs'!$B$24
Name GrowthUtility: 'Inputs'!$B$25
Name GrowthTax: 'Inputs'!$B$26
Name GrowthOther: 'Inputs'!$B$27
Name GrowthStartDate: 'Inputs'!$B$28
Name LeaseUpIncomeOffset: 'Inputs'!$B$31
Name UnitsDeliveredPerMo: 'Inputs'!$B$32
Name UnitsLeasedPerMo: 'Inputs'!$B$33
Name LeaseUpRampPct: 'Inputs'!$B$34
Name LeaseUpElevationPct: 'Inputs'!$B$35
Name StabilizedOccupancy: 'Inputs'!$B$36
Name LandCost: 'Inputs'!$B$39
Name GrossAcres: 'Inputs'!$B$40
Name NetAcres: 'Inputs'!$B$41
Name FARRatio: 'Inputs'!$B$42
Name EfficiencyRatio: 'Inputs'!$B$43
Name ExistingStructureCost: 'Inputs'!$B$44
Name TaxLevyPct: 'Inputs'!$B$47
Name TaxAssessmentPct: 'Inputs'!$B$48
Name TaxValueAdjFactor: 'Inputs'!$B$49
Name TaxMethodValue: 'Inputs'!$B$50
Name TaxYear1Override: 'Inputs'!$B$51
Name ReassessOnSale: 'Inputs'!$B$52
Name DispoTaxRatePct: 'Inputs'!$B$53
Name FundingOrderPari: 'Inputs'!$B$56
Name TargetLTC: 'Inputs'!$B$57
Name OpReserveCoverage: 'Inputs'!$B$58
Name OpReserveMinMonths: 'Inputs'!$B$59
Name ConLoanTermMonths: 'Inputs'!$B$62
Name ConRate: 'Inputs'!$B$63
Name ConActual360: 'Inputs'!$B$64
Name ConPointsPct: 'Inputs'!$B$65
Name ConOtherCosts: 'Inputs'!$B$66
Name ConMinDebtYield: 'Inputs'!$B$67
Name ConMinDSCR: 'Inputs'!$B$68
Name LenderReqReserveOverride: 'Inputs'!$B$69
Name PermMaxLTV: 'Inputs'!$B$72
Name PermRate: 'Inputs'!$B$73
Name PermTermMonths: 'Inputs'!$B$74
Name PermIOMonths: 'Inputs'!$B$75
Name PermAmortMonths: 'Inputs'!$B$76
Name PermActual360: 'Inputs'!$B$77
Name PermPointsPct: 'Inputs'!$B$78

Sheet Dashboard

Sheet Inputs
A1: Institutional Multifamily Development Model — Inputs
A2: Blue = hard-keyed input. Every value below is a workbook named range.
A4: Property Details
A5: Investment Type | B5: Ground-Up Development | C5: Investment type
A6: Property Name | B6: Meridian Apartments | C6: Deal name
A7: City | B7: Austin
A8: State | B8: TX
A9: Market | B9: Austin-Round Rock | C9: MSA
A10: Product Type | B10: Garden / Mid-Rise
A11: Location | B11: Suburban Infill
A12: Inception Date | B12: 46023 | C12: Model period 1 = this month
A14: Investment Details
A15: Hold Period Months | B15: 84 | C15: Disposition month (1-360 toggle)
A16: Entry Cap Rate | B16: 0.0475 | C16: Market / entry cap rate
A17: Cap Adj Location | B17: 0 | C17: Location adjustment (+/-)
A18: Cap Adj Size | B18: 0 | C18: Size adjustment (+/-)
A19: Cap Adj Aging | B19: 0.0025 | C19: Aging adjustment (+/-)
A20: Exit Cap Residential | B20: 0.05 | C20: Exit cap - residential
A21: Exit Cap Retail | B21: 0.065 | C21: Exit cap - retail
A22: Growth Rent | B22: 0.03 | C22: Annual market-rent growth
A23: Growth Low Inc Rent | B23: 0.02 | C23: Annual low-income-rent growth
A24: Growth Expense | B24: 0.03 | C24: Annual expense growth
A25: Growth Utility | B25: 0.035 | C25: Annual utility growth
A26: Growth Tax | B26: 0.02 | C26: Annual tax growth
... A28: Growth Start Date | B28: 46054 | C28: Date all growth trending begins (override)
A30: Unit Delivery & Lease-Up
A31: Lease Up Income Offset | B31: 1 | C31: 1=offset lease-up income vs equity, 0=no
A32: Units Delivered Per Mo | B32: 30 | C32: Units delivered per month
A33: Units Leased Per Mo | B33: 18 | C33: Units absorbed (leased) per month
A34: Lease Up Ramp Pct | B34: 0.6 | C34: Variable-opex ramp: % of stabilized during lease-up
A35: Lease Up Elevation Pct | B35: 0.25 | C35: Elevated-opex uplift over stabilized during lease-up
A36: Stabilized Occupancy | B36: 0.93 | C36: Physical occupancy at stabilization
A38: Site Details
A39: Land Cost | B39: 14000000 | C39: Total land cost
A40: Gross Acres | B40: 9.5 | C40: Gross site acres
A41: Net Acres | B41: 8 | C41: Net developable acres
A42: FARRatio | B42: 1.75 | C42: Floor-area ratio
A43: Efficiency Ratio | B43: 0.85 | C43: Net rentable / gross buildable
A44: Existing Structure Cost | B44: 0 | C44: Demo / existing structure
A46: Property Taxes
...

Sheet UnitMatrix
A1: Unit Matrix — Residential & Retail
A3: Plan | B3: Class | C3: Units | D3: Avg SF | E3: Total SF | F3: Market Rent | G3: Net Eff. Rent | H3: Annual Rent | I3: Rent / SF | J3: % of Total
A4: Studio | B4: Market | C4: 40 | D4: 540 | E4: =C4*D4 | F4: 1895 | G4: 1845 | H4: =C4*F4*12 | I4: =IF(D4=0,0,F4/D4) | J4: =IF(TotalUnits=0,0,C4/TotalUnits)
A5: 1BR-A | B5: Market | C5: 60 | D5: 720 | E5: =C5*D5 | F5: 2245 | G5: 2195 | H5: =C5*F5*12 | I5: =IF(D5=0,0,F5/D5) | J5: =IF(TotalUnits=0,0,C5/TotalUnits)
A6: 1BR-B | B6: Market | C6: 30 | D6: 780 | E6: =C6*D6 | F6: 2360 | G6: 2300 | H6: =C6*F6*12 | I6: =IF(D6=0,0,F6/D6) | J6: =IF(TotalUnits=0,0,C6/TotalUnits)
A7: 2BR-A | B7: Market | C7: 40 | D7: 1050 | E7: =C7*D7 | F7: 3050 | G7: 2975 | H7: =C7*F7*12 | I7: =IF(D7=0,0,F7/D7) | J7: =IF(TotalUnits=0,0,C7/TotalUnits)
A8: 2BR-B | B8: Market | C8: 10 | D8: 1150 | E8: =C8*D8 | F8: 3220 | G8: 3140 | H8: =C8*F8*12 | I8: =IF(D8=0,0,F8/D8) | J8: =IF(TotalUnits=0,0,C8/TotalUnits)
A9: 1BR-LI | B9: Low | C9: 12 | D9: 720 | E9: =C9*D9 | F9: 1350 | G9: 1350 | H9: =C9*F9*12 | I9: =IF(D9=0,0,F9/D9) | J9: =IF(TotalUnits=0,0,C9/TotalUnits)
A10: 2BR-LI | B10: Low | C10: 8 | D10: 1050 | E10: =C10*D10 | F10: 1625 | G10: 1625 | H10: =C10*F10*12 | I10: =IF(D10=0,0,F10/D10) | J10: =IF(TotalUnits=0,0,C10/TotalUnits)
A11: Total / Weighted | C11: =SUM(C4:C10) | E11: =SUM(E4:E10) | H11: =SUM(H4:H10)
A13: Derived Unit Metrics
A14: Total Units | B14: =SUM(C4:C10)
A15: Market-Rate Units | B15: =SUMIF(B4:B10,"Market",C4:C10)
A16: Low-Income Units | B16: =SUMIF(B4:B10,"Low",C4:C10)
A17: Net Rentable SF (NRSF) | B17: =SUM(E4:E10)
A18: Buildable SF | B18: =NRSF/EfficiencyRatio
A19: Avg Unit SF | B19: =IF(TotalUnits=0,0,NRSF/TotalUnits)
A20: Base Market Rent / mo | B20: =SUMPRODUCT((B4:B10="Market")*C4:C10*F4:F10)
A21: Base Low-Income Rent / mo | B21: =SUMPRODUCT((B4:B10="Low")*C4:C10*F4:F10)
A23: Retail Matrix
A24: Suite | B24: SF | C24: Rent / SF / yr | D24: Annual Rent | E24: Monthly Rent
A25: Retail-1 | B25: 4200 | C25: 34 | D25: =B25*C25 | E25: =B25*C25/12
A26: Retail-2 | B26: 3100 | C26: 32 | D26: =B26*C26 | E26: =B26*C26/12
A27: Retail Rent / mo | B27: =SUM(E25:E26)

Sheet Budget
A1: Development Budget & Cost Assumptions
A2: Basis: abs=$ unit=$/unit sf=$/NRSF. Modeled Total drives the cost-curve engine.
A4: Line Item | B4: Group | C4: Type | D4: Basis | E4: Amount | F4: Phase | G4: Cost Curve | H4: Modifier | I4: Modeled Total | J4: Per Unit | K4: Per SF
A5: Land Acquisition | B5: Land | C5: Land | D5: abs | E5: =LandCost | F5: Initial Closing | G5: Single_Point | H5: 0 | I5: =IF(D5="abs",E5,IF(D5="unit",E5*TotalUnits,IF(D5="sf",E5*NRSF,E5))) | J5: =IF(TotalUnits=0,0,I5/TotalUnits) | K5: =IF(NRSF=0,0,I5/NRSF)
A6: Existing Structure/Demo | B6: Land | C6: Land | D6: abs | E6: =ExistingStructureCost | F6: Pre-Construction | G6: Straight_Line | H6: 0 | I6: =IF(D6="abs",E6,IF(D6="unit",E6*TotalUnits,IF(D6="sf",E6*NRSF,E6))) | J6: =IF(TotalUnits=0,0,I6/TotalUnits) | K6: =IF(NRSF=0,0,I6/NRSF)
A7: Due Diligence | B7: Soft | C7: Soft | D7: abs | E7: 150000 | F7: Due Diligence | G7: Straight_Line | H7: 0 | I7: =IF(D7="abs",E7,IF(D7="unit",E7*TotalUnits,IF(D7="sf",E7*NRSF,E7))) | J7: =IF(TotalUnits=0,0,I7/TotalUnits) | K7: =IF(NRSF=0,0,I7/NRSF)
A8: Entitlements | B8: Soft | C8: Soft | D8: abs | E8: 600000 | F8: Entitlement | G8: Straight_Line | H8: 0 | I8: =IF(D8="abs",E8,IF(D8="unit",E8*TotalUnits,IF(D8="sf",E8*NRSF,E8))) | J8: =IF(TotalUnits=0,0,I8/TotalUnits) | K8: =IF(NRSF=0,0,I8/NRSF)
A9: Architecture & Eng. | B9: Soft | C9: Soft | D9: sf | E9: 6.5 | F9: Pre-Construction | G9: Straight_Line | H9: 0 | I9: =IF(D9="abs",E9,IF(D9="unit",E9*TotalUnits,IF(D9="sf",E9*NRSF,E9))) | J9: =IF(TotalUnits=0,0,I9/TotalUnits) | K9: =IF(NRSF=0,0,I9/NRSF)
A10: Consultants | B10: Soft | C10: Soft | D10: abs | E10: 400000 | F10: Entitlement | G10: Straight_Line | H10: 0 | I10: =IF(D10="abs",E10,IF(D10="unit",E10*TotalUnits,IF(D10="sf",E10*NRSF,E10))) | J10: =IF(TotalUnits=0,0,I10/TotalUnits) | K10: =IF(NRSF=0,0,I10/NRSF)
A11: Legal & Org. | B11: Soft | C11: Soft | D11: abs | E11: 300000 | F11: Due Diligence | G11: Straight_Line | H11: 0 | I11: =IF(D11="abs",E11,IF(D11="unit",E11*TotalUnits,IF(D11="sf",E11*NRSF,E11))) | J11: =IF(TotalUnits=0,0,I11/TotalUnits) | K11: =IF(NRSF=0,0,I11/NRSF)
A12: Marketing & Lease-Up | B12: Soft | C12: Soft | D12: unit | E12: 1200 | F12: Lease-Up | G12: Straight_Line | H12: 0 | I12: =IF(D12="abs",E12,IF(D12="unit",E12*TotalUnits,IF(D12="sf",E12*NRSF,E12))) | J12: =IF(TotalUnits=0,0,I12/TotalUnits) | K12: =IF(NRSF=0,0,I12/NRSF)
A13: Insurance (Dev) | B13: Soft | C13: Soft | D13: abs | E13: 500000 | F13: Construction | G13: Straight_Line | H13: 0 | I13: =IF(D13="abs",E13,IF(D13="unit",E13*TotalUnits,IF(D13="sf",E13*NRSF,E13))) | J13: =IF(TotalUnits=0,0,I13/TotalUnits) | K13: =IF(NRSF=0,0,I13/NRSF)
A14: GC Contract (Hard) | B14: Hard | C14: Hard | D14: sf | E14: 200 | F14: Construction | G14: Bell_Curve | H14: 0 | I14: =IF(D14="abs",E14,IF(D14="unit",E14*TotalUnits,IF(D14="sf",E14*NRSF,E14))) | J14: =IF(TotalUnits=0,0,I14/TotalUnits) | K14: =IF(NRSF=0,0,I14/NRSF)
A15: Off-Site Improvements | B15: Hard | C15: Hard | D15: abs | E15: 1200000 | F15: Construction | G15: Straight_Line | H15: 0 | I15: =IF(D15="abs",E15,IF(D15="unit",E15*TotalUnits,IF(D15="sf",E15*NRSF,E15))) | J15: =IF(TotalUnits=0,0,I15/TotalUnits) | K15: =IF(NRSF=0,0,I15/NRSF)
A16: Utilities & Hookups | B16: Hard | C16: Hard | D16: abs | E16: 900000 | F16: Construction | G16: Straight_Line | H16: 0 | I16: =IF(D16="abs",E16,IF(D16="unit",E16*TotalUnits,IF(D16="sf",E16*NRSF,E16))) | J16: =IF(TotalUnits=0,0,I16/TotalUnits) | K16: =IF(NRSF=0,0,I16/NRSF)
A17: Builder's Risk | B17: Hard | C17: Hard | D17: abs | E17: 350000 | F17: Construction | G17: Straight_Line | H17: 0 | I17: =IF(D17="abs",E17,IF(D17="unit",E17*TotalUnits,IF(D17="sf",E17*NRSF,E17))) | J17: =IF(TotalUnits=0,0,I17/TotalUnits) | K17: =IF(NRSF=0,0,I17/NRSF)
A18: Hard Cost Contingency | B18: Hard | C18: Hard | D18: sf | E18: 10 | F18: Construction | G18: Bell_Curve | H18: 0 | I18: =IF(D18="abs",E18,IF(D18="unit",E18*TotalUnits,IF(D18="sf",E18*NRSF,E18))) | J18: =IF(TotalUnits=0,0,I18/TotalUnits) | K18: =IF(NRSF=0,0,I18/NRSF)
... A31: Other Hard Cost 6 | B31: Hard | C31: Hard | D31: abs | E31: 0 | F31: Construction | G31: Bell_Curve | H31: 0 | I31: =IF(D31="abs",E31,IF(D31="unit",E31*TotalUnits,IF(D31="sf",E31*NRSF,E31))) | J31: =IF(TotalUnits=0,0,I31/TotalUnits) | K31: =IF(NRSF=0,0,I31/NRSF)
A33: Budget Summary
A34: Land | I34: =SUMIF(B5:B31,"Land",I5:I31)
A35: Soft Costs | I35: =SUMIF(B5:B31,"Soft",I5:I31)
A36: Hard Costs | I36: =SUMIF(B5:B31,"Hard",I5:I31)
A37: Direct Costs (subtotal) | I37: =SUM(I5:I31)
A38: Sponsor Development Fee | I38: =DevFeePctDirect*DirectCosts
A39: Total Development Cost (per Diagnostics) | I39: =TDC_Total

Sheet Timeline
A1: Timeline Engine — Milestones & Monthly Period Grid
A3: Milestone | B3: Start (mo) | C3: Duration (mo) | D3: End (mo)
A4: Open Escrow | B4: 1 | C4: 1 | D4: =B4+C4-1
A5: Due Diligence | B5: 1 | C5: 3 | D5: =B5+C5-1
A6: Entitlement | B6: 2 | C6: 5 | D6: =B6+C6-1
A7: Pre-Construction | B7: 5 | C7: 3 | D7: =B7+C7-1
A8: Initial Closing | B8: 7 | C8: 1 | D8: =B8+C8-1
A9: Construction | B9: 7 | C9: 20 | D9: =B9+C9-1
A10: 1st Unit Delivery | B10: 21 | C10: 1 | D10: =B10+C10-1
A11: Lease-Up | B11: 21 | C11: 12 | D11: =B11+C11-1
A12: Stabilization | B12: 33 | C12: 1 | D12: =B12+C12-1
A13: Recapitalization/Refinance | B13: 43 | C13: 1 | D13: =B13+C13-1
A14: Disposition | B14: =HoldPeriodMonths | C14: 1 | D14: =B14+C14-1
A16: Key Timing (derived)
A17: Construction Start | B17: =MS_Construction_Start
A18: Construction Maturity | B18: =ConStart+ConLoanTermMonths-1
A19: 1st Unit Delivery | B19: =MS_1st_Unit_Delivery_Start
A20: Stabilization Month | B20: =MS_Stabilization_Start
A21: Disposition Month | B21: =HoldPeriodMonths
A22: Growth Start Month | B22: =(YEAR(GrowthStartDate)-YEAR(InceptionDate))*12+MONTH(GrowthStartDate)-MONTH(InceptionDate)+1
A23: Refi Flag (1=refi,0=sell) | B23: =IF(DispoMonth>ConMaturity,1,0)
A24: Refi Month | B24: =IF(RefiFlag=1,MIN(ConMaturity,IF(RefiMonthOverride>0,RefiMonthOverride,ConMaturity)),0)
A25: Con Payoff Month | B25: =IF(RefiFlag=1,RefiMonth,DispoMonth)
A27: Monthly Period Grid
A28: Period → | C28: Total | D28: 1 | E28: 2 | F28: 3 | G28: 4 | H28: 5 | I28: 6 | J28: 7 | K28: 8 | L28: 9 | M28: 10 | N28: 11 | O28: 12 | P28: 13 | Q28: 14 | R28: 15 | S28: 16 | T28: 17 | U28: 18 | V28: 19 | W28: 20 | X28: 21 | Y28: 22 | Z28: 23 | AA28: 24 | AB28: 25 | AC28: 26 | AD28: 27 | AE28: 28 | AF28: 29 | AG28: 30 | AH28: 31 | AI28: 32 | AJ28: 33 | AK28: 34 | AL28: 35 | AM28: 36 | AN28: 37 | AO28: 38 | AP28: 39 | AQ28: 40 | AR28: 41 | AS28: 42 | AT28: 43 | AU28: 44 | AV28: 45 | AW28: 46 | AX28: 47 | AY28: 48 | AZ28: 49 | BA28: 50 | BB28: 51 | BC28: 52 | BD28: 53 | BE28: 54 | BF28: 55 | BG28: 56 | BH28: 57 | BI28: 58 | BJ28: 59 | BK28: 60 | BL28: 61 | BM28: 62 | BN28: 63 | BO28: 64 | BP28: 65 | BQ28: 66 | BR28: 67 | BS28: 68 | BT28: 69 | BU28: 70 | BV28: 71 | BW28: 72 | BX28: 73 | BY28: 74 | BZ28: 75 | CA28: 76 | CB28: 77 | CC28: 78 | CD28: 79 | CE28: 80 | CF28: 81 | CG28: 82 | CH28: 83 | CI28: 84 | CJ28: 85 | CK28: 86 | CL28: 87 | CM28: 88 | CN28: 89 | CO28: 90 | CP28: 91 | CQ28: 92 | CR28: 93 | CS28: 94 | CT28: 95 | CU28: 96 | CV28: 97 | CW28: 98 | CX28: 99 | CY28: 100 | CZ28: 101 | DA28: 102 | DB28: 103 | DC28: 104 | DD28: 105 | DE28: 106 | DF28: 107 | DG28: 108 | DH28: 109 | DI28: 110 | DJ28: 111 | DK28: 112 | DL28: 113 | DM28: 114 | DN28: 115 | DO28: 116 | DP28: 117 | DQ28: 118 | DR28: 119 | DS28: 120 | DT28: 121 | DU28: 122 | DV28: 123 | DW28: 124 | DX28: 125 | DY28: 126 | DZ28: 127 | EA28: 128 | EB28: 129 | EC28: 130 | ED28: 131 | EE28: 132 | EF28: 133 | EG28: 134 | EH28: 135 | EI28: 136 | EJ28: 137 | EK28: 138 | EL28: 139 | EM28: 140 | EN28: 141 | EO28: 142 | EP28: 143 | EQ28: 144 | ER28: 145 | ES28: 146 | ET28: 147 | EU28: 148 | EV28: 149 | EW28: 150 | EX28: 151 | EY28: 152 | EZ28: 153 | FA28: 154 | FB28: 155 | FC28: 156 | FD28: 157 | FE28: 158 | FF28: 159 | FG28: 160 | FH28: 161 | FI28: 162 | FJ28: 163 | FK28: 164 | FL28: 165 | FM28: 166 | FN28: 167 | FO28: 168 | FP28: 169 | FQ28: 170 | FR28: 171 | FS28: 172 | FT28: 173 | FU28: 174 | FV28: 175 | FW28: 176 | FX28: 177 | FY28: 178 | FZ28: 179 | GA28: 180 | GB28: 181 | GC28: 182 | GD28: 183 | GE28: 184 | GF28: 185 | GG28: 186 | GH28: 187 | GI28: 188 | GJ28: 189 | GK28: 190 | GL28: 191 | GM28: 192 | GN28: 193 | GO28: 194 | GP28: 195 | GQ28: 196 | GR28: 197 | GS28: 198 | GT28: 199 | GU28: 200 | GV28: 201 | GW28: 202 | GX28: 203 | GY28: 204 | GZ28: 205 | HA28: 206 | HB28: 207 | HC28: 208 | HD28: 209 | HE28: 210 | HF28: 211 | HG28: 212 | HH28: 213 | HI28: 214 | HJ28: 215 | HK28: 216 | HL28: 217 | HM28: 218 | HN28: 219 | HO28: 220 | HP28: 221 | HQ28: 222 | HR28: 223 | HS28: 224 | HT28: 225 | HU28: 226 | HV28: 227 | HW28: 228 | HX28: 229 | HY28: 230 | HZ28: 231 | IA28: 232 | IB28: 233 | IC28: 234 | ID28: 235 | IE28: 236 | IF28: 237 | IG28: 238 | IH28: 239 | II28: 240 | IJ28: 241 | IK28: 242 | IL28: 243 | IM28: 244 | IN28: 245 | IO28: 246 | IP28: 247 | IQ28: 248 | IR28: 249 | IS28: 250 | IT28: 251 | IU28: 252 | IV28: 253 | IW28: 254 | IX28: 255 | IY28: 256 | IZ28: 257 | JA28: 258 | JB28: 259 | JC28: 260 | JD28: 261 | JE28: 262 | JF28: 263 | JG28: 264 | JH28: 265 | JI28: 266 | JJ28: 267 | JK28: 268 | JL28: 269 | JM28: 270 | JN28: 271 | JO28: 272 | JP28: 273 | JQ28: 274 | JR28: 275 | JS28: 276 | JT28: 277 | JU28: 278 | JV28: 279 | JW28: 280 | JX28: 281 | JY28: 282 | JZ28: 283 | KA28: 284 | KB28: 285 | KC28: 286 | KD28: 287 | KE28: 288 | KF28: 289 | KG28: 290 | KH28: 291 | KI28: 292 | KJ28: 293 | KK28: 294 | KL28: 295 | KM28: 296 | KN28: 297 | KO28: 298 | KP28: 299 | KQ28: 300 | KR28: 301 | KS28: 302 | KT28: 303 | KU28: 304 | KV28: 305 | KW28: 306 | KX28: 307 | KY28: 308 | KZ28: 309 | LA28: 310 | LB28: 311 | LC28: 312 | LD28: 313 | LE28: 314 | LF28: 315 | LG28: 316 | LH28: 317 | LI28: 318 | LJ28: 319 | LK28: 320 | LL28: 321 | LM28: 322 | LN28: 323 | LO28: 324 | LP28: 325 | LQ28: 326 | LR28: 327 | LS28: 328 | LT28: 329 | LU28: 330 | LV28: 331 | LW28: 332 | LX28: 333 | LY28: 334 | LZ28: 335 | MA28: 336 | MB28: 337 | MC28: 338 | MD28: 339 | ME28: 340 | MF28: 341 | MG28: 342 | MH28: 343 | MI28: 344 | MJ28: 345 | MK28: 346 | ML28: 347 | MM28: 348 | MN28: 349 | MO28: 350 | MP28: 351 | MQ28: 352 | MR28: 353 | MS28: 354 | MT28: 355 | MU28: 356 | MV28: 357 | MW28: 358 | MX28: 359 | MY28: 360 | MZ28: 361 | NA28: 362 | NB28: 363 | NC28: 364 | ND28: 365 | NE28: 366 | NF28: 367 | NG28: 368 | NH28: 369 | NI28: 370 | NJ28: 371 | NK28: 372
A29: Month Start | D29: =EDATE(InceptionDate,0) | E29: =EDATE(InceptionDate,1) | F29: =EDATE(InceptionDate,2) | G29: =EDATE(InceptionDate,3) | H29: =EDATE(InceptionDate,4) | I29: =EDATE(InceptionDate,5) | J29: =EDATE(InceptionDate,6) | K29: =EDATE(InceptionDate,7) | L29: =EDATE(InceptionDate,8) | M29: =EDATE(InceptionDate,9) | N29: =EDATE(InceptionDate,10) | O29: =EDATE(InceptionDate,11) | P29: =EDATE(InceptionDate,12) | Q29: =EDATE(InceptionDate,13) | R29: =EDATE(InceptionDate,14) | S29: =EDATE(InceptionDate,15) | T29: =EDATE(InceptionDate,16) | U29: =EDATE(InceptionDate,17) | V29: =EDATE(InceptionDate,18) | W29: =EDATE(InceptionDate,19) | X29: =EDATE(InceptionDate,20) | Y29: =EDATE(InceptionDate,21) | Z29: =EDATE(InceptionDate,22) | AA29: =EDATE(InceptionDate,23) | AB29: =EDATE(InceptionDate,24) | AC29: =EDATE(InceptionDate,25) | AD29: =EDATE(InceptionDate,26) | AE29: =EDATE(InceptionDate,27) | AF29: =EDATE(InceptionDate,28) | AG29: =EDATE(InceptionDate,29) | AH29: =EDATE(InceptionDate,30) | AI29: =EDATE(InceptionDate,31) | AJ29: =EDATE(InceptionDate,32) | AK29: =EDATE(InceptionDate,33) | AL29: =EDATE(InceptionDate,34) | AM29: =EDATE(InceptionDate,35) | AN29: =EDATE(InceptionDate,36) | AO29: =EDATE(InceptionDate,37) | AP29: =EDATE(InceptionDate,38) | AQ29: =EDATE(InceptionDate,39) | AR29: =EDATE(InceptionDate,40) | AS29: =EDATE(InceptionDate,41) | AT29: =EDATE(InceptionDate,42) | AU29: =EDATE(InceptionDate,43) | AV29: =EDATE(InceptionDate,44) | AW29: =EDATE(InceptionDate,45) | AX29: =EDATE(InceptionDate,46) | AY29: =EDATE(InceptionDate,47) | AZ29: =EDATE(InceptionDate,48) | BA29: =EDATE(InceptionDate,49) | BB29: =EDATE(InceptionDate,50) | BC29: =EDATE(InceptionDate,51) | BD29: =EDATE(InceptionDate,52) | BE29: =EDATE(InceptionDate,53) | BF29: =EDATE(InceptionDate,54) | BG29: =EDATE(InceptionDate,55) | BH29: =EDATE(InceptionDate,56) | BI29: =EDATE(InceptionDate,57) | BJ29: =EDATE(InceptionDate,58) | BK29: =EDATE(InceptionDate,59) | BL29: =EDATE(InceptionDate,60) | BM29: =EDATE(InceptionDate,61) | BN29: =EDATE(InceptionDate,62) | BO29: =EDATE(InceptionDate,63) | BP29: =EDATE(InceptionDate,64) | BQ29: =EDATE(InceptionDate,65) | BR29: =EDATE(InceptionDate,66) | BS29: =EDATE(InceptionDate,67) | BT29: =EDATE(InceptionDate,68) | BU29: =EDATE(InceptionDate,69) | BV29: =EDATE(InceptionDate,70) | BW29: =EDATE(InceptionDate,71) | BX29: =EDATE(InceptionDate,72) | BY29: =EDATE(InceptionDate,73) | BZ29: =EDATE(InceptionDate,74) | CA29: =EDATE(InceptionDate,75) | CB29: =EDATE(InceptionDate,76) | CC29: =EDATE(InceptionDate,77) | CD29: =EDATE(InceptionDate,78) | CE29: =EDATE(InceptionDate,79) | CF29: =EDATE(InceptionDate,80) | CG29: =EDATE(InceptionDate,81) | CH29: =EDATE(InceptionDate,82) | CI29: =EDATE(InceptionDate,83) | CJ29: =EDATE(InceptionDate,84) | CK29: =EDATE(InceptionDate,85) | CL29: =EDATE(InceptionDate,86) | CM29: =EDATE(InceptionDate,87) | CN29: =EDATE(InceptionDate,88) | CO29: =EDATE(InceptionDate,89) | CP29: =EDATE(InceptionDate,90) | CQ29: =EDATE(InceptionDate,91) | CR29: =EDATE(InceptionDate,92) | CS29: =EDATE(InceptionDate,93) | CT29: =EDATE(InceptionDate,94) | CU29: =EDATE(InceptionDate,95) | CV29: =EDATE(InceptionDate,96) | CW29: =EDATE(InceptionDate,97) | CX29: =EDATE(InceptionDate,98) | CY29: =EDATE(InceptionDate,99) | CZ29: =EDATE(InceptionDate,100) | DA29: =EDATE(InceptionDate,101) | DB29: =EDATE(InceptionDate,102) | DC29: =EDATE(InceptionDate,103) | DD29: =EDATE(InceptionDate,104) | DE29: =EDATE(InceptionDate,105) | DF29: =EDATE(InceptionDate,106) | DG29: =EDATE(InceptionDate,107) | DH29: =EDATE(InceptionDate,108) | DI29: =EDATE(InceptionDate,109) | DJ29: =EDATE(InceptionDate,110) | DK29: =EDATE(InceptionDate,111) | DL29: =EDATE(InceptionDate,112) | DM29: =EDATE(InceptionDate,113) | DN29: =EDATE(InceptionDate,114) | DO29: =EDATE(InceptionDate,115) | DP29: =EDATE(InceptionDate,116) | DQ29: =EDATE(InceptionDate,117) | DR29: =EDATE(InceptionDate,118) | DS29: =EDATE(InceptionDate,119) | DT29: =EDATE(InceptionDate,120) | DU29: =EDATE(InceptionDate,121) | DV29: =EDATE(InceptionDate,122) | DW29: =EDATE(InceptionDate,123) | DX29: =EDATE(InceptionDate,124) | DY29: =EDATE(InceptionDate,125) | DZ29: =EDATE(InceptionDate,126) | EA29: =EDATE(InceptionDate,127) | EB29: =EDATE(InceptionDate,128) | EC29: =EDATE(InceptionDate,129) | ED29: =EDATE(InceptionDate,130) | EE29: =EDATE(InceptionDate,131) | EF29: =EDATE(InceptionDate,132) | EG29: =EDATE(InceptionDate,133) | EH29: =EDATE(InceptionDate,134) | EI29: =EDATE(InceptionDate,135) | EJ29: =EDATE(InceptionDate,136) | EK29: =EDATE(InceptionDate,137) | EL29: =EDATE(InceptionDate,138) | EM29: =EDATE(InceptionDate,139) | EN29: =EDATE(InceptionDate,140) | EO29: =EDATE(InceptionDate,141) | EP29: =EDATE(InceptionDate,142) | EQ29: =EDATE(InceptionDate,143) | ER29: =EDATE(InceptionDate,144) | ES29: =EDATE(InceptionDate,145) | ET29: =EDATE(InceptionDate,146) | EU29: =EDATE(InceptionDate,147) | EV29: =EDATE(InceptionDate,148) | EW29: =EDATE(InceptionDate,149) | EX29: =EDATE(InceptionDate,150) | EY29: =EDATE(InceptionDate,151) | EZ29: =EDATE(InceptionDate,152) | FA29: =EDATE(InceptionDate,153) | FB29: =EDATE(InceptionDate,154) | FC29: =EDATE(InceptionDate,155) | FD29: =EDATE(InceptionDate,156) | FE29: =EDATE(InceptionDate,157) | FF29: =EDATE(InceptionDate,158) | FG29: =EDATE(InceptionDate,159) | FH29: =EDATE(InceptionDate,160) | FI29: =EDATE(InceptionDate,161) | FJ29: =EDATE(InceptionDate,162) | FK29: =EDATE(InceptionDate,163) | FL29: =EDATE(InceptionDate,164) | FM29: =EDATE(InceptionDate,165) | FN29: =EDATE(InceptionDate,166) | FO29: =EDATE(InceptionDate,167) | FP29: =EDATE(InceptionDate,168) | FQ29: =EDATE(InceptionDate,169) | FR29: =EDATE(InceptionDate,170) | FS29: =EDATE(InceptionDate,171) | FT29: =EDATE(InceptionDate,172) | FU29: =EDATE(InceptionDate,173) | FV29: =EDATE(InceptionDate,174) | FW29: =EDATE(InceptionDate,175) | FX29: =EDATE(InceptionDate,176) | FY29: =EDATE(InceptionDate,177) | FZ29: =EDATE(InceptionDate,178) | GA29: =EDATE(InceptionDate,179) | GB29: =EDATE(InceptionDate,180) | GC29: =EDATE(InceptionDate,181) | GD29: =EDATE(InceptionDate,182) | GE29: =EDATE(InceptionDate,183) | GF29: =EDATE(InceptionDate,184) | GG29: =EDATE(InceptionDate,185) | GH29: =EDATE(InceptionDate,186) | GI29: =EDATE(InceptionDate,187) | GJ29: =EDATE(InceptionDate,188) | GK29: =EDATE(InceptionDate,189) | GL29: =EDATE(InceptionDate,190) | GM29: =EDATE(InceptionDate,191) | GN29: =EDATE(InceptionDate,192) | GO29: =EDATE(InceptionDate,193) | GP29: =EDATE(InceptionDate,194) | GQ29: =EDATE(InceptionDate,195) | GR29: =EDATE(InceptionDate,196) | GS29: =EDATE(InceptionDate,197) | GT29: =EDATE(InceptionDate,198) | GU29: =EDATE(InceptionDate,199) | GV29: =EDATE(InceptionDate,200) | GW29: =EDATE(InceptionDate,201) | GX29: =EDATE(InceptionDate,202) | GY29: =EDATE(InceptionDate,203) | GZ29: =EDATE(InceptionDate,204) | HA29: =EDATE(InceptionDate,205) | HB29: =EDATE(InceptionDate,206) | HC29: =EDATE(InceptionDate,207) | HD29: =EDATE(InceptionDate,208) | HE29: =EDATE(InceptionDate,209) | HF29: =EDATE(InceptionDate,210) | HG29: =EDATE(InceptionDate,211) | HH29: =EDATE(InceptionDate,212) | HI29: =EDATE(InceptionDate,213) | HJ29: =EDATE(InceptionDate,214) | HK29: =EDATE(InceptionDate,215) | HL29: =EDATE(InceptionDate,216) | HM29: =EDATE(InceptionDate,217) | HN29: =EDATE(InceptionDate,218) | HO29: =EDATE(InceptionDate,219) | HP29: =EDATE(InceptionDate,220) | HQ29: =EDATE(InceptionDate,221) | HR29: =EDATE(InceptionDate,222) | HS29: =EDATE(InceptionDate,223) | HT29: =EDATE(InceptionDate,224) | HU29: =EDATE(InceptionDate,225) | HV29: =EDATE(InceptionDate,226) | HW29: =EDATE(InceptionDate,227) | HX29: =EDATE(InceptionDate,228) | HY29: =EDATE(InceptionDate,229) | HZ29: =EDATE(InceptionDate,230) | IA29: =EDATE(InceptionDate,231) | IB29: =EDATE(InceptionDate,232) | IC29: =EDATE(InceptionDate,233) | ID29: =EDATE(InceptionDate,234) | IE29: =EDATE(InceptionDate,235) | IF29: =EDATE(InceptionDate,236) | IG29: =EDATE(InceptionDate,237) | IH29: =EDATE(InceptionDate,238) | II29: =EDATE(InceptionDate,239) | IJ29: =EDATE(InceptionDate,240) | IK29: =EDATE(InceptionDate,241) | IL29: =EDATE(InceptionDate,242) | IM29: =EDATE(InceptionDate,243) | IN29: =EDATE(InceptionDate,244) | IO29: =EDATE(InceptionDate,245) | IP29: =EDATE(InceptionDate,246) | IQ29: =EDATE(InceptionDate,247) | IR29: =EDATE(InceptionDate,248) | IS29: =EDATE(InceptionDate,249) | IT29: =EDATE(InceptionDate,250) | IU29: =EDATE(InceptionDate,251) | IV29: =EDATE(InceptionDate,252) | IW29: =EDATE(InceptionDate,253) | IX29: =EDATE(InceptionDate,254) | IY29: =EDATE(InceptionDate,255) | IZ29: =EDATE(InceptionDate,256) | JA29: =EDATE(InceptionDate,257) | JB29: =EDATE(InceptionDate,258) | JC29: =EDATE(InceptionDate,259) | JD29: =EDATE(InceptionDate,260) | JE29: =EDATE(InceptionDate,261) | JF29: =EDATE(InceptionDate,262) | JG29: =EDATE(InceptionDate,263) | JH29: =EDATE(InceptionDate,264) | JI29: =EDATE(InceptionDate,265) | JJ29: =EDATE(InceptionDate,266) | JK29: =EDATE(InceptionDate,267) | JL29: =EDATE(InceptionDate,268) | JM29: =EDATE(InceptionDate,269) | JN29: =EDATE(InceptionDate,270) | JO29: =EDATE(InceptionDate,271) | JP29: =EDATE(InceptionDate,272) | JQ29: =EDATE(InceptionDate,273) | JR29: =EDATE(InceptionDate,274) | JS29: =EDATE(InceptionDate,275) | JT29: =EDATE(InceptionDate,276) | JU29: =EDATE(InceptionDate,277) | JV29: =EDATE(InceptionDate,278) | JW29: =EDATE(InceptionDate,279) | JX29: =EDATE(InceptionDate,280) | JY29: =EDATE(InceptionDate,281) | JZ29: =EDATE(InceptionDate,282) | KA29: =EDATE(InceptionDate,283) | KB29: =EDATE(InceptionDate,284) | KC29: =EDATE(InceptionDate,285) | KD29: =EDATE(InceptionDate,286) | KE29: =EDATE(InceptionDate,287) | KF29: =EDATE(InceptionDate,288) | KG29: =EDATE(InceptionDate,289) | KH29: =EDATE(InceptionDate,290) | KI29: =EDATE(InceptionDate,291) | KJ29: =EDATE(InceptionDate,292) | KK29: =EDATE(InceptionDate,293) | KL29: =EDATE(InceptionDate,294) | KM29: =EDATE(InceptionDate,295) | KN29: =EDATE(InceptionDate,296) | KO29: =EDATE(InceptionDate,297) | KP29: =EDATE(InceptionDate,298) | KQ29: =EDATE(InceptionDate,299) | KR29: =EDATE(InceptionDate,300) | KS29: =EDATE(InceptionDate,301) | KT29: =EDATE(InceptionDate,302) | KU29: =EDATE(InceptionDate,303) | KV29: =EDATE(InceptionDate,304) | KW29: =EDATE(InceptionDate,305) | KX29: =EDATE(InceptionDate,306) | KY29: =EDATE(InceptionDate,307) | KZ29: =EDATE(InceptionDate,308) | LA29: =EDATE(InceptionDate,309) | LB29: =EDATE(InceptionDate,310) | LC29: =EDATE(InceptionDate,311) | LD29: =EDATE(InceptionDate,312) | LE29: =EDATE(InceptionDate,313) | LF29: =EDATE(InceptionDate,314) | LG29: =EDATE(InceptionDate,315) | LH29: =EDATE(InceptionDate,316) | LI29: =EDATE(InceptionDate,317) | LJ29: =EDATE(InceptionDate,318) | LK29: =EDATE(InceptionDate,319) | LL29: =EDATE(InceptionDate,320) | LM29: =EDATE(InceptionDate,321) | LN29: =EDATE(InceptionDate,322) | LO29: =EDATE(InceptionDate,323) | LP29: =EDATE(InceptionDate,324) | LQ29: =EDATE(InceptionDate,325) | LR29: =EDATE(InceptionDate,326) | LS29: =EDATE(InceptionDate,327) | LT29: =EDATE(InceptionDate,328) | LU29: =EDATE(InceptionDate,329) | LV29: =EDATE(InceptionDate,330) | LW29: =EDATE(InceptionDate,331) | LX29: =EDATE(InceptionDate,332) | LY29: =EDATE(InceptionDate,333) | LZ29: =EDATE(InceptionDate,334) | MA29: =EDATE(InceptionDate,335) | MB29: =EDATE(InceptionDate,336) | MC29: =EDATE(InceptionDate,337) | MD29: =EDATE(InceptionDate,338) | ME29: =EDATE(InceptionDate,339) | MF29: =EDATE(InceptionDate,340) | MG29: =EDATE(InceptionDate,341) | MH29: =EDATE(InceptionDate,342) | MI29: =EDATE(InceptionDate,343) | MJ29: =EDATE(InceptionDate,344) | MK29: =EDATE(InceptionDate,345) | ML29: =EDATE(InceptionDate,346) | MM29: =EDATE(InceptionDate,347) | MN29: =EDATE(InceptionDate,348) | MO29: =EDATE(InceptionDate,349) | MP29: =EDATE(InceptionDate,350) | MQ29: =EDATE(InceptionDate,351) | MR29: =EDATE(InceptionDate,352) | MS29: =EDATE(InceptionDate,353) | MT29: =EDATE(InceptionDate,354) | MU29: =EDATE(InceptionDate,355) | MV29: =EDATE(InceptionDate,356) | MW29: =EDATE(InceptionDate,357) | MX29: =EDATE(InceptionDate,358) | MY29: =EDATE(InceptionDate,359) | MZ29: =EDATE(InceptionDate,360) | NA29: =EDATE(InceptionDate,361) | NB29: =EDATE(InceptionDate,362) | NC29: =EDATE(InceptionDate,363) | ND29: =EDATE(InceptionDate,364) | NE29: =EDATE(InceptionDate,365) | NF29: =EDATE(InceptionDate,366) | NG29: =EDATE(InceptionDate,367) | NH29: =EDATE(InceptionDate,368) | NI29: =EDATE(InceptionDate,369) | NJ29: =EDATE(InceptionDate,370) | NK29: =EDATE(InceptionDate,371)
A30: Flag: Open Escrow | D30: =IF(AND(1>=$B$4,1<=$D$4),1,0) | E30: =IF(AND(2>=$B$4,2<=$D$4),1,0) | F30: =IF(AND(3>=$B$4,3<=$D$4),1,0) | G30: =IF(AND(4>=$B$4,4<=$D$4),1,0) | H30: =IF(AND(5>=$B$4,5<=$D$4),1,0) | I30: =IF(AND(6>=$B$4,6<=$D$4),1,0) | J30: =IF(AND(7>=$B$4,7<=$D$4),1,0) | K30: =IF(AND(8>=$B$4,8<=$D$4),1,0) | L30: =IF(AND(9>=$B$4,9<=$D$4),1,0) | M30: =IF(AND(10>=$B$4,10<=$D$4),1,0) | N30: =IF(AND(11>=$B$4,11<=$D$4),1,0) | O30: =IF(AND(12>=$B$4,12<=$D$4),1,0) | P30: =IF(AND(13>=$B$4,13<=$D$4),1,0) | Q30: =IF(AND(14>=$B$4,14<=$D$4),1,0) | R30: =IF(AND(15>=$B$4,15<=$D$4),1,0) | S30: =IF(AND(16>=$B$4,16<=$D$4),1,0) | T30: =IF(AND(17>=$B$4,17<=$D$4),1,0) | U30: =IF(AND(18>=$B$4,18<=$D$4),1,0) | V30: =IF(AND(19>=$B$4,19<=$D$4),1,0) | W30: =IF(AND(20>=$B$4,20<=$D$4),1,0) | X30: =IF(AND(21>=$B$4,21<=$D$4),1,0) | Y30: =IF(AND(22>=$B$4,22<=$D$4),1,0) | Z30: =IF(AND(23>=$B$4,23<=$D$4),1,0) | AA30: =IF(AND(24>=$B$4,24<=$D$4),1,0) | AB30: =IF(AND(25>=$B$4,25<=$D$4),1,0) | AC30: =IF(AND(26>=$B$4,26<=$D$4),1,0) | AD30: =IF(AND(27>=$B$4,27<=$D$4),1,0) | AE30: =IF(AND(28>=$B$4,28<=$D$4),1,0) | AF30: =IF(AND(29>=$B$4,29<=$D$4),1,0) | AG30: =IF(AND(30>=$B$4,30<=$D$4),1,0) | AH30: =IF(AND(31>=$B$4,31<=$D$4),1,0) | AI30: =IF(AND(32>=$B$4,32<=$D$4),1,0) | AJ30: =IF(AND(33>=$B$4,33<=$D$4),1,0) | AK30: =IF(AND(34>=$B$4,34<=$D$4),1,0) | AL30: =IF(AND(35>=$B$4,35<=$D$4),1,0) | AM30: =IF(AND(36>=$B$4,36<=$D$4),1,0) | AN30: =IF(AND(37>=$B$4,37<=$D$4),1,0) | AO30: =IF(AND(38>=$B$4,38<=$D$4),1,0) | AP30: =IF(AND(39>=$B$4,39<=$D$4),1,0) | AQ30: =IF(AND(40>=$B$4,40<=$D$4),1,0) | AR30: =IF(AND(41>=$B$4,41<=$D$4),1,0) | AS30: =IF(AND(42>=$B$4,42<=$D$4),1,0) | AT30: =IF(AND(43>=$B$4,43<=$D$4),1,0) | AU30: =IF(AND(44>=$B$4,44<=$D$4),1,0) | AV30: =IF(AND(45>=$B$4,45<=$D$4),1,0) | AW30: =IF(AND(46>=$B$4,46<=$D$4),1,0) | AX30: =IF(AND(47>=$B$4,47<=$D$4),1,0) | AY30: =IF(AND(48>=$B$4,48<=$D$4),1,0) | AZ30: =IF(AND(49>=$B$4,49<=$D$4),1,0) | BA30: =IF(AND(50>=$B$4,50<=$D$4),1,0) | BB30: =IF(AND(51>=$B$4,51<=$D$4),1,0) | BC30: =IF(AND(52>=$B$4,52<=$D$4),1,0) | BD30: =IF(AND(53>=$B$4,53<=$D$4),1,0) | BE30: =IF(AND(54>=$B$4,54<=$D$4),1,0) | BF30: =IF(AND(55>=$B$4,55<=$D$4),1,0) | BG30: =IF(AND(56>=$B$4,56<=$D$4),1,0) | BH30: =IF(AND(57>=$B$4,57<=$D$4),1,0) | BI30: =IF(AND(58>=$B$4,58<=$D$4),1,0) | BJ30: =IF(AND(59>=$B$4,59<=$D$4),1,0) | BK30: =IF(AND(60>=$B$4,60<=$D$4),1,0) | BL30: =IF(AND(61>=$B$4,61<=$D$4),1,0) | BM30: =IF(AND(62>=$B$4,62<=$D$4),1,0) | BN30: =IF(AND(63>=$B$4,63<=$D$4),1,0) | BO30: =IF(AND(64>=$B$4,64<=$D$4),1,0) | BP30: =IF(AND(65>=$B$4,65<=$D$4),1,0) | BQ30: =IF(AND(66>=$B$4,66<=$D$4),1,0) | BR30: =IF(AND(67>=$B$4,67<=$D$4),1,0) | BS30: =IF(AND(68>=$B$4,68<=$D$4),1,0) | BT30: =IF(AND(69>=$B$4,69<=$D$4),1,0) | BU30: =IF(AND(70>=$B$4,70<=$D$4),1,0) | BV30: =IF(AND(71>=$B$4,71<=$D$4),1,0) | BW30: =IF(AND(72>=$B$4,72<=$D$4),1,0) | BX30: =IF(AND(73>=$B$4,73<=$D$4),1,0) | BY30: =IF(AND(74>=$B$4,74<=$D$4),1,0) | BZ30: =IF(AND(75>=$B$4,75<=$D$4),1,0) | CA30: =IF(AND(76>=$B$4,76<=$D$4),1,0) | CB30: =IF(AND(77>=$B$4,77<=$D$4),1,0) | CC30: =IF(AND(78>=$B$4,78<=$D$4),1,0) | CD30: =IF(AND(79>=$B$4,79<=$D$4),1,0) | CE30: =IF(AND(80>=$B$4,80<=$D$4),1,0) | CF30: =IF(AND(81>=$B$4,81<=$D$4),1,0) | CG30: =IF(AND(82>=$B$4,82<=$D$4),1,0) | CH30: =IF(AND(83>=$B$4,83<=$D$4),1,0) | CI30: =IF(AND(84>=$B$4,84<=$D$4),1,0) | CJ30: =IF(AND(85>=$B$4,85<=$D$4),1,0) | CK30: =IF(AND(86>=$B$4,86<=$D$4),1,0) | CL30: =IF(AND(87>=$B$4,87<=$D$4),1,0) | CM30: =IF(AND(88>=$B$4,88<=$D$4),1,0) | CN30: =IF(AND(89>=$B$4,89<=$D$4),1,0) | CO30: =IF(AND(90>=$B$4,90<=$D$4),1,0) | CP30: =IF(AND(91>=$B$4,91<=$D$4),1,0) | CQ30: =IF(AND(92>=$B$4,92<=$D$4),1,0) | CR30: =IF(AND(93>=$B$4,93<=$D$4),1,0) | CS30: =IF(AND(94>=$B$4,94<=$D$4),1,0) | CT30: =IF(AND(95>=$B$4,95<=$D$4),1,0) | CU30: =IF(AND(96>=$B$4,96<=$D$4),1,0) | CV30: =IF(AND(97>=$B$4,97<=$D$4),1,0) | CW30: =IF(AND(98>=$B$4,98<=$D$4),1,0) | CX30: =IF(AND(99>=$B$4,99<=$D$4),1,0) | CY30: =IF(AND(100>=$B$4,100<=$D$4),1,0) | CZ30: =IF(AND(101>=$B$4,101<=$D$4),1,0) | DA30: =IF(AND(102>=$B$4,102<=$D$4),1,0) | DB30: =IF(AND(103>=$B$4,103<=$D$4),1,0) | DC30: =IF(AND(104>=$B$4,104<=$D$4),1,0) | DD30: =IF(AND(105>=$B$4,105<=$D$4),1,0) | DE30: =IF(AND(106>=$B$4,106<=$D$4),1,0) | DF30: =IF(AND(107>=$B$4,107<=$D$4),1,0) | DG30: =IF(AND(108>=$B$4,108<=$D$4),1,0) | DH30: =IF(AND(109>=$B$4,109<=$D$4),1,0) | DI30: =IF(AND(110>=$B$4,110<=$D$4),1,0) | DJ30: =IF(AND(111>=$B$4,111<=$D$4),1,0) | DK30: =IF(AND(112>=$B$4,112<=$D$4),1,0) | DL30: =IF(AND(113>=$B$4,113<=$D$4),1,0) | DM30: =IF(AND(114>=$B$4,114<=$D$4),1,0) | DN30: =IF(AND(115>=$B$4,115<=$D$4),1,0) | DO30: =IF(AND(116>=$B$4,116<=$D$4),1,0) | DP30: =IF(AND(117>=$B$4,117<=$D$4),1,0) | DQ30: =IF(AND(118>=$B$4,118<=$D$4),1,0) | DR30: =IF(AND(119>=$B$4,119<=$D$4),1,0) | DS30: =IF(AND(120>=$B$4,120<=$D$4),1,0) | DT30: =IF(AND(121>=$B$4,121<=$D$4),1,0) | DU30: =IF(AND(122>=$B$4,122<=$D$4),1,0) | DV30: =IF(AND(123>=$B$4,123<=$D$4),1,0) | DW30: =IF(AND(124>=$B$4,124<=$D$4),1,0) | DX30: =IF(AND(125>=$B$4,125<=$D$4),1,0) | DY30: =IF(AND(126>=$B$4,126<=$D$4),1,0) | DZ30: =IF(AND(127>=$B$4,127<=$D$4),1,0) | EA30: =IF(AND(128>=$B$4,128<=$D$4),1,0) | EB30: =IF(AND(129>=$B$4,129<=$D$4),1,0) | EC30: =IF(AND(130>=$B$4,130<=$D$4),1,0) | ED30: =IF(AND(131>=$B$4,131<=$D$4),1,0) | EE30: =IF(AND(132>=$B$4,132<=$D$4),1,0) | EF30: =IF(AND(133>=$B$4,133<=$D$4),1,0) | EG30: =IF(AND(134>=$B$4,134<=$D$4),1,0) | EH30: =IF(AND(135>=$B$4,135<=$D$4),1,0) | EI30: =IF(AND(136>=$B$4,136<=$D$4),1,0) | EJ30: =IF(AND(137>=$B$4,137<=$D$4),1,0) | EK30: =IF(AND(138>=$B$4,138<=$D$4),1,0) | EL30: =IF(AND(139>=$B$4,139<=$D$4),1,0) | EM30: =IF(AND(140>=$B$4,140<=$D$4),1,0) | EN30: =IF(AND(141>=$B$4,141<=$D$4),1,0) | EO30: =IF(AND(142>=$B$4,142<=$D$4),1,0) | EP30: =IF(AND(143>=$B$4,143<=$D$4),1,0) | EQ30: =IF(AND(144>=$B$4,144<=$D$4),1,0) | ER30: =IF(AND(145>=$B$4,145<=$D$4),1,0) | ES30: =IF(AND(146>=$B$4,146<=$D$4),1,0) | ET30: =IF(AND(147>=$B$4,147<=$D$4),1,0) | EU30: =IF(AND(148>=$B$4,148<=$D$4),1,0) | EV30: =IF(AND(149>=$B$4,149<=$D$4),1,0) | EW30: =IF(AND(150>=$B$4,150<=$D$4),1,0) | EX30: =IF(AND(151>=$B$4,151<=$D$4),1,0) | EY30: =IF(AND(152>=$B$4,152<=$D$4),1,0) | EZ30: =IF(AND(153>=$B$4,153<=$D$4),1,0) | FA30: =IF(AND(154>=$B$4,154<=$D$4),1,0) | FB30: =IF(AND(155>=$B$4,155<=$D$4),1,0) | FC30: =IF(AND(156>=$B$4,156<=$D$4),1,0) | FD30: =IF(AND(157>=$B$4,157<=$D$4),1,0) | FE30: =IF(AND(158>=$B$4,158<=$D$4),1,0) | FF30: =IF(AND(159>=$B$4,159<=$D$4),1,0) | FG30: =IF(AND(160>=$B$4,160<=$D$4),1,0) | FH30: =IF(AND(161>=$B$4,161<=$D$4),1,0) | FI30: =IF(AND(162>=$B$4,162<=$D$4),1,0) | FJ30: =IF(AND(163>=$B$4,163<=$D$4),1,0) | FK30: =IF(AND(164>=$B$4,164<=$D$4),1,0) | FL30: =IF(AND(165>=$B$4,165<=$D$4),1,0) | FM30: =IF(AND(166>=$B$4,166<=$D$4),1,0) | FN30: =IF(AND(167>=$B$4,167<=$D$4),1,0) | FO30: =IF(AND(168>=$B$4,168<=$D$4),1,0) | FP30: =IF(AND(169>=$B$4,169<=$D$4),1,0) | FQ30: =IF(AND(170>=$B$4,170<=$D$4),1,0) | FR30: =IF(AND(171>=$B$4,171<=$D$4),1,0) | FS30: =IF(AND(172>=$B$4,172<=$D$4),1,0) | FT30: =IF(AND(173>=$B$4,173<=$D$4),1,0) | FU30: =IF(AND(174>=$B$4,174<=$D$4),1,0) | FV30: =IF(AND(175>=$B$4,175<=$D$4),1,0) | FW30: =IF(AND(176>=$B$4,176<=$D$4),1,0) | FX30: =IF(AND(177>=$B$4,177<=$D$4),1,0) | FY30: =IF(AND(178>=$B$4,178<=$D$4),1,0) | FZ30: =IF(AND(179>=$B$4,179<=$D$4),1,0) | GA30: =IF(AND(180>=$B$4,180<=$D$4),1,0) | GB30: =IF(AND(181>=$B$4,181<=$D$4),1,0) | GC30: =IF(AND(182>=$B$4,182<=$D$4),1,0) | GD30: =IF(AND(183>=$B$4,183<=$D$4),1,0) | GE30: =IF(AND(184>=$B$4,184<=$D$4),1,0) | GF30: =IF(AND(185>=$B$4,185<=$D$4),1,0) | GG30: =IF(AND(186>=$B$4,186<=$D$4),1,0) | GH30: =IF(AND(187>=$B$4,187<=$D$4),1,0) | GI30: =IF(AND(188>=$B$4,188<=$D$4),1,0) | GJ30: =IF(AND(189>=$B$4,189<=$D$4),1,0) | GK30: =IF(AND(190>=$B$4,190<=$D$4),1,0) | GL30: =IF(AND(191>=$B$4,191<=$D$4),1,0) | GM30: =IF(AND(192>=$B$4,192<=$D$4),1,0) | GN30: =IF(AND(193>=$B$4,193<=$D$4),1,0) | GO30: =IF(AND(194>=$B$4,194<=$D$4),1,0) | GP30: =IF(AND(195>=$B$4,195<=$D$4),1,0) | GQ30: =IF(AND(196>=$B$4,196<=$D$4),1,0) | GR30: =IF(AND(197>=$B$4,197<=$D$4),1,0) | GS30: =IF(AND(198>=$B$4,198<=$D$4),1,0) | GT30: =IF(AND(199>=$B$4,199<=$D$4),1,0) | GU30: =IF(AND(200>=$B$4,200<=$D$4),1,0) | GV30: =IF(AND(201>=$B$4,201<=$D$4),1,0) | GW30: =IF(AND(202>=$B$4,202<=$D$4),1,0) | GX30: =IF(AND(203>=$B$4,203<=$D$4),1,0) | GY30: =IF(AND(204>=$B$4,204<=$D$4),1,0) | GZ30: =IF(AND(205>=$B$4,205<=$D$4),1,0) | HA30: =IF(AND(206>=$B$4,206<=$D$4),1,0) | HB30: =IF(AND(207>=$B$4,207<=$D$4),1,0) | HC30: =IF(AND(208>=$B$4,208<=$D$4),1,0) | HD30: =IF(AND(209>=$B$4,209<=$D$4),1,0) | HE30: =IF(AND(210>=$B$4,210<=$D$4),1,0) | HF30: =IF(AND(211>=$B$4,211<=$D$4),1,0) | HG30: =IF(AND(212>=$B$4,212<=$D$4),1,0) | HH30: =IF(AND(213>=$B$4,213<=$D$4),1,0) | HI30: =IF(AND(214>=$B$4,214<=$D$4),1,0) | HJ30: =IF(AND(215>=$B$4,215<=$D$4),1,0) | HK30: =IF(AND(216>=$B$4,216<=$D$4),1,0) | HL30: =IF(AND(217>=$B$4,217<=$D$4),1,0) | HM30: =IF(AND(218>=$B$4,218<=$D$4),1,0) | HN30: =IF(AND(219>=$B$4,219<=$D$4),1,0) | HO30: =IF(AND(220>=$B$4,220<=$D$4),1,0) | HP30: =IF(AND(221>=$B$4,221<=$D$4),1,0) | HQ30: =IF(AND(222>=$B$4,222<=$D$4),1,0) | HR30: =IF(AND(223>=$B$4,223<=$D$4),1,0) | HS30: =IF(AND(224>=$B$4,224<=$D$4),1,0) | HT30: =IF(AND(225>=$B$4,225<=$D$4),1,0) | HU30: =IF(AND(226>=$B$4,226<=$D$4),1,0) | HV30: =IF(AND(227>=$B$4,227<=$D$4),1,0) | HW30: =IF(AND(228>=$B$4,228<=$D$4),1,0) | HX30: =IF(AND(229>=$B$4,229<=$D$4),1,0) | HY30: =IF(AND(230>=$B$4,230<=$D$4),1,0) | HZ30: =IF(AND(231>=$B$4,231<=$D$4),1,0) | IA30: =IF(AND(232>=$B$4,232<=$D$4),1,0) | IB30: =IF(AND(233>=$B$4,233<=$D$4),1,0) | IC30: =IF(AND(234>=$B$4,234<=$D$4),1,0) | ID30: =IF(AND(235>=$B$4,235<=$D$4),1,0) | IE30: =IF(AND(236>=$B$4,236<=$D$4),1,0) | IF30: =IF(AND(237>=$B$4,237<=$D$4),1,0) | IG30: =IF(AND(238>=$B$4,238<=$D$4),1,0) | IH30: =IF(AND(239>=$B$4,239<=$D$4),1,0) | II30: =IF(AND(240>=$B$4,240<=$D$4),1,0) | IJ30: =IF(AND(241>=$B$4,241<=$D$4),1,0) | IK30: =IF(AND(242>=$B$4,242<=$D$4),1,0) | IL30: =IF(AND(243>=$B$4,243<=$D$4),1,0) | IM30: =IF(AND(244>=$B$4,244<=$D$4),1,0) | IN30: =IF(AND(245>=$B$4,245<=$D$4),1,0) | IO30: =IF(AND(246>=$B$4,246<=$D$4),1,0) | IP30: =IF(AND(247>=$B$4,247<=$D$4),1,0) | IQ30: =IF(AND(248>=$B$4,248<=$D$4),1,0) | IR30: =IF(AND(249>=$B$4,249<=$D$4),1,0) | IS30: =IF(AND(250>=$B$4,250<=$D$4),1,0) | IT30: =IF(AND(251>=$B$4,251<=$D$4),1,0) | IU30: =IF(AND(252>=$B$4,252<=$D$4),1,0) | IV30: =IF(AND(253>=$B$4,253<=$D$4),1,0) | IW30: =IF(AND(254>=$B$4,254<=$D$4),1,0) | IX30: =IF(AND(255>=$B$4,255<=$D$4),1,0) | IY30: =IF(AND(256>=$B$4,256<=$D$4),1,0) | IZ30: =IF(AND(257>=$B$4,257<=$D$4),1,0) | JA30: =IF(AND(258>=$B$4,258<=$D$4),1,0) | JB30: =IF(AND(259>=$B$4,259<=$D$4),1,0) | JC30: =IF(AND(260>=$B$4,260<=$D$4),1,0) | JD30: =IF(AND(261>=$B$4,261<=$D$4),1,0) | JE30: =IF(AND(262>=$B$4,262<=$D$4),1,0) | JF30: =IF(AND(263>=$B$4,263<=$D$4),1,0) | JG30: =IF(AND(264>=$B$4,264<=$D$4),1,0) | JH30: =IF(AND(265>=$B$4,265<=$D$4),1,0) | JI30: =IF(AND(266>=$B$4,266<=$D$4),1,0) | JJ30: =IF(AND(267>=$B$4,267<=$D$4),1,0) | JK30: =IF(AND(268>=$B$4,268<=$D$4),1,0) | JL30: =IF(AND(269>=$B$4,269<=$D$4),1,0) | JM30: =IF(AND(270>=$B$4,270<=$D$4),1,0) | JN30: =IF(AND(271>=$B$4,271<=$D$4),1,0) | JO30: =IF(AND(272>=$B$4,272<=$D$4),1,0) | JP30: =IF(AND(273>=$B$4,273<=$D$4),1,0) | JQ30: =IF(AND(274>=$B$4,274<=$D$4),1,0) | JR30: =IF(AND(275>=$B$4,275<=$D$4),1,0) | JS30: =IF(AND(276>=$B$4,276<=$D$4),1,0) | JT30: =IF(AND(277>=$B$4,277<=$D$4),1,0) | JU30: =IF(AND(278>=$B$4,278<=$D$4),1,0) | JV30: =IF(AND(279>=$B$4,279<=$D$4),1,0) | JW30: =IF(AND(280>=$B$4,280<=$D$4),1,0) | JX30: =IF(AND(281>=$B$4,281<=$D$4),1,0) | JY30: =IF(AND(282>=$B$4,282<=$D$4),1,0) | JZ30: =IF(AND(283>=$B$4,283<=$D$4),1,0) | KA30: =IF(AND(284>=$B$4,284<=$D$4),1,0) | KB30: =IF(AND(285>=$B$4,285<=$D$4),1,0) | KC30: =IF(AND(286>=$B$4,286<=$D$4),1,0) | KD30: =IF(AND(287>=$B$4,287<=$D$4),1,0) | KE30: =IF(AND(288>=$B$4,288<=$D$4),1,0) | KF30: =IF(AND(289>=$B$4,289<=$D$4),1,0) | KG30: =IF(AND(290>=$B$4,290<=$D$4),1,0) | KH30: =IF(AND(291>=$B$4,291<=$D$4),1,0) | KI30: =IF(AND(292>=$B$4,292<=$D$4),1,0) | KJ30: =IF(AND(293>=$B$4,293<=$D$4),1,0) | KK30: =IF(AND(294>=$B$4,294<=$D$4),1,0) | KL30: =IF(AND(295>=$B$4,295<=$D$4),1,0) | KM30: =IF(AND(296>=$B$4,296<=$D$4),1,0) | KN30: =IF(AND(297>=$B$4,297<=$D$4),1,0) | KO30: =IF(AND(298>=$B$4,298<=$D$4),1,0) | KP30: =IF(AND(299>=$B$4,299<=$D$4),1,0) | KQ30: =IF(AND(300>=$B$4,300<=$D$4),1,0) | KR30: =IF(AND(301>=$B$4,301<=$D$4),1,0) | KS30: =IF(AND(302>=$B$4,302<=$D$4),1,0) | KT30: =IF(AND(303>=$B$4,303<=$D$4),1,0) | KU30: =IF(AND(304>=$B$4,304<=$D$4),1,0) | KV30: =IF(AND(305>=$B$4,305<=$D$4),1,0) | KW30: =IF(AND(306>=$B$4,306<=$D$4),1,0) | KX30: =IF(AND(307>=$B$4,307<=$D$4),1,0) | KY30: =IF(AND(308>=$B$4,308<=$D$4),1,0) | KZ30: =IF(AND(309>=$B$4,309<=$D$4),1,0) | LA30: =IF(AND(310>=$B$4,310<=$D$4),1,0) | LB30: =IF(AND(311>=$B$4,311<=$D$4),1,0) | LC30: =IF(AND(312>=$B$4,312<=$D$4),1,0) | LD30: =IF(AND(313>=$B$4,313<=$D$4),1,0) | LE30: =IF(AND(314>=$B$4,314<=$D$4),1,0) | LF30: =IF(AND(315>=$B$4,315<=$D$4),1,0) | LG30: =IF(AND(316>=$B$4,316<=$D$4),1,0) | LH30: =IF(AND(317>=$B$4,317<=$D$4),1,0) | LI30: =IF(AND(318>=$B$4,318<=$D$4),1,0) | LJ30: =IF(AND(319>=$B$4,319<=$D$4),1,0) | LK30: =IF(AND(320>=$B$4,320<=$D$4),1,0) | LL30: =IF(AND(321>=$B$4,321<=$D$4),1,0) | LM30: =IF(AND(322>=$B$4,322<=$D$4),1,0) | LN30: =IF(AND(323>=$B$4,323<=$D$4),1,0) | LO30: =IF(AND(324>=$B$4,324<=$D$4),1,0) | LP30: =IF(AND(325>=$B$4,325<=$D$4),1,0) | LQ30: =IF(AND(326>=$B$4,326<=$D$4),1,0) | LR30: =IF(AND(327>=$B$4,327<=$D$4),1,0) | LS30: =IF(AND(328>=$B$4,328<=$D$4),1,0) | LT30: =IF(AND(329>=$B$4,329<=$D$4),1,0) | LU30: =IF(AND(330>=$B$4,330<=$D$4),1,0) | LV30: =IF(AND(331>=$B$4,331<=$D$4),1,0) | LW30: =IF(AND(332>=$B$4,332<=$D$4),1,0) | LX30: =IF(AND(333>=$B$4,333<=$D$4),1,0) | LY30: =IF(AND(334>=$B$4,334<=$D$4),1,0) | LZ30: =IF(AND(335>=$B$4,335<=$D$4),1,0) | MA30: =IF(AND(336>=$B$4,336<=$D$4),1,0) | MB30: =IF(AND(337>=$B$4,337<=$D$4),1,0) | MC30: =IF(AND(338>=$B$4,338<=$D$4),1,0) | MD30: =IF(AND(339>=$B$4,339<=$D$4),1,0) | ME30: =IF(AND(340>=$B$4,340<=$D$4),1,0) | MF30: =IF(AND(341>=$B$4,341<=$D$4),1,0) | MG30: =IF(AND(342>=$B$4,342<=$D$4),1,0) | MH30: =IF(AND(343>=$B$4,343<=$D$4),1,0) | MI30: =IF(AND(344>=$B$4,344<=$D$4),1,0) | MJ30: =IF(AND(345>=$B$4,345<=$D$4),1,0) | MK30: =IF(AND(346>=$B$4,346<=$D$4),1,0) | ML30: =IF(AND(347>=$B$4,347<=$D$4),1,0) | MM30: =IF(AND(348>=$B$4,348<=$D$4),1,0) | MN30: =IF(AND(349>=$B$4,349<=$D$4),1,0) | MO30: =IF(AND(350>=$B$4,350<=$D$4),1,0) | MP30: =IF(AND(351>=$B$4,351<=$D$4),1,0) | MQ30: =IF(AND(352>=$B$4,352<=$D$4),1,0) | MR30: =IF(AND(353>=$B$4,353<=$D$4),1,0) | MS30: =IF(AND(354>=$B$4,354<=$D$4),1,0) | MT30: =IF(AND(355>=$B$4,355<=$D$4),1,0) | MU30: =IF(AND(356>=$B$4,356<=$D$4),1,0) | MV30: =IF(AND(357>=$B$4,357<=$D$4),1,0) | MW30: =IF(AND(358>=$B$4,358<=$D$4),1,0) | MX30: =IF(AND(359>=$B$4,359<=$D$4),1,0) | MY30: =IF(AND(360>=$B$4,360<=$D$4),1,0) | MZ30: =IF(AND(361>=$B$4,361<=$D$4),1,0) | NA30: =IF(AND(362>=$B$4,362<=$D$4),1,0) | NB30: =IF(AND(363>=$B$4,363<=$D$4),1,0) | NC30: =IF(AND(364>=$B$4,364<=$D$4),1,0) | ND30: =IF(AND(365>=$B$4,365<=$D$4),1,0) | NE30: =IF(AND(366>=$B$4,366<=$D$4),1,0) | NF30: =IF(AND(367>=$B$4,367<=$D$4),1,0) | NG30: =IF(AND(368>=$B$4,368<=$D$4),1,0) | NH30: =IF(AND(369>=$B$4,369<=$D$4),1,0) | NI30: =IF(AND(370>=$B$4,370<=$D$4),1,0) | NJ30: =IF(AND(371>=$B$4,371<=$D$4),1,0) | NK30: =IF(AND(372>=$B$4,372<=$D$4),1,0)
